Workbook

Sheet Gold_Dashboard
A1: داشبورد طلا و سکه
A2: ⚠️ داده‌های نمونه‌اند. ورودی‌ها را در شیت Gold_Input به‌روز کنید.
A4: ۱) قیمت‌ها و ارزش‌گذاری
A5: اونس جهانی (دلار) | B5: =GOLD_OZ -> 3400 | D5: شکاف دلار آزاد و نیمایی | E5: =IFERROR(USD_FREE/USD_NIMA-1,"") -> 0.31944444
A6: دلار آزاد (ریال) | B6: =USD_FREE -> 950000 | D6: نسبت طلا به نقره | E6: =IFERROR(GOLD_OZ/SILVER_OZ,"") -> 85
A7: سکه تمام — بازار | B7: =COIN_FULL -> 900000000 | D7: ارزش خام گرم ۱۸ عیار | E7: =Coin_Bubble!$E$9 -> 77885184
A8: سکه تمام — ارزش ذاتی | B8: =Coin_Bubble!$E$5 -> 7.6012824e+08 | D8: حباب گرم ۱۸ عیار | E8: =Coin_Bubble!$H$9 -> 0.052831826
A9: حباب سکه تمام | B9: =BUBBLE_FULL -> 0.18401074 | D9: حباب ربع سکه | E9: =Coin_Bubble!$H$7 -> 0.49974694
A11: ۲) روند قیمت سکه (از شیت Gold_History)
A12: آخرین ردیف داده | B12: =COUNT($A$5:$A$1204)+4 -> 4
A13: تاریخ آخرین داده | B13: =IFERROR(INDEX(Gold_History!$A$1:$A$1204,$B$12),"") -> -
A14: تاریخ شمسی | B14: =IFERROR(INDEX(Gold_History!$B$1:$B$1204,$B$12),"") -> -
A15: قیمت | B15: =IFERROR(INDEX(Gold_History!$C$1:$C$1204,$B$12),"") -> close
A16: بازده روز | B16: =IFERROR(INDEX(Gold_History!$H$1:$H$1204,$B$12),"") -> -
A17: MA کوتاه | B17: =IFERROR(INDEX(Gold_History!$I$1:$I$1204,$B$12),"") -> MA_SHORT
A18: MA میان‌مدت | B18: =IFERROR(INDEX(Gold_History!$J$1:$J$1204,$B$12),"") -> MA_MED
A19: MA بلند | B19: =IFERROR(INDEX(Gold_History!$K$1:$K$1204,$B$12),"") -> MA_LONG2
A20: نوسان سالانه | B20: =IFERROR(INDEX(Gold_History!$L$1:$L$1204,$B$12),"") -> -
A21: سقف ۶۰ روزه | B21: =IFERROR(INDEX(Gold_History!$M$1:$M$1204,$B$12),"") -> -
A22: کف ۶۰ روزه | B22: =IFERROR(INDEX(Gold_History!$N$1:$N$1204,$B$12),"") -> -
A23: افت از سقف | B23: =IFERROR(INDEX(Gold_History!$O$1:$O$1204,$B$12),"") -> -
A24: امتیاز روند (−۱۰ تا +۱۰) | B24: =IFERROR(MAX(-10,MIN(10,IF($B$15>$B$17,2.5,-2.5)+IF($B$15>$B$18,3.5,-3.5)+IF($B$15>$B$19,4,-4))),0) -> -10
A25: وضعیت روند | B25: =IF($B$24>=5,"صعودی قوی",IF($B$24>=2,"صعودی",IF($B$24<=-5,"نزولی قوی",IF($B$24<=-2,"نزولی","خنثی")))) -> نزولی قوی
A27: ۳) تفکیک بازده — این رشد از کجا آمده؟
A28: بازده کل ریالی | B28: =Coin_Bubble!$B$13 -> 0.8
A29: سهم طلای جهانی | B29: =Coin_Bubble!$B$14 -> 0.30769231
A30: سهم نرخ ارز | B30: =Coin_Bubble!$B$15 -> 0.58333333
A31: سهم تغییر حباب | B31: =Coin_Bubble!$B$18 -> -0.13065015
A33: اگر «سهم نرخ ارز» بزرگ‌ترین جزء باشد، این یک موقعیت ارزی است که لباس طلا پوشیده. حباب هم می‌تواند ماه‌ها بالا بماند — سنجه ارزش‌گذاری است، نه زمان‌بندی.

Sheet Asset_Signals
A1: سیگنال طلا و سکه
A2: همان انضباط سیگنال سهام، به‌علاوه یک بُعد که در سهام معادل ندارد: ارزش‌گذاری نسبی. حباب ۱۸٪ به‌تنهایی معنا ندارد — صدک آن در توزیع تاریخی معنا دارد.
A3: دارایی | B3: شیت تاریخچه | C3: ردیف آخر | D3: قیمت | E3: MA کوتاه | F3: MA میان‌مدت | G3: MA بلند | H3: MA زیر قیمت | I3: فاصله از MA میان | J3: بازده ۵ روزه | K3: بازده ۲۰ روزه | L3: بازده ۶۰ روزه | M3: نوسان سالانه | N3: میانه نوسان | O3: افت از سقف ۶۰ روزه | P3: سنجه ارزش‌گذاری | Q3: صدک ارزش‌گذاری | R3: امتیاز روند (T) | S3: امتیاز مومنتوم (M) | T3: امتیاز نوسان (V) | U3: امتیاز ارزش‌گذاری (P) | V3: امتیاز کل | W3: سیگنال | X3: قدرت | Y3: دلیل
A4: ورودی | B4: ورودی | C4: COUNT | D4: تاریخچه!C | E4: تاریخچه!I | F4: تاریخچه!J | G4: تاریخچه!K | H4: شمارش | I4: — | J4: — | K4: — | L4: — | M4: تاریخچه!L | N4: MEDIAN | O4: تاریخچه!O | P4: تاریخچه!P | Q4: تاریخچه!Q | R4: ±۱۰ | S4: ±۱۰ | T4: ±۱۰ | U4: ±۱۰ | V4: میانگین وزنی | W4: آستانه Settings | X4: ۱ تا ۵ | Y4: —
A5: سکه تمام بهار آزادی | B5: Gold_History | C5: =COUNT(INDIRECT($B5&"!$A$5:$A$5000"))+4 -> 504 | D5: =IFERROR(INDEX(INDIRECT($B5&"!$C:$C"),$C5),"") -> 1156997319 | E5: =IFERROR(INDEX(INDIRECT($B5&"!$I:$I"),$C5),"") -> 1.1485435e+09 | F5: =IFERROR(INDEX(INDIRECT($B5&"!$J:$J"),$C5),"") -> 1.1103131e+09 | G5: =IFERROR(INDEX(INDIRECT($B5&"!$K:$K"),$C5),"") -> 1.0161751e+09 | H5: =IF(NOT(ISNUMBER($D5)),"",IF($D5>$E5,1,0)+IF($D5>$F5,1,0)+IF($D5>$G5,1,0)) -> 3 | I5: =IFERROR($D5/$F5-1,"") -> 0.042045975 | J5: =IFERROR($D5/INDEX(INDIRECT($B5&"!$C:$C"),$C5-5)-1,"") -> -0.00065436043 | K5: =IFERROR($D5/INDEX(INDIRECT($B5&"!$C:$C"),$C5-20)-1,"") -> 0.04839504 | L5: =IFERROR($D5/INDEX(INDIRECT($B5&"!$C:$C"),$C5-60)-1,"") -> 0.082220785 | M5: =IFERROR(INDEX(INDIRECT($B5&"!$L:$L"),$C5),"") -> 0.17099498 | N5: =IFERROR(MEDIAN(INDIRECT($B5&"!$L$5:$L$5000")),"") -> 0.19417256 | O5: =IFERROR(INDEX(INDIRECT($B5&"!$O:$O"),$C5),"") -> -0.022630563 | P5: =IFERROR(IF(ISBLANK(INDEX(INDIRECT($B5&"!$P:$P"),$C5)),"",INDEX(INDIRECT($B5&"!$P:$P"),$C5)),"") | Q5: =IFERROR(IF(ISBLANK(INDEX(INDIRECT($B5&"!$Q:$Q"),$C5)),"",INDEX(INDIRECT($B5&"!$Q:$Q"),$C5)),"") | R5: =IF(NOT(ISNUMBER($D5)),0,IFERROR(MAX(-10,MIN(10,IF($D5>$E5,2.5,-2.5)+IF($D5>$F5,3.5,-3.5)+IF($D5>$G5,4,-4))),0)) -> 10 | S5: =IF(NOT(ISNUMBER($D5)),0,IFERROR(MAX(-10,MIN(10,IF($J5>0.02,2,IF($J5>0,1,IF($J5<-0.02,-2,-1)))+IF($K5>0.05,4,IF($K5>0,2,IF($K5<-0.05,-4,-2)))+IF($L5>0.1,4,IF($L5>0,2,IF($L5<-0.1,-4,-2))))),0)) -> 3 | T5: =IF(OR(NOT(ISNUMBER($M5)),NOT(ISNUMBER($N5)),$N5=0),0,IFERROR(MAX(-10,MIN(10,IF($M5/$N5>2,-6,IF($M5/$N5>1.4,-3,IF($M5/$N5<0.7,3,1))))),0)) -> 1 | U5: =IF(NOT(ISNUMBER($Q5)),0,IFERROR(MAX(-10,MIN(10,IF($Q5>=0.9,-8,IF($Q5>=0.75,-4,IF($Q5<=0.1,8,IF($Q5<=0.25,4,0)))))),0)) -> 0 | V5: =IF(NOT(ISNUMBER($D5)),"",IFERROR(($R5*AW_TREND+$S5*AW_MOM+$T5*AW_VOL+IF(ISNUMBER($Q5),$U5*AW_VAL,0))/(AW_TREND+AW_MOM+AW_VOL+IF(ISNUMBER($Q5),AW_VAL,0)),0)) -> 5.8666667 | W5: =IF(NOT(ISNUMBER($V5)),"",IF($V5>=TH_SBUY,"خرید قوی",IF($V5>=TH_BUY,"خرید",IF($V5<=TH_SSELL,"فروش قوی",IF($V5<=TH_SELL,"فروش","نگهداری"))))) -> خرید قوی | X5: =IF(NOT(ISNUMBER($V5)),"",IF(ABS($V5)>=8,5,IF(ABS($V5)>=5,4,IF(ABS($V5)>=3,3,IF(ABS($V5)>=1.5,2,1))))) -> 4 | Y5: =IF(NOT(ISNUMBER($D5)),"","روند: "&IF($R5>=5,"صعودی قوی",IF($R5>=2,"صعودی",IF($R5<=-5,"نزولی قوی",IF($R5<=-2,"نزولی","خنثی"))))&" | MA: "&$H5&"/3"&" | مومنتوم ۲۰ روزه: "&IFERROR(TEXT($K5,"0.0%"),"—")&" | نوسان: "&IFERROR(TEXT($M5,"0%"),"—")&" (میانه "&IFERROR(TEXT($N5,"0%"),"—")&")"&" | ارزش‌گذاری: صدک "&IFERROR(TEXT($Q5,"0%"),"—")) -> روند: صعودی قوی | MA: 3/3 | مومنتوم ۲۰ روزه: 4.8% | نوسان: 17% (میانه 19%) | ارزش‌گذاری: صدک
A6: طلای ۱۸ عیار | B6: Hist_Gram18 | C6: =COUNT(INDIRECT($B6&"!$A$5:$A$5000"))+4 -> 504 | D6: =IFERROR(INDEX(INDIRECT($B6&"!$C:$C"),$C6),"") -> 107465892 | E6: =IFERROR(INDEX(INDIRECT($B6&"!$I:$I"),$C6),"") -> 1.0420445e+08 | F6: =IFERROR(INDEX(INDIRECT($B6&"!$J:$J"),$C6),"") -> 1.0523274e+08 | G6: =IFERROR(INDEX(INDIRECT($B6&"!$K:$K"),$C6),"") -> 1.0971305e+08 | H6: =IF(NOT(ISNUMBER($D6)),"",IF($D6>$E6,1,0)+IF($D6>$F6,1,0)+IF($D6>$G6,1,0)) -> 2 | I6: =IFERROR($D6/$F6-1,"") -> 0.021221039 | J6: =IFERROR($D6/INDEX(INDIRECT($B6&"!$C:$C"),$C6-5)-1,"") -> 0.024098384 | K6: =IFERROR($D6/INDEX(INDIRECT($B6&"!$C:$C"),$C6-20)-1,"") -> 0.06168539 | L6: =IFERROR($D6/INDEX(INDIRECT($B6&"!$C:$C"),$C6-60)-1,"") -> -0.0019970388 | M6: =IFERROR(INDEX(INDIRECT($B6&"!$L:$L"),$C6),"") -> 0.13557378 | N6: =IFERROR(MEDIAN(INDIRECT($B6&"!$L$5:$L$5000")),"") -> 0.20399491 | O6: =IFERROR(INDEX(INDIRECT($B6&"!$O:$O"),$C6),"") -> -0.023761528 | P6: =IFERROR(IF(ISBLANK(INDEX(INDIRECT($B6&"!$P:$P"),$C6)),"",INDEX(INDIRECT($B6&"!$P:$P"),$C6)),"") | Q6: =IFERROR(IF(ISBLANK(INDEX(INDIRECT($B6&"!$Q:$Q"),$C6)),"",INDEX(INDIRECT($B6&"!$Q:$Q"),$C6)),"") | R6: =IF(NOT(ISNUMBER($D6)),0,IFERROR(MAX(-10,MIN(10,IF($D6>$E6,2.5,-2.5)+IF($D6>$F6,3.5,-3.5)+IF($D6>$G6,4,-4))),0)) -> 2 | S6: =IF(NOT(ISNUMBER($D6)),0,IFERROR(MAX(-10,MIN(10,IF($J6>0.02,2,IF($J6>0,1,IF($J6<-0.02,-2,-1)))+IF($K6>0.05,4,IF($K6>0,2,IF($K6<-0.05,-4,-2)))+IF($L6>0.1,4,IF($L6>0,2,IF($L6<-0.1,-4,-2))))),0)) -> 4 | T6: =IF(OR(NOT(ISNUMBER($M6)),NOT(ISNUMBER($N6)),$N6=0),0,IFERROR(MAX(-10,MIN(10,IF($M6/$N6>2,-6,IF($M6/$N6>1.4,-3,IF($M6/$N6<0.7,3,1))))),0)) -> 3 | U6: =IF(NOT(ISNUMBER($Q6)),0,IFERROR(MAX(-10,MIN(10,IF($Q6>=0.9,-8,IF($Q6>=0.75,-4,IF($Q6<=0.1,8,IF($Q6<=0.25,4,0)))))),0)) -> 0 | V6: =IF(NOT(ISNUMBER($D6)),"",IFERROR(($R6*AW_TREND+$S6*AW_MOM+$T6*AW_VOL+IF(ISNUMBER($Q6),$U6*AW_VAL,0))/(AW_TREND+AW_MOM+AW_VOL+IF(ISNUMBER($Q6),AW_VAL,0)),0)) -> 2.8666667 | W6: =IF(NOT(ISNUMBER($V6)),"",IF($V6>=TH_SBUY,"خرید قوی",IF($V6>=TH_BUY,"خرید",IF($V6<=TH_SSELL,"فروش قوی",IF($V6<=TH_SELL,"فروش","نگهداری"))))) -> خرید | X6: =IF(NOT(ISNUMBER($V6)),"",IF(ABS($V6)>=8,5,IF(ABS($V6)>=5,4,IF(ABS($V6)>=3,3,IF(ABS($V6)>=1.5,2,1))))) -> 2 | Y6: =IF(NOT(ISNUMBER($D6)),"","روند: "&IF($R6>=5,"صعودی قوی",IF($R6>=2,"صعودی",IF($R6<=-5,"نزولی قوی",IF($R6<=-2,"نزولی","خنثی"))))&" | MA: "&$H6&"/3"&" | مومنتوم ۲۰ روزه: "&IFERROR(TEXT($K6,"0.0%"),"—")&" | نوسان: "&IFERROR(TEXT($M6,"0%"),"—")&" (میانه "&IFERROR(TEXT($N6,"0%"),"—")&")"&" | ارزش‌گذاری: صدک "&IFERROR(TEXT($Q6,"0%"),"—")) -> روند: صعودی | MA: 2/3 | مومنتوم ۲۰ روزه: 6.2% | نوسان: 14% (میانه 20%) | ارزش‌گذاری: صدک
A7: اونس طلای جهانی | B7: Hist_Ons | C7: =COUNT(INDIRECT($B7&"!$A$5:$A$5000"))+4 -> 504 | D7: =IFERROR(INDEX(INDIRECT($B7&"!$C:$C"),$C7),"") -> 7916 | E7: =IFERROR(INDEX(INDIRECT($B7&"!$I:$I"),$C7),"") -> 7545.1 | F7: =IFERROR(INDEX(INDIRECT($B7&"!$J:$J"),$C7),"") -> 7360.68 | G7: =IFERROR(INDEX(INDIRECT($B7&"!$K:$K"),$C7),"") -> 6918.65 | H7: =IF(NOT(ISNUMBER($D7)),"",IF($D7>$E7,1,0)+IF($D7>$F7,1,0)+IF($D7>$G7,1,0)) -> 3 | I7: =IFERROR($D7/$F7-1,"") -> 0.075444117 | J7: =IFERROR($D7/INDEX(INDIRECT($B7&"!$C:$C"),$C7-5)-1,"") -> 0.019052523 | K7: =IFERROR($D7/INDEX(INDIRECT($B7&"!$C:$C"),$C7-20)-1,"") -> 0.10051439 | L7: =IFERROR($D7/INDEX(INDIRECT($B7&"!$C:$C"),$C7-60)-1,"") -> 0.062550336 | M7: =IFERROR(INDEX(INDIRECT($B7&"!$L:$L"),$C7),"") -> 0.16757102 | N7: =IFERROR(MEDIAN(INDIRECT($B7&"!$L$5:$L$5000")),"") -> 0.19495266 | O7: =IFERROR(INDEX(INDIRECT($B7&"!$O:$O"),$C7),"") -> -0.017012294 | P7: =IFERROR(IF(ISBLANK(INDEX(INDIRECT($B7&"!$P:$P"),$C7)),"",INDEX(INDIRECT($B7&"!$P:$P"),$C7)),"") | Q7: =IFERROR(IF(ISBLANK(INDEX(INDIRECT($B7&"!$Q:$Q"),$C7)),"",INDEX(INDIRECT($B7&"!$Q:$Q"),$C7)),"") | R7: =IF(NOT(ISNUMBER($D7)),0,IFERROR(MAX(-10,MIN(10,IF($D7>$E7,2.5,-2.5)+IF($D7>$F7,3.5,-3.5)+IF($D7>$G7,4,-4))),0)) -> 10 | S7: =IF(NOT(ISNUMBER($D7)),0,IFERROR(MAX(-10,MIN(10,IF($J7>0.02,2,IF($J7>0,1,IF($J7<-0.02,-2,-1)))+IF($K7>0.05,4,IF($K7>0,2,IF($K7<-0.05,-4,-2)))+IF($L7>0.1,4,IF($L7>0,2,IF($L7<-0.1,-4,-2))))),0)) -> 7 | T7: =IF(OR(NOT(ISNUMBER($M7)),NOT(ISNUMBER($N7)),$N7=0),0,IFERROR(MAX(-10,MIN(10,IF($M7/$N7>2,-6,IF($M7/$N7>1.4,-3,IF($M7/$N7<0.7,3,1))))),0)) -> 1 | U7: =IF(NOT(ISNUMBER($Q7)),0,IFERROR(MAX(-10,MIN(10,IF($Q7>=0.9,-8,IF($Q7>=0.75,-4,IF($Q7<=0.1,8,IF($Q7<=0.25,4,0)))))),0)) -> 0 | V7: =IF(NOT(ISNUMBER($D7)),"",IFERROR(($R7*AW_TREND+$S7*AW_MOM+$T7*AW_VOL+IF(ISNUMBER($Q7),$U7*AW_VAL,0))/(AW_TREND+AW_MOM+AW_VOL+IF(ISNUMBER($Q7),AW_VAL,0)),0)) -> 7.2 | W7: =IF(NOT(ISNUMBER($V7)),"",IF($V7>=TH_SBUY,"خرید قوی",IF($V7>=TH_BUY,"خرید",IF($V7<=TH_SSELL,"فروش قوی",IF($V7<=TH_SELL,"فروش","نگهداری"))))) -> خرید قوی | X7: =IF(NOT(ISNUMBER($V7)),"",IF(ABS($V7)>=8,5,IF(ABS($V7)>=5,4,IF(ABS($V7)>=3,3,IF(ABS($V7)>=1.5,2,1))))) -> 4 | Y7: =IF(NOT(ISNUMBER($D7)),"","روند: "&IF($R7>=5,"صعودی قوی",IF($R7>=2,"صعودی",IF($R7<=-5,"نزولی قوی",IF($R7<=-2,"نزولی","خنثی"))))&" | MA: "&$H7&"/3"&" | مومنتوم ۲۰ روزه: "&IFERROR(TEXT($K7,"0.0%"),"—")&" | نوسان: "&IFERROR(TEXT($M7,"0%"),"—")&" (میانه "&IFERROR(TEXT($N7,"0%"),"—")&")"&" | ارزش‌گذاری: صدک "&IFERROR(TEXT($Q7,"0%"),"—")) -> روند: صعودی قوی | MA: 3/3 | مومنتوم ۲۰ روزه: 10.1% | نوسان: 17% (میانه 19%) | ارزش‌گذاری: صدک
A9: سنجه ارزش‌گذاری برای سکه و گرم، حباب نسبت به ارزش ذاتی فلز است. برای اونس جهانی سنجه ارزش‌گذاری تعریف نشده — طلای جهانی «ارزش ذاتی» قابل‌محاسبه‌ای ندارد که بتوان با آن سنجید، پس امتیاز ارزش‌گذاری آن صفر می‌ماند.
A10: ستون «سنجه ارزش‌گذاری» را اسکریپت پایتون پر می‌کند، چون ساختن آن نیازمند هم‌تراز کردن چند سری زمانی با تاریخ‌های ناهمسان است — کاری که در اکسل شکننده می‌شود ولی در پایتون بدیهی است. صدک آن اما در اکسل حساب می‌شود تا با تغییر داده زنده به‌روز بماند.
A11: ⚠️ هیچ‌کدام از آستانه‌ها و وزن‌ها بک‌تست نشده‌اند. برای آزمودنشان روی سری واقعی: python -m timeframe backtest --csv <سری>.csv --name <دارایی>

Sheet Coin_Bubble
A1: ارزش ذاتی و حباب مسکوکات
A2: ارزش ذاتی یک محاسبه قطعی است: محتوای طلای خالص × قیمت جهانی × نرخ ارز. حباب همان اختلاف قیمت بازار با این عدد است.
A3: مسکوک | B3: وزن (گرم) | C3: عیار | D3: طلای خالص (گرم) | E3: ارزش ذاتی (ریال) | F3: قیمت بازار (ریال) | G3: حباب (ریال) | H3: حباب ٪
A4: - | B4: ورودی | C4: ورودی | D4: وزن × عیار | E4: GOLD_OZ · USD_FREE | F4: ورودی | G4: بازار − ذاتی | H4: ÷ ذاتی − ۱
A5: سکه تمام بهار آزادی | B5: 8.133 | C5: 0.9 | D5: =$B5*$C5 -> 7.3197 | E5: =$D5*(GOLD_OZ/31.1034768)*USD_FREE -> 7.6012824e+08 | F5: =COIN_FULL -> 900000000 | G5: =IFERROR($F5-$E5,"") -> 1.3987176e+08 | H5: =IFERROR($F5/$E5-1,"") -> 0.18401074
A6: نیم سکه | B6: 4.0665 | C6: 0.9 | D6: =$B6*$C6 -> 3.65985 | E6: =$D6*(GOLD_OZ/31.1034768)*USD_FREE -> 3.8006412e+08 | F6: =COIN_HALF -> 470000000 | G6: =IFERROR($F6-$E6,"") -> 89935881 | H6: =IFERROR($F6/$E6-1,"") -> 0.23663344
A7: ربع سکه | B7: 2.03325 | C7: 0.9 | D7: =$B7*$C7 -> 1.829925 | E7: =$D7*(GOLD_OZ/31.1034768)*USD_FREE -> 1.9003206e+08 | F7: =COIN_QTR -> 285000000 | G7: =IFERROR($F7-$E7,"") -> 94967941 | H7: =IFERROR($F7/$E7-1,"") -> 0.49974694
A8: سکه گرمی | B8: 1.0166 | C8: 0.9 | D8: =$B8*$C8 -> 0.91494 | E8: =$D8*(GOLD_OZ/31.1034768)*USD_FREE -> 95013693 | G8: =IFERROR($F8-$E8,"") -> -95013693 | H8: =IFERROR($F8/$E8-1,"") -> -1
A9: طلای ۱۸ عیار (هر گرم) | B9: 1 | C9: 0.75 | D9: =$B9*$C9 -> 0.75 | E9: =$D9*(GOLD_OZ/31.1034768)*USD_FREE -> 77885184 | F9: =GRAM_18K -> 82000000 | G9: =IFERROR($F9-$E9,"") -> 4114816.4 | H9: =IFERROR($F9/$E9-1,"") -> 0.052831826
A12: تفکیک بازده ریالی سکه به سه محرک
A13: بازده کل ریالی سکه | B13: =IFERROR(COIN_FULL/COIN_FULL_0-1,"") -> 0.8
A14: سهم طلای جهانی | B14: =IFERROR(GOLD_OZ/GOLD_OZ_0-1,"") -> 0.30769231
A15: سهم نرخ ارز | B15: =IFERROR(USD_FREE/USD_FREE_0-1,"") -> 0.58333333
A16: حباب مبنا | B16: =IFERROR(COIN_FULL_0/(7.3197*(GOLD_OZ_0/31.1034768)*USD_FREE_0)-1,"") -> 0.36194968
A17: حباب کنونی | B17: =IFERROR($H$5,"") -> 0.18401074
A18: سهم تغییر حباب | B18: =IFERROR((1+$B17)/(1+$B16)-1,"") -> -0.13065015
A19: کنترل صحت (باید با بازده کل یکی باشد) | B19: =IFERROR((1+$B14)*(1+$B15)*(1+$B18)-1,"") -> 0.8
A20: اختلاف کنترل با بازده کل | B20: =IFERROR($B19-$B13,"") -> 0
A22: چرا این تفکیک مهم است: رشد ریالی طلا در ایران اغلب اصلاً درباره طلا نیست. اگر «سهم نرخ ارز» بزرگ‌ترین جزء باشد، شما روی ریال شرط بسته‌اید، نه روی طلا.

Sheet Gold_Input
A1: ورودی‌های لحظه‌ای طلا
A2: سلول‌های زرد را پر کنید. همه محاسبات فایل از همین چند عدد می‌آیند.
A4: بازار جهانی
A5: اونس طلا (دلار) | B5: 3400 | C5: منبع: بازار جهانی
A6: اونس نقره (دلار) | B6: 40 | C6: اختیاری — برای نسبت طلا به نقره
A8: نرخ ارز
A9: دلار آزاد (ریال) | B9: 950000 | C9: نرخ بازار آزاد
A10: دلار نیمایی / مرجع (ریال) | B10: 720000 | C10: برای محاسبه شکاف
A12: قیمت بازار داخلی
A13: سکه تمام بهار آزادی (ریال) | B13: 900000000 | C13: قیمت بازار
A14: نیم سکه (ریال) | B14: 470000000
A15: ربع سکه (ریال) | B15: 285000000
A16: طلای ۱۸ عیار هر گرم (ریال) | B16: 82000000 | C16: شامل اجرت و مالیات
A18: مبنای مقایسه (برای تفکیک بازده)
A19: اونس در تاریخ مبنا (دلار) | B19: 2600 | C19: مثلاً ابتدای سال
A20: دلار در تاریخ مبنا (ریال) | B20: 600000
A21: سکه در تاریخ مبنا (ریال) | B21: 500000000
A23: ⚠️ اعداد بالا نمونه‌اند. قیمت واقعی روز را جایگزین کنید — همه خروجی‌های فایل مستقیماً از همین سلول‌ها می‌آیند.

Sheet Gold_History
A1: تاریخچه روزانه سکه تمام بهار آزادی
A2: ستون‌های A تا F ورودی؛ بقیه فرمول. ستون P (حباب) را اسکریپت پایتون پر می‌کند.
A3: تاریخ میلادی | B3: تاریخ شمسی | C3: قیمت | D3: بیشترین | E3: کمترین | F3: حجم / یادداشت | G3: شمارنده | H3: بازده روزانه | I3: MA کوتاه | J3: MA میان‌مدت | K3: MA بلند | L3: نوسان ۲۰ روزه (سالانه) | M3: سقف ۶۰ روزه | N3: کف ۶۰ روزه | O3: افت از سقف | P3: حباب سکه | Q3: صدک تاریخی سنجه
A4: - | B4: - | C4: close | D4: high | E4: low | F4: volume | G4: n | H4: - | I4: MA_SHORT | J4: MA_MED | K4: MA_LONG2 | L4: - | M4: - | N4: - | O4: - | P4: پایتون | Q4: PERCENTRANK
A5: 45570 | B5: 1403/07/14 | C5: 626838716 | D5: 630140094 | E5: 624944947 | F5: 0 | G5: =IF($A5="","",IF(ISNUMBER($G4),$G4+1,1)) -> 1 | H5: =IF(OR(NOT(ISNUMBER($G5)),$G5<2,NOT(ISNUMBER($C4)),$C4=0),"",$C5/$C4-1) | I5: =IF(AND(ISNUMBER($G5),$G5>=MA_SHORT),AVERAGE(INDEX($C$5:$C5,2-MA_SHORT):$C5),"") | J5: =IF(AND(ISNUMBER($G5),$G5>=MA_MED),AVERAGE(INDEX($C$5:$C5,2-MA_MED):$C5),"") | K5: =IF(AND(ISNUMBER($G5),$G5>=MA_LONG2),AVERAGE(INDEX($C$5:$C5,2-MA_LONG2):$C5),"") | L5: =IF(AND(ISNUMBER($G5),$G5>=21),STDEV(INDEX($H$5:$H5,2-20):$H5)*SQRT(245),"") | M5: =IF(AND(ISNUMBER($G5),$G5>=60),MAX(INDEX($D$5:$D5,2-60):$D5),"") | N5: =IF(AND(ISNUMBER($G5),$G5>=60),MIN(INDEX($E$5:$E5,2-60):$E5),"") | O5: =IF(OR(NOT(ISNUMBER($C5)),NOT(ISNUMBER($M5)),$M5=0),"",$C5/$M5-1) | Q5: =IF(NOT(ISNUMBER($P5)),"",IFERROR(PERCENTRANK($P$5:$P$1204,$P5),""))
A6: 45571 | B6: 1403/07/15 | C6: 620421683 | D6: 621354578 | E6: 616119534 | F6: 0 | G6: =IF($A6="","",IF(ISNUMBER($G5),$G5+1,1)) -> 2 | H6: =IF(OR(NOT(ISNUMBER($G6)),$G6<2,NOT(ISNUMBER($C5)),$C5=0),"",$C6/$C5-1) -> -0.010237136 | I6: =IF(AND(ISNUMBER($G6),$G6>=MA_SHORT),AVERAGE(INDEX($C$5:$C6,3-MA_SHORT):$C6),"") | J6: =IF(AND(ISNUMBER($G6),$G6>=MA_MED),AVERAGE(INDEX($C$5:$C6,3-MA_MED):$C6),"") | K6: =IF(AND(ISNUMBER($G6),$G6>=MA_LONG2),AVERAGE(INDEX($C$5:$C6,3-MA_LONG2):$C6),"") | L6: =IF(AND(ISNUMBER($G6),$G6>=21),STDEV(INDEX($H$5:$H6,3-20):$H6)*SQRT(245),"") | M6: =IF(AND(ISNUMBER($G6),$G6>=60),MAX(INDEX($D$5:$D6,3-60):$D6),"") | N6: =IF(AND(ISNUMBER($G6),$G6>=60),MIN(INDEX($E$5:$E6,3-60):$E6),"") | O6: =IF(OR(NOT(ISNUMBER($C6)),NOT(ISNUMBER($M6)),$M6=0),"",$C6/$M6-1) | Q6: =IF(NOT(ISNUMBER($P6)),"",IFERROR(PERCENTRANK($P$5:$P$1204,$P6),""))
A7: 45572 | B7: 1403/07/16 | C7: 624417457 | D7: 627215646 | E7: 622585500 | F7: 0 | G7: =IF($A7="","",IF(ISNUMBER($G6),$G6+1,1)) -> 3 | H7: =IF(OR(NOT(ISNUMBER($G7)),$G7<2,NOT(ISNUMBER($C6)),$C6=0),"",$C7/$C6-1) -> 0.0064404164 | I7: =IF(AND(ISNUMBER($G7),$G7>=MA_SHORT),AVERAGE(INDEX($C$5:$C7,4-MA_SHORT):$C7),"") | J7: =IF(AND(ISNUMBER($G7),$G7>=MA_MED),AVERAGE(INDEX($C$5:$C7,4-MA_MED):$C7),"") | K7: =IF(AND(ISNUMBER($G7),$G7>=MA_LONG2),AVERAGE(INDEX($C$5:$C7,4-MA_LONG2):$C7),"") | L7: =IF(AND(ISNUMBER($G7),$G7>=21),STDEV(INDEX($H$5:$H7,4-20):$H7)*SQRT(245),"") | M7: =IF(AND(ISNUMBER($G7),$G7>=60),MAX(INDEX($D$5:$D7,4-60):$D7),"") | N7: =IF(AND(ISNUMBER($G7),$G7>=60),MIN(INDEX($E$5:$E7,4-60):$E7),"") | O7: =IF(OR(NOT(ISNUMBER($C7)),NOT(ISNUMBER($M7)),$M7=0),"",$C7/$M7-1) | Q7: =IF(NOT(ISNUMBER($P7)),"",IFERROR(PERCENTRANK($P$5:$P$1204,$P7),""))
A8: 45573 | B8: 1403/07/17 | C8: 624789174 | D8: 627195417 | E8: 624741080 | F8: 0 | G8: =IF($A8="","",IF(ISNUMBER($G7),$G7+1,1)) -> 4 | H8: =IF(OR(NOT(ISNUMBER($G8)),$G8<2,NOT(ISNUMBER($C7)),$C7=0),"",$C8/$C7-1) -> 0.00059530206 | I8: =IF(AND(ISNUMBER($G8),$G8>=MA_SHORT),AVERAGE(INDEX($C$5:$C8,5-MA_SHORT):$C8),"") | J8: =IF(AND(ISNUMBER($G8),$G8>=MA_MED),AVERAGE(INDEX($C$5:$C8,5-MA_MED):$C8),"") | K8: =IF(AND(ISNUMBER($G8),$G8>=MA_LONG2),AVERAGE(INDEX($C$5:$C8,5-MA_LONG2):$C8),"") | L8: =IF(AND(ISNUMBER($G8),$G8>=21),STDEV(INDEX($H$5:$H8,5-20):$H8)*SQRT(245),"") | M8: =IF(AND(ISNUMBER($G8),$G8>=60),MAX(INDEX($D$5:$D8,5-60):$D8),"") | N8: =IF(AND(ISNUMBER($G8),$G8>=60),MIN(INDEX($E$5:$E8,5-60):$E8),"") | O8: =IF(OR(NOT(ISNUMBER($C8)),NOT(ISNUMBER($M8)),$M8=0),"",$C8/$M8-1) | Q8: =IF(NOT(ISNUMBER($P8)),"",IFERROR(PERCENTRANK($P$5:$P$1204,$P8),""))
A9: 45574 | B9: 1403/07/18 | C9: 622706145 | D9: 623188407 | E9: 622214574 | F9: 0 | G9: =IF($A9="","",IF(ISNUMBER($G8),$G8+1,1)) -> 5 | H9: =IF(OR(NOT(ISNUMBER($G9)),$G9<2,NOT(ISNUMBER($C8)),$C8=0),"",$C9/$C8-1) -> -0.003333971 | I9: =IF(AND(ISNUMBER($G9),$G9>=MA_SHORT),AVERAGE(INDEX($C$5:$C9,6-MA_SHORT):$C9),"") | J9: =IF(AND(ISNUMBER($G9),$G9>=MA_MED),AVERAGE(INDEX($C$5:$C9,6-MA_MED):$C9),"") | K9: =IF(AND(ISNUMBER($G9),$G9>=MA_LONG2),AVERAGE(INDEX($C$5:$C9,6-MA_LONG2):$C9),"") | L9: =IF(AND(ISNUMBER($G9),$G9>=21),STDEV(INDEX($H$5:$H9,6-20):$H9)*SQRT(245),"") | M9: =IF(AND(ISNUMBER($G9),$G9>=60),MAX(INDEX($D$5:$D9,6-60):$D9),"") | N9: =IF(AND(ISNUMBER($G9),$G9>=60),MIN(INDEX($E$5:$E9,6-60):$E9),"") | O9: =IF(OR(NOT(ISNUMBER($C9)),NOT(ISNUMBER($M9)),$M9=0),"",$C9/$M9-1) | Q9: =IF(NOT(ISNUMBER($P9)),"",IFERROR(PERCENTRANK($P$5:$P$1204,$P9),""))
A10: 45577 | B10: 1403/07/21 | C10: 617602030 | D10: 617680882 | E10: 616879688 | F10: 0 | G10: =IF($A10="","",IF(ISNUMBER($G9),$G9+1,1)) -> 6 | H10: =IF(OR(NOT(ISNUMBER($G10)),$G10<2,NOT(ISNUMBER($C9)),$C9=0),"",$C10/$C9-1) -> -0.0081966671 | I10: =IF(AND(ISNUMBER($G10),$G10>=MA_SHORT),AVERAGE(INDEX($C$5:$C10,7-MA_SHORT):$C10),"") | J10: =IF(AND(ISNUMBER($G10),$G10>=MA_MED),AVERAGE(INDEX($C$5:$C10,7-MA_MED):$C10),"") | K10: =IF(AND(ISNUMBER($G10),$G10>=MA_LONG2),AVERAGE(INDEX($C$5:$C10,7-MA_LONG2):$C10),"") | L10: =IF(AND(ISNUMBER($G10),$G10>=21),STDEV(INDEX($H$5:$H10,7-20):$H10)*SQRT(245),"") | M10: =IF(AND(ISNUMBER($G10),$G10>=60),MAX(INDEX($D$5:$D10,7-60):$D10),"") | N10: =IF(AND(ISNUMBER($G10),$G10>=60),MIN(INDEX($E$5:$E10,7-60):$E10),"") | O10: =IF(OR(NOT(ISNUMBER($C10)),NOT(ISNUMBER($M10)),$M10=0),"",$C10/$M10-1) | Q10: =IF(NOT(ISNUMBER($P10)),"",IFERROR(PERCENTRANK($P$5:$P$1204,$P10),""))
A11: 45578 | B11: 1403/07/22 | C11: 631310081 | D11: 631373473 | E11: 628839340 | F11: 0 | G11: =IF($A11="","",IF(ISNUMBER($G10),$G10+1,1)) -> 7 | H11: =IF(OR(NOT(ISNUMBER($G11)),$G11<2,NOT(ISNUMBER($C10)),$C10=0),"",$C11/$C10-1) -> 0.022195605 | I11: =IF(AND(ISNUMBER($G11),$G11>=MA_SHORT),AVERAGE(INDEX($C$5:$C11,8-MA_SHORT):$C11),"") | J11: =IF(AND(ISNUMBER($G11),$G11>=MA_MED),AVERAGE(INDEX($C$5:$C11,8-MA_MED):$C11),"") | K11: =IF(AND(ISNUMBER($G11),$G11>=MA_LONG2),AVERAGE(INDEX($C$5:$C11,8-MA_LONG2):$C11),"") | L11: =IF(AND(ISNUMBER($G11),$G11>=21),STDEV(INDEX($H$5:$H11,8-20):$H11)*SQRT(245),"") | M11: =IF(AND(ISNUMBER($G11),$G11>=60),MAX(INDEX($D$5:$D11,8-60):$D11),"") | N11: =IF(AND(ISNUMBER($G11),$G11>=60),MIN(INDEX($E$5:$E11,8-60):$E11),"") | O11: =IF(OR(NOT(ISNUMBER($C11)),NOT(ISNUMBER($M11)),$M11=0),"",$C11/$M11-1) | Q11: =IF(NOT(ISNUMBER($P11)),"",IFERROR(PERCENTRANK($P$5:$P$1204,$P11),""))
A12: 45579 | B12: 1403/07/23 | C12: 623852340 | D12: 626030304 | E12: 623378852 | F12: 0 | G12: =IF($A12="","",IF(ISNUMBER($G11),$G11+1,1)) -> 8 | H12: =IF(OR(NOT(ISNUMBER($G12)),$G12<2,NOT(ISNUMBER($C11)),$C11=0),"",$C12/$C11-1) -> -0.011813119 | I12: =IF(AND(ISNUMBER($G12),$G12>=MA_SHORT),AVERAGE(INDEX($C$5:$C12,9-MA_SHORT):$C12),"") | J12: =IF(AND(ISNUMBER($G12),$G12>=MA_MED),AVERAGE(INDEX($C$5:$C12,9-MA_MED):$C12),"") | K12: =IF(AND(ISNUMBER($G12),$G12>=MA_LONG2),AVERAGE(INDEX($C$5:$C12,9-MA_LONG2):$C12),"") | L12: =IF(AND(ISNUMBER($G12),$G12>=21),STDEV(INDEX($H$5:$H12,9-20):$H12)*SQRT(245),"") | M12: =IF(AND(ISNUMBER($G12),$G12>=60),MAX(INDEX($D$5:$D12,9-60):$D12),"") | N12: =IF(AND(ISNUMBER($G12),$G12>=60),MIN(INDEX($E$5:$E12,9-60):$E12),"") | O12: =IF(OR(NOT(ISNUMBER($C12)),NOT(ISNUMBER($M12)),$M12=0),"",$C12/$M12-1) | Q12: =IF(NOT(ISNUMBER($P12)),"",IFERROR(PERCENTRANK($P$5:$P$1204,$P12),""))
A13: 45580 | B13: 1403/07/24 | C13: 620390455 | D13: 620409390 | E13: 618118873 | F13: 0 | G13: =IF($A13="","",IF(ISNUMBER($G12),$G12+1,1)) -> 9 | H13: =IF(OR(NOT(ISNUMBER($G13)),$G13<2,NOT(ISNUMBER($C12)),$C12=0),"",$C13/$C12-1) -> -0.0055492058 | I13: =IF(AND(ISNUMBER($G13),$G13>=MA_SHORT),AVERAGE(INDEX($C$5:$C13,10-MA_SHORT):$C13),"") | J13: =IF(AND(ISNUMBER($G13),$G13>=MA_MED),AVERAGE(INDEX($C$5:$C13,10-MA_MED):$C13),"") | K13: =IF(AND(ISNUMBER($G13),$G13>=MA_LONG2),AVERAGE(INDEX($C$5:$C13,10-MA_LONG2):$C13),"") | L13: =IF(AND(ISNUMBER($G13),$G13>=21),STDEV(INDEX($H$5:$H13,10-20):$H13)*SQRT(245),"") | M13: =IF(AND(ISNUMBER($G13),$G13>=60),MAX(INDEX($D$5:$D13,10-60):$D13),"") | N13: =IF(AND(ISNUMBER($G13),$G13>=60),MIN(INDEX($E$5:$E13,10-60):$E13),"") | O13: =IF(OR(NOT(ISNUMBER($C13)),NOT(ISNUMBER($M13)),$M13=0),"",$C13/$M13-1) | Q13: =IF(NOT(ISNUMBER($P13)),"",IFERROR(PERCENTRANK($P$5:$P$1204,$P13),""))
A14: 45581 | B14: 1403/07/25 | C14: 618650370 | D14: 621220352 | E14: 614878295 | F14: 0 | G14: =IF($A14="","",IF(ISNUMBER($G13),$G13+1,1)) -> 10 | H14: =IF(OR(NOT(ISNUMBER($G14)),$G14<2,NOT(ISNUMBER($C13)),$C13=0),"",$C14/$C13-1) -> -0.0028048223 | I14: =IF(AND(ISNUMBER($G14),$G14>=MA_SHORT),AVERAGE(INDEX($C$5:$C14,11-MA_SHORT):$C14),"") | J14: =IF(AND(ISNUMBER($G14),$G14>=MA_MED),AVERAGE(INDEX($C$5:$C14,11-MA_MED):$C14),"") | K14: =IF(AND(ISNUMBER($G14),$G14>=MA_LONG2),AVERAGE(INDEX($C$5:$C14,11-MA_LONG2):$C14),"") | L14: =IF(AND(ISNUMBER($G14),$G14>=21),STDEV(INDEX($H$5:$H14,11-20):$H14)*SQRT(245),"") | M14: =IF(AND(ISNUMBER($G14),$G14>=60),MAX(INDEX($D$5:$D14,11-60):$D14),"") | N14: =IF(AND(ISNUMBER($G14),$G14>=60),MIN(INDEX($E$5:$E14,11-60):$E14),"") | O14: =IF(OR(NOT(ISNUMBER($C14)),NOT(ISNUMBER($M14)),$M14=0),"",$C14/$M14-1) | Q14: =IF(NOT(ISNUMBER($P14)),"",IFERROR(PERCENTRANK($P$5:$P$1204,$P14),""))
A15: 45584 | B15: 1403/07/28 | C15: 632260662 | D15: 636359153 | E15: 629193707 | F15: 0 | G15: =IF($A15="","",IF(ISNUMBER($G14),$G14+1,1)) -> 11 | H15: =IF(OR(NOT(ISNUMBER($G15)),$G15<2,NOT(ISNUMBER($C14)),$C14=0),"",$C15/$C14-1) -> 0.021999974 | I15: =IF(AND(ISNUMBER($G15),$G15>=MA_SHORT),AVERAGE(INDEX($C$5:$C15,12-MA_SHORT):$C15),"") | J15: =IF(AND(ISNUMBER($G15),$G15>=MA_MED),AVERAGE(INDEX($C$5:$C15,12-MA_MED):$C15),"") | K15: =IF(AND(ISNUMBER($G15),$G15>=MA_LONG2),AVERAGE(INDEX($C$5:$C15,12-MA_LONG2):$C15),"") | L15: =IF(AND(ISNUMBER($G15),$G15>=21),STDEV(INDEX($H$5:$H15,12-20):$H15)*SQRT(245),"") | M15: =IF(AND(ISNUMBER($G15),$G15>=60),MAX(INDEX($D$5:$D15,12-60):$D15),"") | N15: =IF(AND(ISNUMBER($G15),$G15>=60),MIN(INDEX($E$5:$E15,12-60):$E15),"") | O15: =IF(OR(NOT(ISNUMBER($C15)),NOT(ISNUMBER($M15)),$M15=0),"",$C15/$M15-1) | Q15: =IF(NOT(ISNUMBER($P15)),"",IFERROR(PERCENTRANK($P$5:$P$1204,$P15),""))
A16: 45585 | B16: 1403/07/29 | C16: 635853159 | D16: 637467624 | E16: 633409494 | F16: 0 | G16: =IF($A16="","",IF(ISNUMBER($G15),$G15+1,1)) -> 12 | H16: =IF(OR(NOT(ISNUMBER($G16)),$G16<2,NOT(ISNUMBER($C15)),$C15=0),"",$C16/$C15-1) -> 0.0056819872 | I16: =IF(AND(ISNUMBER($G16),$G16>=MA_SHORT),AVERAGE(INDEX($C$5:$C16,13-MA_SHORT):$C16),"") | J16: =IF(AND(ISNUMBER($G16),$G16>=MA_MED),AVERAGE(INDEX($C$5:$C16,13-MA_MED):$C16),"") | K16: =IF(AND(ISNUMBER($G16),$G16>=MA_LONG2),AVERAGE(INDEX($C$5:$C16,13-MA_LONG2):$C16),"") | L16: =IF(AND(ISNUMBER($G16),$G16>=21),STDEV(INDEX($H$5:$H16,13-20):$H16)*SQRT(245),"") | M16: =IF(AND(ISNUMBER($G16),$G16>=60),MAX(INDEX($D$5:$D16,13-60):$D16),"") | N16: =IF(AND(ISNUMBER($G16),$G16>=60),MIN(INDEX($E$5:$E16,13-60):$E16),"") | O16: =IF(OR(NOT(ISNUMBER($C16)),NOT(ISNUMBER($M16)),$M16=0),"",$C16/$M16-1) | Q16: =IF(NOT(ISNUMBER($P16)),"",IFERROR(PERCENTRANK($P$5:$P$1204,$P16),""))
A17: 45586 | B17: 1403/07/30 | C17: 637303526 | D17: 637950489 | E17: 636062214 | F17: 0 | G17: =IF($A17="","",IF(ISNUMBER($G16),$G16+1,1)) -> 13 | H17: =IF(OR(NOT(ISNUMBER($G17)),$G17<2,NOT(ISNUMBER($C16)),$C16=0),"",$C17/$C16-1) -> 0.0022809779 | I17: =IF(AND(ISNUMBER($G17),$G17>=MA_SHORT),AVERAGE(INDEX($C$5:$C17,14-MA_SHORT):$C17),"") | J17: =IF(AND(ISNUMBER($G17),$G17>=MA_MED),AVERAGE(INDEX($C$5:$C17,14-MA_MED):$C17),"") | K17: =IF(AND(ISNUMBER($G17),$G17>=MA_LONG2),AVERAGE(INDEX($C$5:$C17,14-MA_LONG2):$C17),"") | L17: =IF(AND(ISNUMBER($G17),$G17>=21),STDEV(INDEX($H$5:$H17,14-20):$H17)*SQRT(245),"") | M17: =IF(AND(ISNUMBER($G17),$G17>=60),MAX(INDEX($D$5:$D17,14-60):$D17),"") | N17: =IF(AND(ISNUMBER($G17),$G17>=60),MIN(INDEX($E$5:$E17,14-60):$E17),"") | O17: =IF(OR(NOT(ISNUMBER($C17)),NOT(ISNUMBER($M17)),$M17=0),"",$C17/$M17-1) | Q17: =IF(NOT(ISNUMBER($P17)),"",IFERROR(PERCENTRANK($P$5:$P$1204,$P17),""))
A18: 45587 | B18: 1403/08/01 | C18: 633352131 | D18: 633679591 | E18: 631650592 | F18: 0 | G18: =IF($A18="","",IF(ISNUMBER($G17),$G17+1,1)) -> 14 | H18: =IF(OR(NOT(ISNUMBER($G18)),$G18<2,NOT(ISNUMBER($C17)),$C17=0),"",$C18/$C17-1) -> -0.0062001775 | I18: =IF(AND(ISNUMBER($G18),$G18>=MA_SHORT),AVERAGE(INDEX($C$5:$C18,15-MA_SHORT):$C18),"") | J18: =IF(AND(ISNUMBER($G18),$G18>=MA_MED),AVERAGE(INDEX($C$5:$C18,15-MA_MED):$C18),"") | K18: =IF(AND(ISNUMBER($G18),$G18>=MA_LONG2),AVERAGE(INDEX($C$5:$C18,15-MA_LONG2):$C18),"") | L18: =IF(AND(ISNUMBER($G18),$G18>=21),STDEV(INDEX($H$5:$H18,15-20):$H18)*SQRT(245),"") | M18: =IF(AND(ISNUMBER($G18),$G18>=60),MAX(INDEX($D$5:$D18,15-60):$D18),"") | N18: =IF(AND(ISNUMBER($G18),$G18>=60),MIN(INDEX($E$5:$E18,15-60):$E18),"") | O18: =IF(OR(NOT(ISNUMBER($C18)),NOT(ISNUMBER($M18)),$M18=0),"",$C18/$M18-1) | Q18: =IF(NOT(ISNUMBER($P18)),"",IFERROR(PERCENTRANK($P$5:$P$1204,$P18),""))
A19: 45588 | B19: 1403/08/02 | C19: 651030125 | D19: 652105753 | E19: 650897125 | F19: 0 | G19: =IF($A19="","",IF(ISNUMBER($G18),$G18+1,1)) -> 15 | H19: =IF(OR(NOT(ISNUMBER($G19)),$G19<2,NOT(ISNUMBER($C18)),$C18=0),"",$C19/$C18-1) -> 0.027911794 | I19: =IF(AND(ISNUMBER($G19),$G19>=MA_SHORT),AVERAGE(INDEX($C$5:$C19,16-MA_SHORT):$C19),"") | J19: =IF(AND(ISNUMBER($G19),$G19>=MA_MED),AVERAGE(INDEX($C$5:$C19,16-MA_MED):$C19),"") | K19: =IF(AND(ISNUMBER($G19),$G19>=MA_LONG2),AVERAGE(INDEX($C$5:$C19,16-MA_LONG2):$C19),"") | L19: =IF(AND(ISNUMBER($G19),$G19>=21),STDEV(INDEX($H$5:$H19,16-20):$H19)*SQRT(245),"") | M19: =IF(AND(ISNUMBER($G19),$G19>=60),MAX(INDEX($D$5:$D19,16-60):$D19),"") | N19: =IF(AND(ISNUMBER($G19),$G19>=60),MIN(INDEX($E$5:$E19,16-60):$E19),"") | O19: =IF(OR(NOT(ISNUMBER($C19)),NOT(ISNUMBER($M19)),$M19=0),"",$C19/$M19-1) | Q19: =IF(NOT(ISNUMBER($P19)),"",IFERROR(PERCENTRANK($P$5:$P$1204,$P19),""))
A20: 45591 | B20: 1403/08/05 | C20: 637265592 | D20: 640869489 | E20: 635261693 | F20: 0 | G20: =IF($A20="","",IF(ISNUMBER($G19),$G19+1,1)) -> 16 | H20: =IF(OR(NOT(ISNUMBER($G20)),$G20<2,NOT(ISNUMBER($C19)),$C19=0),"",$C20/$C19-1) -> -0.021142698 | I20: =IF(AND(ISNUMBER($G20),$G20>=MA_SHORT),AVERAGE(INDEX($C$5:$C20,17-MA_SHORT):$C20),"") | J20: =IF(AND(ISNUMBER($G20),$G20>=MA_MED),AVERAGE(INDEX($C$5:$C20,17-MA_MED):$C20),"") | K20: =IF(AND(ISNUMBER($G20),$G20>=MA_LONG2),AVERAGE(INDEX($C$5:$C20,17-MA_LONG2):$C20),"") | L20: =IF(AND(ISNUMBER($G20),$G20>=21),STDEV(INDEX($H$5:$H20,17-20):$H20)*SQRT(245),"") | M20: =IF(AND(ISNUMBER($G20),$G20>=60),MAX(INDEX($D$5:$D20,17-60):$D20),"") | N20: =IF(AND(ISNUMBER($G20),$G20>=60),MIN(INDEX($E$5:$E20,17-60):$E20),"") | O20: =IF(OR(NOT(ISNUMBER($C20)),NOT(ISNUMBER($M20)),$M20=0),"",$C20/$M20-1) | Q20: =IF(NOT(ISNUMBER($P20)),"",IFERROR(PERCENTRANK($P$5:$P$1204,$P20),""))
A21: 45592 | B21: 1403/08/06 | C21: 644606995 | D21: 646647680 | E21: 643803172 | F21: 0 | G21: =IF($A21="","",IF(ISNUMBER($G20),$G20+1,1)) -> 17 | H21: =IF(OR(NOT(ISNUMBER($G21)),$G21<2,NOT(ISNUMBER($C20)),$C20=0),"",$C21/$C20-1) -> 0.011520162 | I21: =IF(AND(ISNUMBER($G21),$G21>=MA_SHORT),AVERAGE(INDEX($C$5:$C21,18-MA_SHORT):$C21),"") | J21: =IF(AND(ISNUMBER($G21),$G21>=MA_MED),AVERAGE(INDEX($C$5:$C21,18-MA_MED):$C21),"") | K21: =IF(AND(ISNUMBER($G21),$G21>=MA_LONG2),AVERAGE(INDEX($C$5:$C21,18-MA_LONG2):$C21),"") | L21: =IF(AND(ISNUMBER($G21),$G21>=21),STDEV(INDEX($H$5:$H21,18-20):$H21)*SQRT(245),"") | M21: =IF(AND(ISNUMBER($G21),$G21>=60),MAX(INDEX($D$5:$D21,18-60):$D21),"") | N21: =IF(AND(ISNUMBER($G21),$G21>=60),MIN(INDEX($E$5:$E21,18-60):$E21),"") | O21: =IF(OR(NOT(ISNUMBER($C21)),NOT(ISNUMBER($M21)),$M21=0),"",$C21/$M21-1) | Q21: =IF(NOT(ISNUMBER($P21)),"",IFERROR(PERCENTRANK($P$5:$P$1204,$P21),""))
A22: 45593 | B22: 1403/08/07 | C22: 640216798 | D22: 644958753 | E22: 637731468 | F22: 0 | G22: =IF($A22="","",IF(ISNUMBER($G21),$G21+1,1)) -> 18 | H22: =IF(OR(NOT(ISNUMBER($G22)),$G22<2,NOT(ISNUMBER($C21)),$C21=0),"",$C22/$C21-1) -> -0.0068106568 | I22: =IF(AND(ISNUMBER($G22),$G22>=MA_SHORT),AVERAGE(INDEX($C$5:$C22,19-MA_SHORT):$C22),"") | J22: =IF(AND(ISNUMBER($G22),$G22>=MA_MED),AVERAGE(INDEX($C$5:$C22,19-MA_MED):$C22),"") | K22: =IF(AND(ISNUMBER($G22),$G22>=MA_LONG2),AVERAGE(INDEX($C$5:$C22,19-MA_LONG2):$C22),"") | L22: =IF(AND(ISNUMBER($G22),$G22>=21),STDEV(INDEX($H$5:$H22,19-20):$H22)*SQRT(245),"") | M22: =IF(AND(ISNUMBER($G22),$G22>=60),MAX(INDEX($D$5:$D22,19-60):$D22),"") | N22: =IF(AND(ISNUMBER($G22),$G22>=60),MIN(INDEX($E$5:$E22,19-60):$E22),"") | O22: =IF(OR(NOT(ISNUMBER($C22)),NOT(ISNUMBER($M22)),$M22=0),"",$C22/$M22-1) | Q22: =IF(NOT(ISNUMBER($P22)),"",IFERROR(PERCENTRANK($P$5:$P$1204,$P22),""))
A23: 45594 | B23: 1403/08/08 | C23: 634103994 | D23: 635404835 | E23: 631715968 | F23: 0 | G23: =IF($A23="","",IF(ISNUMBER($G22),$G22+1,1)) -> 19 | H23: =IF(OR(NOT(ISNUMBER($G23)),$G23<2,NOT(ISNUMBER($C22)),$C22=0),"",$C23/$C22-1) -> -0.0095480219 | I23: =IF(AND(ISNUMBER($G23),$G23>=MA_SHORT),AVERAGE(INDEX($C$5:$C23,20-MA_SHORT):$C23),"") | J23: =IF(AND(ISNUMBER($G23),$G23>=MA_MED),AVERAGE(INDEX($C$5:$C23,20-MA_MED):$C23),"") | K23: =IF(AND(ISNUMBER($G23),$G23>=MA_LONG2),AVERAGE(INDEX($C$5:$C23,20-MA_LONG2):$C23),"") | L23: =IF(AND(ISNUMBER($G23),$G23>=21),STDEV(INDEX($H$5:$H23,20-20):$H23)*SQRT(245),"") | M23: =IF(AND(ISNUMBER($G23),$G23>=60),MAX(INDEX($D$5:$D23,20-60):$D23),"") | N23: =IF(AND(ISNUMBER($G23),$G23>=60),MIN(INDEX($E$5:$E23,20-60):$E23),"") | O23: =IF(OR(NOT(ISNUMBER($C23)),NOT(ISNUMBER($M23)),$M23=0),"",$C23/$M23-1) | Q23: =IF(NOT(ISNUMBER($P23)),"",IFERROR(PERCENTRANK($P$5:$P$1204,$P23),""))
A24: 45595 | B24: 1403/08/09 | C24: 637125355 | D24: 639643641 | E24: 637043723 | F24: 0 | G24: =IF($A24="","",IF(ISNUMBER($G23),$G23+1,1)) -> 20 | H24: =IF(OR(NOT(ISNUMBER($G24)),$G24<2,NOT(ISNUMBER($C23)),$C23=0),"",$C24/$C23-1) -> 0.0047647721 | I24: =IF(AND(ISNUMBER($G24),$G24>=MA_SHORT),AVERAGE(INDEX($C$5:$C24,21-MA_SHORT):$C24),"") -> 6.3070484e+08 | J24: =IF(AND(ISNUMBER($G24),$G24>=MA_MED),AVERAGE(INDEX($C$5:$C24,21-MA_MED):$C24),"") | K24: =IF(AND(ISNUMBER($G24),$G24>=MA_LONG2),AVERAGE(INDEX($C$5:$C24,21-MA_LONG2):$C24),"") | L24: =IF(AND(ISNUMBER($G24),$G24>=21),STDEV(INDEX($H$5:$H24,21-20):$H24)*SQRT(245),"") | M24: =IF(AND(ISNUMBER($G24),$G24>=60),MAX(INDEX($D$5:$D24,21-60):$D24),"") | N24: =IF(AND(ISNUMBER($G24),$G24>=60),MIN(INDEX($E$5:$E24,21-60):$E24),"") | O24: =IF(OR(NOT(ISNUMBER($C24)),NOT(ISNUMBER($M24)),$M24=0),"",$C24/$M24-1) | Q24: =IF(NOT(ISNUMBER($P24)),"",IFERROR(PERCENTRANK($P$5:$P$1204,$P24),""))
A25: 45598 | B25: 1403/08/12 | C25: 641311840 | D25: 641502330 | E25: 639706632 | F25: 0 | G25: =IF($A25="","",IF(ISNUMBER($G24),$G24+1,1)) -> 21 | H25: =IF(OR(NOT(ISNUMBER($G25)),$G25<2,NOT(ISNUMBER($C24)),$C24=0),"",$C25/$C24-1) -> 0.0065708969 | I25: =IF(AND(ISNUMBER($G25),$G25>=MA_SHORT),AVERAGE(INDEX($C$5:$C25,22-MA_SHORT):$C25),"") -> 6.314285e+08 | J25: =IF(AND(ISNUMBER($G25),$G25>=MA_MED),AVERAGE(INDEX($C$5:$C25,22-MA_MED):$C25),"") | K25: =IF(AND(ISNUMBER($G25),$G25>=MA_LONG2),AVERAGE(INDEX($C$5:$C25,22-MA_LONG2):$C25),"") | L25: =IF(AND(ISNUMBER($G25),$G25>=21),STDEV(INDEX($H$5:$H25,22-20):$H25)*SQRT(245),"") -> 0.19630097 | M25: =IF(AND(ISNUMBER($G25),$G25>=60),MAX(INDEX($D$5:$D25,22-60):$D25),"") | N25: =IF(AND(ISNUMBER($G25),$G25>=60),MIN(INDEX($E$5:$E25,22-60):$E25),"") | O25: =IF(OR(NOT(ISNUMBER($C25)),NOT(ISNUMBER($M25)),$M25=0),"",$C25/$M25-1) | Q25: =IF(NOT(ISNUMBER($P25)),"",IFERROR(PERCENTRANK($P$5:$P$1204,$P25),""))
A26: 45599 | B26: 1403/08/13 | C26: 616216450 | D26: 619082365 | E26: 616144601 | F26: 0 | G26: =IF($A26="","",IF(ISNUMBER($G25),$G25+1,1)) -> 22 | H26: =IF(OR(NOT(ISNUMBER($G26)),$G26<2,NOT(ISNUMBER($C25)),$C25=0),"",$C26/$C25-1) -> -0.039131337 | I26: =IF(AND(ISNUMBER($G26),$G26>=MA_SHORT),AVERAGE(INDEX($C$5:$C26,23-MA_SHORT):$C26),"") -> 6.3121823e+08 | J26: =IF(AND(ISNUMBER($G26),$G26>=MA_MED),AVERAGE(INDEX($C$5:$C26,23-MA_MED):$C26),"") | K26: =IF(AND(ISNUMBER($G26),$G26>=MA_LONG2),AVERAGE(INDEX($C$5:$C26,23-MA_LONG2):$C26),"") | L26: =IF(AND(ISNUMBER($G26),$G26>=21),STDEV(INDEX($H$5:$H26,23-20):$H26)*SQRT(245),"") -> 0.23936579 | M26: =IF(AND(ISNUMBER($G26),$G26>=60),MAX(INDEX($D$5:$D26,23-60):$D26),"") | N26: =IF(AND(ISNUMBER($G26),$G26>=60),MIN(INDEX($E$5:$E26,23-60):$E26),"") | O26: =IF(OR(NOT(ISNUMBER($C26)),NOT(ISNUMBER($M26)),$M26=0),"",$C26/$M26-1) | Q26: =IF(NOT(ISNUMBER($P26)),"",IFERROR(PERCENTRANK($P$5:$P$1204,$P26),""))
A27: 45600 | B27: 1403/08/14 | C27: 604129498 | D27: 605379975 | E27: 603550631 | F27: 0 | G27: =IF($A27="","",IF(ISNUMBER($G26),$G26+1,1)) -> 23 | H27: =IF(OR(NOT(ISNUMBER($G27)),$G27<2,NOT(ISNUMBER($C26)),$C26=0),"",$C27/$C26-1) -> -0.019614783 | I27: =IF(AND(ISNUMBER($G27),$G27>=MA_SHORT),AVERAGE(INDEX($C$5:$C27,24-MA_SHORT):$C27),"") -> 630203836 | J27: =IF(AND(ISNUMBER($G27),$G27>=MA_MED),AVERAGE(INDEX($C$5:$C27,24-MA_MED):$C27),"") | K27: =IF(AND(ISNUMBER($G27),$G27>=MA_LONG2),AVERAGE(INDEX($C$5:$C27,24-MA_LONG2):$C27),"") | L27: =IF(AND(ISNUMBER($G27),$G27>=21),STDEV(INDEX($H$5:$H27,24-20):$H27)*SQRT(245),"") -> 0.24724693 | M27: =IF(AND(ISNUMBER($G27),$G27>=60),MAX(INDEX($D$5:$D27,24-60):$D27),"") | N27: =IF(AND(ISNUMBER($G27),$G27>=60),MIN(INDEX($E$5:$E27,24-60):$E27),"") | O27: =IF(OR(NOT(ISNUMBER($C27)),NOT(ISNUMBER($M27)),$M27=0),"",$C27/$M27-1) | Q27: =IF(NOT(ISNUMBER($P27)),"",IFERROR(PERCENTRANK($P$5:$P$1204,$P27),""))
A28: 45601 | B28: 1403/08/15 | C28: 615269021 | D28: 618490724 | E28: 614075019 | F28: 0 | G28: =IF($A28="","",IF(ISNUMBER($G27),$G27+1,1)) -> 24 | H28: =IF(OR(NOT(ISNUMBER($G28)),$G28<2,NOT(ISNUMBER($C27)),$C27=0),"",$C28/$C27-1) -> 0.018438966 | I28: =IF(AND(ISNUMBER($G28),$G28>=MA_SHORT),AVERAGE(INDEX($C$5:$C28,25-MA_SHORT):$C28),"") -> 6.2972783e+08 | J28: =IF(AND(ISNUMBER($G28),$G28>=MA_MED),AVERAGE(INDEX($C$5:$C28,25-MA_MED):$C28),"") | K28: =IF(AND(ISNUMBER($G28),$G28>=MA_LONG2),AVERAGE(INDEX($C$5:$C28,25-MA_LONG2):$C28),"") | L28: =IF(AND(ISNUMBER($G28),$G28>=21),STDEV(INDEX($H$5:$H28,25-20):$H28)*SQRT(245),"") -> 0.25692405 | M28: =IF(AND(ISNUMBER($G28),$G28>=60),MAX(INDEX($D$5:$D28,25-60):$D28),"") | N28: =IF(AND(ISNUMBER($G28),$G28>=60),MIN(INDEX($E$5:$E28,25-60):$E28),"") | O28: =IF(OR(NOT(ISNUMBER($C28)),NOT(ISNUMBER($M28)),$M28=0),"",$C28/$M28-1) | Q28: =IF(NOT(ISNUMBER($P28)),"",IFERROR(PERCENTRANK($P$5:$P$1204,$P28),""))
A29: 45602 | B29: 1403/08/16 | C29: 617883526 | D29: 619251828 | E29: 614610898 | F29: 0 | G29: =IF($A29="","",IF(ISNUMBER($G28),$G28+1,1)) -> 25 | H29: =IF(OR(NOT(ISNUMBER($G29)),$G29<2,NOT(ISNUMBER($C28)),$C28=0),"",$C29/$C28-1) -> 0.0042493688 | I29: =IF(AND(ISNUMBER($G29),$G29>=MA_SHORT),AVERAGE(INDEX($C$5:$C29,26-MA_SHORT):$C29),"") -> 6.294867e+08 | J29: =IF(AND(ISNUMBER($G29),$G29>=MA_MED),AVERAGE(INDEX($C$5:$C29,26-MA_MED):$C29),"") | K29: =IF(AND(ISNUMBER($G29),$G29>=MA_LONG2),AVERAGE(INDEX($C$5:$C29,26-MA_LONG2):$C29),"") | L29: =IF(AND(ISNUMBER($G29),$G29>=21),STDEV(INDEX($H$5:$H29,26-20):$H29)*SQRT(245),"") -> 0.25726907 | M29: =IF(AND(ISNUMBER($G29),$G29>=60),MAX(INDEX($D$5:$D29,26-60):$D29),"") | N29: =IF(AND(ISNUMBER($G29),$G29>=60),MIN(INDEX($E$5:$E29,26-60):$E29),"") | O29: =IF(OR(NOT(ISNUMBER($C29)),NOT(ISNUMBER($M29)),$M29=0),"",$C29/$M29-1) | Q29: =IF(NOT(ISNUMBER($P29)),"",IFERROR(PERCENTRANK($P$5:$P$1204,$P29),""))
A30: 45605 | B30: 1403/08/19 | C30: 633431119 | D30: 635380345 | E30: 630624546 | F30: 0 | G30: =IF($A30="","",IF(ISNUMBER($G29),$G29+1,1)) -> 26 | H30: =IF(OR(NOT(ISNUMBER($G30)),$G30<2,NOT(ISNUMBER($C29)),$C29=0),"",$C30/$C29-1) -> 0.02516266 | I30: =IF(AND(ISNUMBER($G30),$G30>=MA_SHORT),AVERAGE(INDEX($C$5:$C30,27-MA_SHORT):$C30),"") -> 6.3027815e+08 | J30: =IF(AND(ISNUMBER($G30),$G30>=MA_MED),AVERAGE(INDEX($C$5:$C30,27-MA_MED):$C30),"") | K30: =IF(AND(ISNUMBER($G30),$G30>=MA_LONG2),AVERAGE(INDEX($C$5:$C30,27-MA_LONG2):$C30),"") | L30: =IF(AND(ISNUMBER($G30),$G30>=21),STDEV(INDEX($H$5:$H30,27-20):$H30)*SQRT(245),"") -> 0.27016944 | M30: =IF(AND(ISNUMBER($G30),$G30>=60),MAX(INDEX($D$5:$D30,27-60):$D30),"") | N30: =IF(AND(ISNUMBER($G30),$G30>=60),MIN(INDEX($E$5:$E30,27-60):$E30),"") | O30: =IF(OR(NOT(ISNUMBER($C30)),NOT(ISNUMBER($M30)),$M30=0),"",$C30/$M30-1) | Q30: =IF(NOT(ISNUMBER($P30)),"",IFERROR(PERCENTRANK($P$5:$P$1204,$P30),""))
A31: 45606 | B31: 1403/08/20 | C31: 632662194 | D31: 633769817 | E31: 628411969 | F31: 0 | G31: =IF($A31="","",IF(ISNUMBER($G30),$G30+1,1)) -> 27 | H31: =IF(OR(NOT(ISNUMBER($G31)),$G31<2,NOT(ISNUMBER($C30)),$C30=0),"",$C31/$C30-1) -> -0.0012139047 | I31: =IF(AND(ISNUMBER($G31),$G31>=MA_SHORT),AVERAGE(INDEX($C$5:$C31,28-MA_SHORT):$C31),"") -> 6.3034576e+08 | J31: =IF(AND(ISNUMBER($G31),$G31>=MA_MED),AVERAGE(INDEX($C$5:$C31,28-MA_MED):$C31),"") | K31: =IF(AND(ISNUMBER($G31),$G31>=MA_LONG2),AVERAGE(INDEX($C$5:$C31,28-MA_LONG2):$C31),"") | L31: =IF(AND(ISNUMBER($G31),$G31>=21),STDEV(INDEX($H$5:$H31,28-20):$H31)*SQRT(245),"") -> 0.25914241 | M31: =IF(AND(ISNUMBER($G31),$G31>=60),MAX(INDEX($D$5:$D31,28-60):$D31),"") | N31: =IF(AND(ISNUMBER($G31),$G31>=60),MIN(INDEX($E$5:$E31,28-60):$E31),"") | O31: =IF(OR(NOT(ISNUMBER($C31)),NOT(ISNUMBER($M31)),$M31=0),"",$C31/$M31-1) | Q31: =IF(NOT(ISNUMBER($P31)),"",IFERROR(PERCENTRANK($P$5:$P$1204,$P31),""))
A32: 45607 | B32: 1403/08/21 | C32: 639275580 | D32: 639694350 | E32: 636832524 | F32: 0 | G32: =IF($A32="","",IF(ISNUMBER($G31),$G31+1,1)) -> 28 | H32: =IF(OR(NOT(ISNUMBER($G32)),$G32<2,NOT(ISNUMBER($C31)),$C31=0),"",$C32/$C31-1) -> 0.010453266 | I32: =IF(AND(ISNUMBER($G32),$G32>=MA_SHORT),AVERAGE(INDEX($C$5:$C32,29-MA_SHORT):$C32),"") -> 6.3111692e+08 | J32: =IF(AND(ISNUMBER($G32),$G32>=MA_MED),AVERAGE(INDEX($C$5:$C32,29-MA_MED):$C32),"") | K32: =IF(AND(ISNUMBER($G32),$G32>=MA_LONG2),AVERAGE(INDEX($C$5:$C32,29-MA_LONG2):$C32),"") | L32: =IF(AND(ISNUMBER($G32),$G32>=21),STDEV(INDEX($H$5:$H32,29-20):$H32)*SQRT(245),"") -> 0.25750384 | M32: =IF(AND(ISNUMBER($G32),$G32>=60),MAX(INDEX($D$5:$D32,29-60):$D32),"") | N32: =IF(AND(ISNUMBER($G32),$G32>=60),MIN(INDEX($E$5:$E32,29-60):$E32),"") | O32: =IF(OR(NOT(ISNUMBER($C32)),NOT(ISNUMBER($M32)),$M32=0),"",$C32/$M32-1) | Q32: =IF(NOT(ISNUMBER($P32)),"",IFERROR(PERCENTRANK($P$5:$P$1204,$P32),""))
A33: 45608 | B33: 1403/08/22 | C33: 634778073 | D33: 638260286 | E33: 629631198 | F33: 0 | G33: =IF($A33="","",IF(ISNUMBER($G32),$G32+1,1)) -> 29 | H33: =IF(OR(NOT(ISNUMBER($G33)),$G33<2,NOT(ISNUMBER($C32)),$C32=0),"",$C33/$C32-1) -> -0.007035318 | I33: =IF(AND(ISNUMBER($G33),$G33>=MA_SHORT),AVERAGE(INDEX($C$5:$C33,30-MA_SHORT):$C33),"") -> 6.318363e+08 | J33: =IF(AND(ISNUMBER($G33),$G33>=MA_MED),AVERAGE(INDEX($C$5:$C33,30-MA_MED):$C33),"") | K33: =IF(AND(ISNUMBER($G33),$G33>=MA_LONG2),AVERAGE(INDEX($C$5:$C33,30-MA_LONG2):$C33),"") | L33: =IF(AND(ISNUMBER($G33),$G33>=21),STDEV(INDEX($H$5:$H33,30-20):$H33)*SQRT(245),"") -> 0.25806925 | M33: =IF(AND(ISNUMBER($G33),$G33>=60),MAX(INDEX($D$5:$D33,30-60):$D33),"") | N33: =IF(AND(ISNUMBER($G33),$G33>=60),MIN(INDEX($E$5:$E33,30-60):$E33),"") | O33: =IF(OR(NOT(ISNUMBER($C33)),NOT(ISNUMBER($M33)),$M33=0),"",$C33/$M33-1) | Q33: =IF(NOT(ISNUMBER($P33)),"",IFERROR(PERCENTRANK($P$5:$P$1204,$P33),""))
A34: 45609 | B34: 1403/08/23 | C34: 622985857 | D34: 629235422 | E34: 618853324 | F34: 0 | G34: =IF($A34="","",IF(ISNUMBER($G33),$G33+1,1)) -> 30 | H34: =IF(OR(NOT(ISNUMBER($G34)),$G34<2,NOT(ISNUMBER($C33)),$C33=0),"",$C34/$C33-1) -> -0.018576911 | I34: =IF(AND(ISNUMBER($G34),$G34>=MA_SHORT),AVERAGE(INDEX($C$5:$C34,31-MA_SHORT):$C34),"") -> 6.3205307e+08 | J34: =IF(AND(ISNUMBER($G34),$G34>=MA_MED),AVERAGE(INDEX($C$5:$C34,31-MA_MED):$C34),"") | K34: =IF(AND(ISNUMBER($G34),$G34>=MA_LONG2),AVERAGE(INDEX($C$5:$C34,31-MA_LONG2):$C34),"") | L34: =IF(AND(ISNUMBER($G34),$G34>=21),STDEV(INDEX($H$5:$H34,31-20):$H34)*SQRT(245),"") -> 0.26703407 | M34: =IF(AND(ISNUMBER($G34),$G34>=60),MAX(INDEX($D$5:$D34,31-60):$D34),"") | N34: =IF(AND(ISNUMBER($G34),$G34>=60),MIN(INDEX($E$5:$E34,31-60):$E34),"") | O34: =IF(OR(NOT(ISNUMBER($C34)),NOT(ISNUMBER($M34)),$M34=0),"",$C34/$M34-1) | Q34: =IF(NOT(ISNUMBER($P34)),"",IFERROR(PERCENTRANK($P$5:$P$1204,$P34),""))
A35: 45612 | B35: 1403/08/26 | C35: 634052831 | D35: 634866159 | E35: 631864735 | F35: 0 | G35: =IF($A35="","",IF(ISNUMBER($G34),$G34+1,1)) -> 31 | H35: =IF(OR(NOT(ISNUMBER($G35)),$G35<2,NOT(ISNUMBER($C34)),$C34=0),"",$C35/$C34-1) -> 0.017764406 | I35: =IF(AND(ISNUMBER($G35),$G35>=MA_SHORT),AVERAGE(INDEX($C$5:$C35,32-MA_SHORT):$C35),"") -> 6.3214268e+08 | J35: =IF(AND(ISNUMBER($G35),$G35>=MA_MED),AVERAGE(INDEX($C$5:$C35,32-MA_MED):$C35),"") | K35: =IF(AND(ISNUMBER($G35),$G35>=MA_LONG2),AVERAGE(INDEX($C$5:$C35,32-MA_LONG2):$C35),"") | L35: =IF(AND(ISNUMBER($G35),$G35>=21),STDEV(INDEX($H$5:$H35,32-20):$H35)*SQRT(245),"") -> 0.26301548 | M35: =IF(AND(ISNUMBER($G35),$G35>=60),MAX(INDEX($D$5:$D35,32-60):$D35),"") | N35: =IF(AND(ISNUMBER($G35),$G35>=60),MIN(INDEX($E$5:$E35,32-60):$E35),"") | O35: =IF(OR(NOT(ISNUMBER($C35)),NOT(ISNUMBER($M35)),$M35=0),"",$C35/$M35-1) | Q35: =IF(NOT(ISNUMBER($P35)),"",IFERROR(PERCENTRANK($P$5:$P$1204,$P35),""))
A36: 45613 | B36: 1403/08/27 | C36: 628207170 | D36: 629550922 | E36: 626872843 | F36: 0 | G36: =IF($A36="","",IF(ISNUMBER($G35),$G35+1,1)) -> 32 | H36: =IF(OR(NOT(ISNUMBER($G36)),$G36<2,NOT(ISNUMBER($C35)),$C35=0),"",$C36/$C35-1) -> -0.0092195172 | I36: =IF(AND(ISNUMBER($G36),$G36>=MA_SHORT),AVERAGE(INDEX($C$5:$C36,33-MA_SHORT):$C36),"") -> 6.3176038e+08 | J36: =IF(AND(ISNUMBER($G36),$G36>=MA_MED),AVERAGE(INDEX($C$5:$C36,33-MA_MED):$C36),"") | K36: =IF(AND(ISNUMBER($G36),$G36>=MA_LONG2),AVERAGE(INDEX($C$5:$C36,33-MA_LONG2):$C36),"") | L36: =IF(AND(ISNUMBER($G36),$G36>=21),STDEV(INDEX($H$5:$H36,33-20):$H36)*SQRT(245),"") -> 0.26423454 | M36: =IF(AND(ISNUMBER($G36),$G36>=60),MAX(INDEX($D$5:$D36,33-60):$D36),"") | N36: =IF(AND(ISNUMBER($G36),$G36>=60),MIN(INDEX($E$5:$E36,33-60):$E36),"") | O36: =IF(OR(NOT(ISNUMBER($C36)),NOT(ISNUMBER($M36)),$M36=0),"",$C36/$M36-1) | Q36: =IF(NOT(ISNUMBER($P36)),"",IFERROR(PERCENTRANK($P$5:$P$1204,$P36),""))
A37: 45614 | B37: 1403/08/28 | C37: 632233861 | D37: 633290397 | E37: 628086366 | F37: 0 | G37: =IF($A37="","",IF(ISNUMBER($G36),$G36+1,1)) -> 33 | H37: =IF(OR(NOT(ISNUMBER($G37)),$G37<2,NOT(ISNUMBER($C36)),$C36=0),"",$C37/$C36-1) -> 0.0064098138 | I37: =IF(AND(ISNUMBER($G37),$G37>=MA_SHORT),AVERAGE(INDEX($C$5:$C37,34-MA_SHORT):$C37),"") -> 6.315069e+08 | J37: =IF(AND(ISNUMBER($G37),$G37>=MA_MED),AVERAGE(INDEX($C$5:$C37,34-MA_MED):$C37),"") | K37: =IF(AND(ISNUMBER($G37),$G37>=MA_LONG2),AVERAGE(INDEX($C$5:$C37,34-MA_LONG2):$C37),"") | L37: =IF(AND(ISNUMBER($G37),$G37>=21),STDEV(INDEX($H$5:$H37,34-20):$H37)*SQRT(245),"") -> 0.26518204 | M37: =IF(AND(ISNUMBER($G37),$G37>=60),MAX(INDEX($D$5:$D37,34-60):$D37),"") | N37: =IF(AND(ISNUMBER($G37),$G37>=60),MIN(INDEX($E$5:$E37,34-60):$E37),"") | O37: =IF(OR(NOT(ISNUMBER($C37)),NOT(ISNUMBER($M37)),$M37=0),"",$C37/$M37-1) | Q37: =IF(NOT(ISNUMBER($P37)),"",IFERROR(PERCENTRANK($P$5:$P$1204,$P37),""))
A38: 45615 | B38: 1403/08/29 | C38: 639077133 | D38: 639516836 | E38: 636173154 | F38: 0 | G38: =IF($A38="","",IF(ISNUMBER($G37),$G37+1,1)) -> 34 | H38: =IF(OR(NOT(ISNUMBER($G38)),$G38<2,NOT(ISNUMBER($C37)),$C37=0),"",$C38/$C37-1) -> 0.010823957 | I38: =IF(AND(ISNUMBER($G38),$G38>=MA_SHORT),AVERAGE(INDEX($C$5:$C38,35-MA_SHORT):$C38),"") -> 6.3179315e+08 | J38: =IF(AND(ISNUMBER($G38),$G38>=MA_MED),AVERAGE(INDEX($C$5:$C38,35-MA_MED):$C38),"") | K38: =IF(AND(ISNUMBER($G38),$G38>=MA_LONG2),AVERAGE(INDEX($C$5:$C38,35-MA_LONG2):$C38),"") | L38: =IF(AND(ISNUMBER($G38),$G38>=21),STDEV(INDEX($H$5:$H38,35-20):$H38)*SQRT(245),"") -> 0.2669548 | M38: =IF(AND(ISNUMBER($G38),$G38>=60),MAX(INDEX($D$5:$D38,35-60):$D38),"") | N38: =IF(AND(ISNUMBER($G38),$G38>=60),MIN(INDEX($E$5:$E38,35-60):$E38),"") | O38: =IF(OR(NOT(ISNUMBER($C38)),NOT(ISNUMBER($M38)),$M38=0),"",$C38/$M38-1) | Q38: =IF(NOT(ISNUMBER($P38)),"",IFERROR(PERCENTRANK($P$5:$P$1204,$P38),""))
A39: 45616 | B39: 1403/08/30 | C39: 641066058 | D39: 641783185 | E39: 640959765 | F39: 0 | G39: =IF($A39="","",IF(ISNUMBER($G38),$G38+1,1)) -> 35 | H39: =IF(OR(NOT(ISNUMBER($G39)),$G39<2,NOT(ISNUMBER($C38)),$C38=0),"",$C39/$C38-1) -> 0.003112183 | I39: =IF(AND(ISNUMBER($G39),$G39>=MA_SHORT),AVERAGE(INDEX($C$5:$C39,36-MA_SHORT):$C39),"") -> 6.3129495e+08 | J39: =IF(AND(ISNUMBER($G39),$G39>=MA_MED),AVERAGE(INDEX($C$5:$C39,36-MA_MED):$C39),"") | K39: =IF(AND(ISNUMBER($G39),$G39>=MA_LONG2),AVERAGE(INDEX($C$5:$C39,36-MA_LONG2):$C39),"") | L39: =IF(AND(ISNUMBER($G39),$G39>=21),STDEV(INDEX($H$5:$H39,36-20):$H39)*SQRT(245),"") -> 0.24763675 | M39: =IF(AND(ISNUMBER($G39),$G39>=60),MAX(INDEX($D$5:$D39,36-60):$D39),"") | N39: =IF(AND(ISNUMBER($G39),$G39>=60),MIN(INDEX($E$5:$E39,36-60):$E39),"") | O39: =IF(OR(NOT(ISNUMBER($C39)),NOT(ISNUMBER($M39)),$M39=0),"",$C39/$M39-1) | Q39: =IF(NOT(ISNUMBER($P39)),"",IFERROR(PERCENTRANK($P$5:$P$1204,$P39),""))
A40: 45619 | B40: 1403/09/03 | C40: 648529979 | D40: 649918363 | E40: 647761604 | F40: 0 | G40: =IF($A40="","",IF(ISNUMBER($G39),$G39+1,1)) -> 36 | H40: =IF(OR(NOT(ISNUMBER($G40)),$G40<2,NOT(ISNUMBER($C39)),$C39=0),"",$C40/$C39-1) -> 0.011642983 | I40: =IF(AND(ISNUMBER($G40),$G40>=MA_SHORT),AVERAGE(INDEX($C$5:$C40,37-MA_SHORT):$C40),"") -> 6.3185817e+08 | J40: =IF(AND(ISNUMBER($G40),$G40>=MA_MED),AVERAGE(INDEX($C$5:$C40,37-MA_MED):$C40),"") | K40: =IF(AND(ISNUMBER($G40),$G40>=MA_LONG2),AVERAGE(INDEX($C$5:$C40,37-MA_LONG2):$C40),"") | L40: =IF(AND(ISNUMBER($G40),$G40>=21),STDEV(INDEX($H$5:$H40,37-20):$H40)*SQRT(245),"") -> 0.23909278 | M40: =IF(AND(ISNUMBER($G40),$G40>=60),MAX(INDEX($D$5:$D40,37-60):$D40),"") | N40: =IF(AND(ISNUMBER($G40),$G40>=60),MIN(INDEX($E$5:$E40,37-60):$E40),"") | O40: =IF(OR(NOT(ISNUMBER($C40)),NOT(ISNUMBER($M40)),$M40=0),"",$C40/$M40-1) | Q40: =IF(NOT(ISNUMBER($P40)),"",IFERROR(PERCENTRANK($P$5:$P$1204,$P40),""))
...

Sheet Hist_Gram18
A1: تاریخچه روزانه طلای ۱۸ عیار
A2: با python scripts/fetch_gold_fx.py --history پر می‌شود.
A3: تاریخ میلادی | B3: تاریخ شمسی | C3: قیمت | D3: بیشترین | E3: کمترین | F3: حجم / یادداشت | G3: شمارنده | H3: بازده روزانه | I3: MA کوتاه | J3: MA میان‌مدت | K3: MA بلند | L3: نوسان ۲۰ روزه (سالانه) | M3: سقف ۶۰ روزه | N3: کف ۶۰ روزه | O3: افت از سقف | P3: حباب گرم نسبت به فلز | Q3: صدک تاریخی سنجه
A4: - | B4: - | C4: close | D4: high | E4: low | F4: volume | G4: n | H4: - | I4: MA_SHORT | J4: MA_MED | K4: MA_LONG2 | L4: - | M4: - | N4: - | O4: - | P4: پایتون | Q4: PERCENTRANK
A5: 45570 | B5: 1403/07/14 | C5: 77531609 | D5: 77684320 | E5: 77185908 | F5: 0 | G5: =IF($A5="","",IF(ISNUMBER($G4),$G4+1,1)) -> 1 | H5: =IF(OR(NOT(ISNUMBER($G5)),$G5<2,NOT(ISNUMBER($C4)),$C4=0),"",$C5/$C4-1) | I5: =IF(AND(ISNUMBER($G5),$G5>=MA_SHORT),AVERAGE(INDEX($C$5:$C5,2-MA_SHORT):$C5),"") | J5: =IF(AND(ISNUMBER($G5),$G5>=MA_MED),AVERAGE(INDEX($C$5:$C5,2-MA_MED):$C5),"") | K5: =IF(AND(ISNUMBER($G5),$G5>=MA_LONG2),AVERAGE(INDEX($C$5:$C5,2-MA_LONG2):$C5),"") | L5: =IF(AND(ISNUMBER($G5),$G5>=21),STDEV(INDEX($H$5:$H5,2-20):$H5)*SQRT(245),"") | M5: =IF(AND(ISNUMBER($G5),$G5>=60),MAX(INDEX($D$5:$D5,2-60):$D5),"") | N5: =IF(AND(ISNUMBER($G5),$G5>=60),MIN(INDEX($E$5:$E5,2-60):$E5),"") | O5: =IF(OR(NOT(ISNUMBER($C5)),NOT(ISNUMBER($M5)),$M5=0),"",$C5/$M5-1) | Q5: =IF(NOT(ISNUMBER($P5)),"",IFERROR(PERCENTRANK($P$5:$P$1204,$P5),""))
A6: 45571 | B6: 1403/07/15 | C6: 79529731 | D6: 79959462 | E6: 79300680 | F6: 0 | G6: =IF($A6="","",IF(ISNUMBER($G5),$G5+1,1)) -> 2 | H6: =IF(OR(NOT(ISNUMBER($G6)),$G6<2,NOT(ISNUMBER($C5)),$C5=0),"",$C6/$C5-1) -> 0.025771708 | I6: =IF(AND(ISNUMBER($G6),$G6>=MA_SHORT),AVERAGE(INDEX($C$5:$C6,3-MA_SHORT):$C6),"") | J6: =IF(AND(ISNUMBER($G6),$G6>=MA_MED),AVERAGE(INDEX($C$5:$C6,3-MA_MED):$C6),"") | K6: =IF(AND(ISNUMBER($G6),$G6>=MA_LONG2),AVERAGE(INDEX($C$5:$C6,3-MA_LONG2):$C6),"") | L6: =IF(AND(ISNUMBER($G6),$G6>=21),STDEV(INDEX($H$5:$H6,3-20):$H6)*SQRT(245),"") | M6: =IF(AND(ISNUMBER($G6),$G6>=60),MAX(INDEX($D$5:$D6,3-60):$D6),"") | N6: =IF(AND(ISNUMBER($G6),$G6>=60),MIN(INDEX($E$5:$E6,3-60):$E6),"") | O6: =IF(OR(NOT(ISNUMBER($C6)),NOT(ISNUMBER($M6)),$M6=0),"",$C6/$M6-1) | Q6: =IF(NOT(ISNUMBER($P6)),"",IFERROR(PERCENTRANK($P$5:$P$1204,$P6),""))
A7: 45572 | B7: 1403/07/16 | C7: 78640334 | D7: 78741587 | E7: 78592835 | F7: 0 | G7: =IF($A7="","",IF(ISNUMBER($G6),$G6+1,1)) -> 3 | H7: =IF(OR(NOT(ISNUMBER($G7)),$G7<2,NOT(ISNUMBER($C6)),$C6=0),"",$C7/$C6-1) -> -0.011183201 | I7: =IF(AND(ISNUMBER($G7),$G7>=MA_SHORT),AVERAGE(INDEX($C$5:$C7,4-MA_SHORT):$C7),"") | J7: =IF(AND(ISNUMBER($G7),$G7>=MA_MED),AVERAGE(INDEX($C$5:$C7,4-MA_MED):$C7),"") | K7: =IF(AND(ISNUMBER($G7),$G7>=MA_LONG2),AVERAGE(INDEX($C$5:$C7,4-MA_LONG2):$C7),"") | L7: =IF(AND(ISNUMBER($G7),$G7>=21),STDEV(INDEX($H$5:$H7,4-20):$H7)*SQRT(245),"") | M7: =IF(AND(ISNUMBER($G7),$G7>=60),MAX(INDEX($D$5:$D7,4-60):$D7),"") | N7: =IF(AND(ISNUMBER($G7),$G7>=60),MIN(INDEX($E$5:$E7,4-60):$E7),"") | O7: =IF(OR(NOT(ISNUMBER($C7)),NOT(ISNUMBER($M7)),$M7=0),"",$C7/$M7-1) | Q7: =IF(NOT(ISNUMBER($P7)),"",IFERROR(PERCENTRANK($P$5:$P$1204,$P7),""))
A8: 45573 | B8: 1403/07/17 | C8: 77380022 | D8: 77468797 | E8: 76933124 | F8: 0 | G8: =IF($A8="","",IF(ISNUMBER($G7),$G7+1,1)) -> 4 | H8: =IF(OR(NOT(ISNUMBER($G8)),$G8<2,NOT(ISNUMBER($C7)),$C7=0),"",$C8/$C7-1) -> -0.01602628 | I8: =IF(AND(ISNUMBER($G8),$G8>=MA_SHORT),AVERAGE(INDEX($C$5:$C8,5-MA_SHORT):$C8),"") | J8: =IF(AND(ISNUMBER($G8),$G8>=MA_MED),AVERAGE(INDEX($C$5:$C8,5-MA_MED):$C8),"") | K8: =IF(AND(ISNUMBER($G8),$G8>=MA_LONG2),AVERAGE(INDEX($C$5:$C8,5-MA_LONG2):$C8),"") | L8: =IF(AND(ISNUMBER($G8),$G8>=21),STDEV(INDEX($H$5:$H8,5-20):$H8)*SQRT(245),"") | M8: =IF(AND(ISNUMBER($G8),$G8>=60),MAX(INDEX($D$5:$D8,5-60):$D8),"") | N8: =IF(AND(ISNUMBER($G8),$G8>=60),MIN(INDEX($E$5:$E8,5-60):$E8),"") | O8: =IF(OR(NOT(ISNUMBER($C8)),NOT(ISNUMBER($M8)),$M8=0),"",$C8/$M8-1) | Q8: =IF(NOT(ISNUMBER($P8)),"",IFERROR(PERCENTRANK($P$5:$P$1204,$P8),""))
A9: 45574 | B9: 1403/07/18 | C9: 78025527 | D9: 78309825 | E9: 77925618 | F9: 0 | G9: =IF($A9="","",IF(ISNUMBER($G8),$G8+1,1)) -> 5 | H9: =IF(OR(NOT(ISNUMBER($G9)),$G9<2,NOT(ISNUMBER($C8)),$C8=0),"",$C9/$C8-1) -> 0.0083420111 | I9: =IF(AND(ISNUMBER($G9),$G9>=MA_SHORT),AVERAGE(INDEX($C$5:$C9,6-MA_SHORT):$C9),"") | J9: =IF(AND(ISNUMBER($G9),$G9>=MA_MED),AVERAGE(INDEX($C$5:$C9,6-MA_MED):$C9),"") | K9: =IF(AND(ISNUMBER($G9),$G9>=MA_LONG2),AVERAGE(INDEX($C$5:$C9,6-MA_LONG2):$C9),"") | L9: =IF(AND(ISNUMBER($G9),$G9>=21),STDEV(INDEX($H$5:$H9,6-20):$H9)*SQRT(245),"") | M9: =IF(AND(ISNUMBER($G9),$G9>=60),MAX(INDEX($D$5:$D9,6-60):$D9),"") | N9: =IF(AND(ISNUMBER($G9),$G9>=60),MIN(INDEX($E$5:$E9,6-60):$E9),"") | O9: =IF(OR(NOT(ISNUMBER($C9)),NOT(ISNUMBER($M9)),$M9=0),"",$C9/$M9-1) | Q9: =IF(NOT(ISNUMBER($P9)),"",IFERROR(PERCENTRANK($P$5:$P$1204,$P9),""))
A10: 45577 | B10: 1403/07/21 | C10: 78573859 | D10: 78605791 | E10: 78386241 | F10: 0 | G10: =IF($A10="","",IF(ISNUMBER($G9),$G9+1,1)) -> 6 | H10: =IF(OR(NOT(ISNUMBER($G10)),$G10<2,NOT(ISNUMBER($C9)),$C9=0),"",$C10/$C9-1) -> 0.0070275975 | I10: =IF(AND(ISNUMBER($G10),$G10>=MA_SHORT),AVERAGE(INDEX($C$5:$C10,7-MA_SHORT):$C10),"") | J10: =IF(AND(ISNUMBER($G10),$G10>=MA_MED),AVERAGE(INDEX($C$5:$C10,7-MA_MED):$C10),"") | K10: =IF(AND(ISNUMBER($G10),$G10>=MA_LONG2),AVERAGE(INDEX($C$5:$C10,7-MA_LONG2):$C10),"") | L10: =IF(AND(ISNUMBER($G10),$G10>=21),STDEV(INDEX($H$5:$H10,7-20):$H10)*SQRT(245),"") | M10: =IF(AND(ISNUMBER($G10),$G10>=60),MAX(INDEX($D$5:$D10,7-60):$D10),"") | N10: =IF(AND(ISNUMBER($G10),$G10>=60),MIN(INDEX($E$5:$E10,7-60):$E10),"") | O10: =IF(OR(NOT(ISNUMBER($C10)),NOT(ISNUMBER($M10)),$M10=0),"",$C10/$M10-1) | Q10: =IF(NOT(ISNUMBER($P10)),"",IFERROR(PERCENTRANK($P$5:$P$1204,$P10),""))
A11: 45578 | B11: 1403/07/22 | C11: 77842492 | D11: 78200588 | E11: 77334786 | F11: 0 | G11: =IF($A11="","",IF(ISNUMBER($G10),$G10+1,1)) -> 7 | H11: =IF(OR(NOT(ISNUMBER($G11)),$G11<2,NOT(ISNUMBER($C10)),$C10=0),"",$C11/$C10-1) -> -0.0093080194 | I11: =IF(AND(ISNUMBER($G11),$G11>=MA_SHORT),AVERAGE(INDEX($C$5:$C11,8-MA_SHORT):$C11),"") | J11: =IF(AND(ISNUMBER($G11),$G11>=MA_MED),AVERAGE(INDEX($C$5:$C11,8-MA_MED):$C11),"") | K11: =IF(AND(ISNUMBER($G11),$G11>=MA_LONG2),AVERAGE(INDEX($C$5:$C11,8-MA_LONG2):$C11),"") | L11: =IF(AND(ISNUMBER($G11),$G11>=21),STDEV(INDEX($H$5:$H11,8-20):$H11)*SQRT(245),"") | M11: =IF(AND(ISNUMBER($G11),$G11>=60),MAX(INDEX($D$5:$D11,8-60):$D11),"") | N11: =IF(AND(ISNUMBER($G11),$G11>=60),MIN(INDEX($E$5:$E11,8-60):$E11),"") | O11: =IF(OR(NOT(ISNUMBER($C11)),NOT(ISNUMBER($M11)),$M11=0),"",$C11/$M11-1) | Q11: =IF(NOT(ISNUMBER($P11)),"",IFERROR(PERCENTRANK($P$5:$P$1204,$P11),""))
A12: 45579 | B12: 1403/07/23 | C12: 78559850 | D12: 79177408 | E12: 78429910 | F12: 0 | G12: =IF($A12="","",IF(ISNUMBER($G11),$G11+1,1)) -> 8 | H12: =IF(OR(NOT(ISNUMBER($G12)),$G12<2,NOT(ISNUMBER($C11)),$C11=0),"",$C12/$C11-1) -> 0.0092155066 | I12: =IF(AND(ISNUMBER($G12),$G12>=MA_SHORT),AVERAGE(INDEX($C$5:$C12,9-MA_SHORT):$C12),"") | J12: =IF(AND(ISNUMBER($G12),$G12>=MA_MED),AVERAGE(INDEX($C$5:$C12,9-MA_MED):$C12),"") | K12: =IF(AND(ISNUMBER($G12),$G12>=MA_LONG2),AVERAGE(INDEX($C$5:$C12,9-MA_LONG2):$C12),"") | L12: =IF(AND(ISNUMBER($G12),$G12>=21),STDEV(INDEX($H$5:$H12,9-20):$H12)*SQRT(245),"") | M12: =IF(AND(ISNUMBER($G12),$G12>=60),MAX(INDEX($D$5:$D12,9-60):$D12),"") | N12: =IF(AND(ISNUMBER($G12),$G12>=60),MIN(INDEX($E$5:$E12,9-60):$E12),"") | O12: =IF(OR(NOT(ISNUMBER($C12)),NOT(ISNUMBER($M12)),$M12=0),"",$C12/$M12-1) | Q12: =IF(NOT(ISNUMBER($P12)),"",IFERROR(PERCENTRANK($P$5:$P$1204,$P12),""))
A13: 45580 | B13: 1403/07/24 | C13: 79016135 | D13: 79201465 | E13: 78939804 | F13: 0 | G13: =IF($A13="","",IF(ISNUMBER($G12),$G12+1,1)) -> 9 | H13: =IF(OR(NOT(ISNUMBER($G13)),$G13<2,NOT(ISNUMBER($C12)),$C12=0),"",$C13/$C12-1) -> 0.0058081195 | I13: =IF(AND(ISNUMBER($G13),$G13>=MA_SHORT),AVERAGE(INDEX($C$5:$C13,10-MA_SHORT):$C13),"") | J13: =IF(AND(ISNUMBER($G13),$G13>=MA_MED),AVERAGE(INDEX($C$5:$C13,10-MA_MED):$C13),"") | K13: =IF(AND(ISNUMBER($G13),$G13>=MA_LONG2),AVERAGE(INDEX($C$5:$C13,10-MA_LONG2):$C13),"") | L13: =IF(AND(ISNUMBER($G13),$G13>=21),STDEV(INDEX($H$5:$H13,10-20):$H13)*SQRT(245),"") | M13: =IF(AND(ISNUMBER($G13),$G13>=60),MAX(INDEX($D$5:$D13,10-60):$D13),"") | N13: =IF(AND(ISNUMBER($G13),$G13>=60),MIN(INDEX($E$5:$E13,10-60):$E13),"") | O13: =IF(OR(NOT(ISNUMBER($C13)),NOT(ISNUMBER($M13)),$M13=0),"",$C13/$M13-1) | Q13: =IF(NOT(ISNUMBER($P13)),"",IFERROR(PERCENTRANK($P$5:$P$1204,$P13),""))
A14: 45581 | B14: 1403/07/25 | C14: 77438026 | D14: 77764144 | E14: 77111892 | F14: 0 | G14: =IF($A14="","",IF(ISNUMBER($G13),$G13+1,1)) -> 10 | H14: =IF(OR(NOT(ISNUMBER($G14)),$G14<2,NOT(ISNUMBER($C13)),$C13=0),"",$C14/$C13-1) -> -0.019971984 | I14: =IF(AND(ISNUMBER($G14),$G14>=MA_SHORT),AVERAGE(INDEX($C$5:$C14,11-MA_SHORT):$C14),"") | J14: =IF(AND(ISNUMBER($G14),$G14>=MA_MED),AVERAGE(INDEX($C$5:$C14,11-MA_MED):$C14),"") | K14: =IF(AND(ISNUMBER($G14),$G14>=MA_LONG2),AVERAGE(INDEX($C$5:$C14,11-MA_LONG2):$C14),"") | L14: =IF(AND(ISNUMBER($G14),$G14>=21),STDEV(INDEX($H$5:$H14,11-20):$H14)*SQRT(245),"") | M14: =IF(AND(ISNUMBER($G14),$G14>=60),MAX(INDEX($D$5:$D14,11-60):$D14),"") | N14: =IF(AND(ISNUMBER($G14),$G14>=60),MIN(INDEX($E$5:$E14,11-60):$E14),"") | O14: =IF(OR(NOT(ISNUMBER($C14)),NOT(ISNUMBER($M14)),$M14=0),"",$C14/$M14-1) | Q14: =IF(NOT(ISNUMBER($P14)),"",IFERROR(PERCENTRANK($P$5:$P$1204,$P14),""))
A15: 45584 | B15: 1403/07/28 | C15: 79093783 | D15: 79584577 | E15: 78762073 | F15: 0 | G15: =IF($A15="","",IF(ISNUMBER($G14),$G14+1,1)) -> 11 | H15: =IF(OR(NOT(ISNUMBER($G15)),$G15<2,NOT(ISNUMBER($C14)),$C14=0),"",$C15/$C14-1) -> 0.021381705 | I15: =IF(AND(ISNUMBER($G15),$G15>=MA_SHORT),AVERAGE(INDEX($C$5:$C15,12-MA_SHORT):$C15),"") | J15: =IF(AND(ISNUMBER($G15),$G15>=MA_MED),AVERAGE(INDEX($C$5:$C15,12-MA_MED):$C15),"") | K15: =IF(AND(ISNUMBER($G15),$G15>=MA_LONG2),AVERAGE(INDEX($C$5:$C15,12-MA_LONG2):$C15),"") | L15: =IF(AND(ISNUMBER($G15),$G15>=21),STDEV(INDEX($H$5:$H15,12-20):$H15)*SQRT(245),"") | M15: =IF(AND(ISNUMBER($G15),$G15>=60),MAX(INDEX($D$5:$D15,12-60):$D15),"") | N15: =IF(AND(ISNUMBER($G15),$G15>=60),MIN(INDEX($E$5:$E15,12-60):$E15),"") | O15: =IF(OR(NOT(ISNUMBER($C15)),NOT(ISNUMBER($M15)),$M15=0),"",$C15/$M15-1) | Q15: =IF(NOT(ISNUMBER($P15)),"",IFERROR(PERCENTRANK($P$5:$P$1204,$P15),""))
