Workbook

Sheet Options
A1: بخش اختیار معامله (Options)
A2: سیگنال آپشن = وضعیت سهم پایه + گران/ارزان بودن قرارداد + مانی‌نس + نقدشوندگی. نوسان ضمنی با تقریب Brenner–Subrahmanyam محاسبه می‌شود و فقط نزدیک ATM معتبر است.
A3: نماد قرارداد | B3: ISIN | C3: نوع | D3: نماد پایه | E3: قیمت اعمال | F3: تاریخ سررسید | G3: روز تا سررسید | H3: آخرین قیمت | I3: قیمت پایانی | J3: حجم معاملات | K3: ارزش معاملات | L3: تعداد معاملات | M3: موقعیت‌های باز ⚠️ | N3: اندازه قرارداد | O3: قیمت دارایی پایه | P3: مانی‌نس (S÷K) | Q3: وضعیت | R3: ارزش ذاتی | S3: ارزش زمانی | T3: زمان تا سررسید (سال) | U3: نوسان ضمنی تقریبی | V3: d1 | W3: d2 | X3: دلتا | Y3: قیمت نظری | Z3: بازار ÷ نظری | AA3: اهرم مؤثر | AB3: امتیاز سهم پایه | AC3: نقدشوندگی معتبر؟ | AD3: امتیاز آپشن | AE3: سیگنال آپشن | AF3: دلیل
A4: instrumentName | B4: instrumentId | C4: - | D4: - | E4: qeymateEmal | F4: tarixSarresid | G4: baghimandetasarresid | H4: lastPrice | I4: closingPrice | J4: tradeVolume | K4: tradeValue | L4: tradeCount | M4: openInterest | N4: andazeyeQarardad | O4: Underlying | P4: - | Q4: ITM/ATM/OTM | R4: - | S4: - | T4: - | U4: Brenner-Subrahmanyam | V4: Black-Scholes | W4: Black-Scholes | X4: N(d1) | Y4: Black-Scholes | Z4: گران/ارزان | AA4: S×|Δ|÷P | AB4: Underlying | AC4: OPT_MIN_* | AD4: −۱۰ تا +۱۰ | AE4: - | AF4: -
A5: ضفلا8001 | B5: IRO9FOLD2261 | C5: Call | D5: فولاد | E5: 8000 | F5: 46315 | G5: 45 | H5: 980 | I5: 950 | J5: 3240 | K5: 3078000000 | L5: 412 | M5: 18500 | N5: 1000 | O5: =IF($A5="","",IFERROR(INDEX(Underlying!$B$1:$B$5000,MATCH($D5,Underlying!$A$1:$A$5000,0)),"")) -> 0 | P5: =IF($A5="","",IFERROR($O5/$E5,"")) -> 0 | Q5: =IF($A5="","",IF($P5="","",IF($C5="Call",IF($P5>1+OPT_ATM_BAND,"ITM",IF($P5<1-OPT_ATM_BAND,"OTM","ATM")),IF($P5<1-OPT_ATM_BAND,"ITM",IF($P5>1+OPT_ATM_BAND,"OTM","ATM"))))) -> OTM | R5: =IF($A5="","",IFERROR(IF($C5="Call",MAX(0,$O5-$E5),MAX(0,$E5-$O5)),"")) -> 0 | S5: =IF($A5="","",IFERROR(MAX(0,$I5-$R5),"")) -> 950 | T5: =IF($A5="","",IFERROR($G5/365,"")) -> 0.12328767 | U5: =IF($A5="","",IF(OR($P5="",ABS($P5-1)>3*OPT_ATM_BAND),"",IFERROR($I5/$O5*SQRT(2*PI()/$T5),""))) | V5: =IF($A5="","",IFERROR((LN($O5/$E5)+(OPT_RF+OPT_VOL^2/2)*$T5)/(OPT_VOL*SQRT($T5)),"")) | W5: =IF($A5="","",IFERROR($V5-OPT_VOL*SQRT($T5),"")) | X5: =IF($A5="","",IFERROR(IF($C5="Call",NORMSDIST($V5),NORMSDIST($V5)-1),"")) | Y5: =IF($A5="","",IFERROR(IF($C5="Call",$O5*NORMSDIST($V5)-$E5*EXP(-OPT_RF*$T5)*NORMSDIST($W5),$E5*EXP(-OPT_RF*$T5)*NORMSDIST(-$W5)-$O5*NORMSDIST(-$V5)),"")) | Z5: =IF($A5="","",IFERROR($I5/$Y5,"")) | AA5: =IF($A5="","",IFERROR($O5*ABS($X5)/$I5,"")) | AB5: =IF($A5="","",IFERROR(INDEX(Underlying!$D$1:$D$5000,MATCH($D5,Underlying!$A$1:$A$5000,0)),0)) -> 0 | AC5: =IF($A5="","",IF(AND($J5>=OPT_MIN_VOL,$G5>=OPT_MIN_DTE),"بله","خیر")) -> بله | AD5: =IF($A5="","",IF($AC5="خیر",0,IFERROR(MAX(-10,MIN(10,IF($C5="Call",$AB5,-$AB5)*0.6+IF($Z5<0.85,2,IF($Z5>1.25,-2,0))+IF($Q5="ATM",1,IF($Q5="ITM",0.5,-1))+IF($G5>=30,0.5,-0.5))),0))) -> -2.5 | AE5: =IF($A5="","",IF($AC5="خیر","بدون سیگنال (نقدشوندگی/سررسید)",IF($AD5>=TH_SBUY,"خرید قوی "&$C5,IF($AD5>=TH_BUY,"خرید "&$C5,IF($AD5<=TH_SSELL,"اجتناب / بستن موقعیت",IF($AD5<=TH_SELL,"ضعیف","بی‌طرف")))))) -> ضعیف | AF5: =IF($A5="","","سهم پایه: "&IFERROR(TEXT($AB5,"0.0"),"—")&" | وضعیت: "&$Q5&" | نوسان ضمنی: "&IFERROR(TEXT($U5,"0%"),"—")&" | بازار÷نظری: "&IFERROR(TEXT($Z5,"0.00"),"—")&" | اهرم: "&IFERROR(TEXT($AA5,"0.0"),"—")&"x"&" | "&$G5&" روز تا سررسید") -> سهم پایه: 0.0 | وضعیت: OTM | نوسان ضمنی: | بازار÷نظری: | اهرم: x | 45 روز تا سررسید
A6: ضفلا9001 | B6: IRO9FOLD2271 | C6: Call | D6: فولاد | E6: 9000 | F6: 46315 | G6: 45 | H6: 430 | I6: 418 | J6: 1870 | K6: 781660000 | L6: 265 | M6: 11200 | N6: 1000 | O6: =IF($A6="","",IFERROR(INDEX(Underlying!$B$1:$B$5000,MATCH($D6,Underlying!$A$1:$A$5000,0)),"")) -> 0 | P6: =IF($A6="","",IFERROR($O6/$E6,"")) -> 0 | Q6: =IF($A6="","",IF($P6="","",IF($C6="Call",IF($P6>1+OPT_ATM_BAND,"ITM",IF($P6<1-OPT_ATM_BAND,"OTM","ATM")),IF($P6<1-OPT_ATM_BAND,"ITM",IF($P6>1+OPT_ATM_BAND,"OTM","ATM"))))) -> OTM | R6: =IF($A6="","",IFERROR(IF($C6="Call",MAX(0,$O6-$E6),MAX(0,$E6-$O6)),"")) -> 0 | S6: =IF($A6="","",IFERROR(MAX(0,$I6-$R6),"")) -> 418 | T6: =IF($A6="","",IFERROR($G6/365,"")) -> 0.12328767 | U6: =IF($A6="","",IF(OR($P6="",ABS($P6-1)>3*OPT_ATM_BAND),"",IFERROR($I6/$O6*SQRT(2*PI()/$T6),""))) | V6: =IF($A6="","",IFERROR((LN($O6/$E6)+(OPT_RF+OPT_VOL^2/2)*$T6)/(OPT_VOL*SQRT($T6)),"")) | W6: =IF($A6="","",IFERROR($V6-OPT_VOL*SQRT($T6),"")) | X6: =IF($A6="","",IFERROR(IF($C6="Call",NORMSDIST($V6),NORMSDIST($V6)-1),"")) | Y6: =IF($A6="","",IFERROR(IF($C6="Call",$O6*NORMSDIST($V6)-$E6*EXP(-OPT_RF*$T6)*NORMSDIST($W6),$E6*EXP(-OPT_RF*$T6)*NORMSDIST(-$W6)-$O6*NORMSDIST(-$V6)),"")) | Z6: =IF($A6="","",IFERROR($I6/$Y6,"")) | AA6: =IF($A6="","",IFERROR($O6*ABS($X6)/$I6,"")) | AB6: =IF($A6="","",IFERROR(INDEX(Underlying!$D$1:$D$5000,MATCH($D6,Underlying!$A$1:$A$5000,0)),0)) -> 0 | AC6: =IF($A6="","",IF(AND($J6>=OPT_MIN_VOL,$G6>=OPT_MIN_DTE),"بله","خیر")) -> بله | AD6: =IF($A6="","",IF($AC6="خیر",0,IFERROR(MAX(-10,MIN(10,IF($C6="Call",$AB6,-$AB6)*0.6+IF($Z6<0.85,2,IF($Z6>1.25,-2,0))+IF($Q6="ATM",1,IF($Q6="ITM",0.5,-1))+IF($G6>=30,0.5,-0.5))),0))) -> -2.5 | AE6: =IF($A6="","",IF($AC6="خیر","بدون سیگنال (نقدشوندگی/سررسید)",IF($AD6>=TH_SBUY,"خرید قوی "&$C6,IF($AD6>=TH_BUY,"خرید "&$C6,IF($AD6<=TH_SSELL,"اجتناب / بستن موقعیت",IF($AD6<=TH_SELL,"ضعیف","بی‌طرف")))))) -> ضعیف | AF6: =IF($A6="","","سهم پایه: "&IFERROR(TEXT($AB6,"0.0"),"—")&" | وضعیت: "&$Q6&" | نوسان ضمنی: "&IFERROR(TEXT($U6,"0%"),"—")&" | بازار÷نظری: "&IFERROR(TEXT($Z6,"0.00"),"—")&" | اهرم: "&IFERROR(TEXT($AA6,"0.0"),"—")&"x"&" | "&$G6&" روز تا سررسید") -> سهم پایه: 0.0 | وضعیت: OTM | نوسان ضمنی: | بازار÷نظری: | اهرم: x | 45 روز تا سررسید
A7: طفلا8001 | B7: IRO9FOLD2281 | C7: Put | D7: فولاد | E7: 8000 | F7: 46315 | G7: 45 | H7: 505 | I7: 520 | J7: 640 | K7: 332800000 | L7: 98 | M7: 4300 | N7: 1000 | O7: =IF($A7="","",IFERROR(INDEX(Underlying!$B$1:$B$5000,MATCH($D7,Underlying!$A$1:$A$5000,0)),"")) -> 0 | P7: =IF($A7="","",IFERROR($O7/$E7,"")) -> 0 | Q7: =IF($A7="","",IF($P7="","",IF($C7="Call",IF($P7>1+OPT_ATM_BAND,"ITM",IF($P7<1-OPT_ATM_BAND,"OTM","ATM")),IF($P7<1-OPT_ATM_BAND,"ITM",IF($P7>1+OPT_ATM_BAND,"OTM","ATM"))))) -> ITM | R7: =IF($A7="","",IFERROR(IF($C7="Call",MAX(0,$O7-$E7),MAX(0,$E7-$O7)),"")) -> 8000 | S7: =IF($A7="","",IFERROR(MAX(0,$I7-$R7),"")) -> 0 | T7: =IF($A7="","",IFERROR($G7/365,"")) -> 0.12328767 | U7: =IF($A7="","",IF(OR($P7="",ABS($P7-1)>3*OPT_ATM_BAND),"",IFERROR($I7/$O7*SQRT(2*PI()/$T7),""))) | V7: =IF($A7="","",IFERROR((LN($O7/$E7)+(OPT_RF+OPT_VOL^2/2)*$T7)/(OPT_VOL*SQRT($T7)),"")) | W7: =IF($A7="","",IFERROR($V7-OPT_VOL*SQRT($T7),"")) | X7: =IF($A7="","",IFERROR(IF($C7="Call",NORMSDIST($V7),NORMSDIST($V7)-1),"")) | Y7: =IF($A7="","",IFERROR(IF($C7="Call",$O7*NORMSDIST($V7)-$E7*EXP(-OPT_RF*$T7)*NORMSDIST($W7),$E7*EXP(-OPT_RF*$T7)*NORMSDIST(-$W7)-$O7*NORMSDIST(-$V7)),"")) | Z7: =IF($A7="","",IFERROR($I7/$Y7,"")) | AA7: =IF($A7="","",IFERROR($O7*ABS($X7)/$I7,"")) | AB7: =IF($A7="","",IFERROR(INDEX(Underlying!$D$1:$D$5000,MATCH($D7,Underlying!$A$1:$A$5000,0)),0)) -> 0 | AC7: =IF($A7="","",IF(AND($J7>=OPT_MIN_VOL,$G7>=OPT_MIN_DTE),"بله","خیر")) -> بله | AD7: =IF($A7="","",IF($AC7="خیر",0,IFERROR(MAX(-10,MIN(10,IF($C7="Call",$AB7,-$AB7)*0.6+IF($Z7<0.85,2,IF($Z7>1.25,-2,0))+IF($Q7="ATM",1,IF($Q7="ITM",0.5,-1))+IF($G7>=30,0.5,-0.5))),0))) -> -1 | AE7: =IF($A7="","",IF($AC7="خیر","بدون سیگنال (نقدشوندگی/سررسید)",IF($AD7>=TH_SBUY,"خرید قوی "&$C7,IF($AD7>=TH_BUY,"خرید "&$C7,IF($AD7<=TH_SSELL,"اجتناب / بستن موقعیت",IF($AD7<=TH_SELL,"ضعیف","بی‌طرف")))))) -> بی‌طرف | AF7: =IF($A7="","","سهم پایه: "&IFERROR(TEXT($AB7,"0.0"),"—")&" | وضعیت: "&$Q7&" | نوسان ضمنی: "&IFERROR(TEXT($U7,"0%"),"—")&" | بازار÷نظری: "&IFERROR(TEXT($Z7,"0.00"),"—")&" | اهرم: "&IFERROR(TEXT($AA7,"0.0"),"—")&"x"&" | "&$G7&" روز تا سررسید") -> سهم پایه: 0.0 | وضعیت: ITM | نوسان ضمنی: | بازار÷نظری: | اهرم: x | 45 روز تا سررسید
A8: ضگل11001 | B8: IRO9GOLG3011 | C8: Call | D8: كگل | E8: 11000 | F8: 46295 | G8: 25 | H8: 790 | I8: 775 | J8: 2110 | K8: 1635250000 | L8: 301 | M8: 9800 | N8: 1000 | O8: =IF($A8="","",IFERROR(INDEX(Underlying!$B$1:$B$5000,MATCH($D8,Underlying!$A$1:$A$5000,0)),"")) -> 0 | P8: =IF($A8="","",IFERROR($O8/$E8,"")) -> 0 | Q8: =IF($A8="","",IF($P8="","",IF($C8="Call",IF($P8>1+OPT_ATM_BAND,"ITM",IF($P8<1-OPT_ATM_BAND,"OTM","ATM")),IF($P8<1-OPT_ATM_BAND,"ITM",IF($P8>1+OPT_ATM_BAND,"OTM","ATM"))))) -> OTM | R8: =IF($A8="","",IFERROR(IF($C8="Call",MAX(0,$O8-$E8),MAX(0,$E8-$O8)),"")) -> 0 | S8: =IF($A8="","",IFERROR(MAX(0,$I8-$R8),"")) -> 775 | T8: =IF($A8="","",IFERROR($G8/365,"")) -> 0.068493151 | U8: =IF($A8="","",IF(OR($P8="",ABS($P8-1)>3*OPT_ATM_BAND),"",IFERROR($I8/$O8*SQRT(2*PI()/$T8),""))) | V8: =IF($A8="","",IFERROR((LN($O8/$E8)+(OPT_RF+OPT_VOL^2/2)*$T8)/(OPT_VOL*SQRT($T8)),"")) | W8: =IF($A8="","",IFERROR($V8-OPT_VOL*SQRT($T8),"")) | X8: =IF($A8="","",IFERROR(IF($C8="Call",NORMSDIST($V8),NORMSDIST($V8)-1),"")) | Y8: =IF($A8="","",IFERROR(IF($C8="Call",$O8*NORMSDIST($V8)-$E8*EXP(-OPT_RF*$T8)*NORMSDIST($W8),$E8*EXP(-OPT_RF*$T8)*NORMSDIST(-$W8)-$O8*NORMSDIST(-$V8)),"")) | Z8: =IF($A8="","",IFERROR($I8/$Y8,"")) | AA8: =IF($A8="","",IFERROR($O8*ABS($X8)/$I8,"")) | AB8: =IF($A8="","",IFERROR(INDEX(Underlying!$D$1:$D$5000,MATCH($D8,Underlying!$A$1:$A$5000,0)),0)) -> 0 | AC8: =IF($A8="","",IF(AND($J8>=OPT_MIN_VOL,$G8>=OPT_MIN_DTE),"بله","خیر")) -> بله | AD8: =IF($A8="","",IF($AC8="خیر",0,IFERROR(MAX(-10,MIN(10,IF($C8="Call",$AB8,-$AB8)*0.6+IF($Z8<0.85,2,IF($Z8>1.25,-2,0))+IF($Q8="ATM",1,IF($Q8="ITM",0.5,-1))+IF($G8>=30,0.5,-0.5))),0))) -> -3.5 | AE8: =IF($A8="","",IF($AC8="خیر","بدون سیگنال (نقدشوندگی/سررسید)",IF($AD8>=TH_SBUY,"خرید قوی "&$C8,IF($AD8>=TH_BUY,"خرید "&$C8,IF($AD8<=TH_SSELL,"اجتناب / بستن موقعیت",IF($AD8<=TH_SELL,"ضعیف","بی‌طرف")))))) -> ضعیف | AF8: =IF($A8="","","سهم پایه: "&IFERROR(TEXT($AB8,"0.0"),"—")&" | وضعیت: "&$Q8&" | نوسان ضمنی: "&IFERROR(TEXT($U8,"0%"),"—")&" | بازار÷نظری: "&IFERROR(TEXT($Z8,"0.00"),"—")&" | اهرم: "&IFERROR(TEXT($AA8,"0.0"),"—")&"x"&" | "&$G8&" روز تا سررسید") -> سهم پایه: 0.0 | وضعیت: OTM | نوسان ضمنی: | بازار÷نظری: | اهرم: x | 25 روز تا سررسید
A9: ضگل12001 | B9: IRO9GOLG3021 | C9: Call | D9: كگل | E9: 12000 | F9: 46295 | G9: 25 | H9: 240 | I9: 232 | J9: 180 | K9: 41760000 | L9: 34 | M9: 2100 | N9: 1000 | O9: =IF($A9="","",IFERROR(INDEX(Underlying!$B$1:$B$5000,MATCH($D9,Underlying!$A$1:$A$5000,0)),"")) -> 0 | P9: =IF($A9="","",IFERROR($O9/$E9,"")) -> 0 | Q9: =IF($A9="","",IF($P9="","",IF($C9="Call",IF($P9>1+OPT_ATM_BAND,"ITM",IF($P9<1-OPT_ATM_BAND,"OTM","ATM")),IF($P9<1-OPT_ATM_BAND,"ITM",IF($P9>1+OPT_ATM_BAND,"OTM","ATM"))))) -> OTM | R9: =IF($A9="","",IFERROR(IF($C9="Call",MAX(0,$O9-$E9),MAX(0,$E9-$O9)),"")) -> 0 | S9: =IF($A9="","",IFERROR(MAX(0,$I9-$R9),"")) -> 232 | T9: =IF($A9="","",IFERROR($G9/365,"")) -> 0.068493151 | U9: =IF($A9="","",IF(OR($P9="",ABS($P9-1)>3*OPT_ATM_BAND),"",IFERROR($I9/$O9*SQRT(2*PI()/$T9),""))) | V9: =IF($A9="","",IFERROR((LN($O9/$E9)+(OPT_RF+OPT_VOL^2/2)*$T9)/(OPT_VOL*SQRT($T9)),"")) | W9: =IF($A9="","",IFERROR($V9-OPT_VOL*SQRT($T9),"")) | X9: =IF($A9="","",IFERROR(IF($C9="Call",NORMSDIST($V9),NORMSDIST($V9)-1),"")) | Y9: =IF($A9="","",IFERROR(IF($C9="Call",$O9*NORMSDIST($V9)-$E9*EXP(-OPT_RF*$T9)*NORMSDIST($W9),$E9*EXP(-OPT_RF*$T9)*NORMSDIST(-$W9)-$O9*NORMSDIST(-$V9)),"")) | Z9: =IF($A9="","",IFERROR($I9/$Y9,"")) | AA9: =IF($A9="","",IFERROR($O9*ABS($X9)/$I9,"")) | AB9: =IF($A9="","",IFERROR(INDEX(Underlying!$D$1:$D$5000,MATCH($D9,Underlying!$A$1:$A$5000,0)),0)) -> 0 | AC9: =IF($A9="","",IF(AND($J9>=OPT_MIN_VOL,$G9>=OPT_MIN_DTE),"بله","خیر")) -> بله | AD9: =IF($A9="","",IF($AC9="خیر",0,IFERROR(MAX(-10,MIN(10,IF($C9="Call",$AB9,-$AB9)*0.6+IF($Z9<0.85,2,IF($Z9>1.25,-2,0))+IF($Q9="ATM",1,IF($Q9="ITM",0.5,-1))+IF($G9>=30,0.5,-0.5))),0))) -> -3.5 | AE9: =IF($A9="","",IF($AC9="خیر","بدون سیگنال (نقدشوندگی/سررسید)",IF($AD9>=TH_SBUY,"خرید قوی "&$C9,IF($AD9>=TH_BUY,"خرید "&$C9,IF($AD9<=TH_SSELL,"اجتناب / بستن موقعیت",IF($AD9<=TH_SELL,"ضعیف","بی‌طرف")))))) -> ضعیف | AF9: =IF($A9="","","سهم پایه: "&IFERROR(TEXT($AB9,"0.0"),"—")&" | وضعیت: "&$Q9&" | نوسان ضمنی: "&IFERROR(TEXT($U9,"0%"),"—")&" | بازار÷نظری: "&IFERROR(TEXT($Z9,"0.00"),"—")&" | اهرم: "&IFERROR(TEXT($AA9,"0.0"),"—")&"x"&" | "&$G9&" روز تا سررسید") -> سهم پایه: 0.0 | وضعیت: OTM | نوسان ضمنی: | بازار÷نظری: | اهرم: x | 25 روز تا سررسید
A10: طگل11001 | B10: IRO9GOLG3031 | C10: Put | D10: كگل | E10: 11000 | F10: 46295 | G10: 25 | H10: 700 | I10: 690 | J10: 60 | K10: 41400000 | L10: 12 | M10: 1450 | N10: 1000 | O10: =IF($A10="","",IFERROR(INDEX(Underlying!$B$1:$B$5000,MATCH($D10,Underlying!$A$1:$A$5000,0)),"")) -> 0 | P10: =IF($A10="","",IFERROR($O10/$E10,"")) -> 0 | Q10: =IF($A10="","",IF($P10="","",IF($C10="Call",IF($P10>1+OPT_ATM_BAND,"ITM",IF($P10<1-OPT_ATM_BAND,"OTM","ATM")),IF($P10<1-OPT_ATM_BAND,"ITM",IF($P10>1+OPT_ATM_BAND,"OTM","ATM"))))) -> ITM | R10: =IF($A10="","",IFERROR(IF($C10="Call",MAX(0,$O10-$E10),MAX(0,$E10-$O10)),"")) -> 11000 | S10: =IF($A10="","",IFERROR(MAX(0,$I10-$R10),"")) -> 0 | T10: =IF($A10="","",IFERROR($G10/365,"")) -> 0.068493151 | U10: =IF($A10="","",IF(OR($P10="",ABS($P10-1)>3*OPT_ATM_BAND),"",IFERROR($I10/$O10*SQRT(2*PI()/$T10),""))) | V10: =IF($A10="","",IFERROR((LN($O10/$E10)+(OPT_RF+OPT_VOL^2/2)*$T10)/(OPT_VOL*SQRT($T10)),"")) | W10: =IF($A10="","",IFERROR($V10-OPT_VOL*SQRT($T10),"")) | X10: =IF($A10="","",IFERROR(IF($C10="Call",NORMSDIST($V10),NORMSDIST($V10)-1),"")) | Y10: =IF($A10="","",IFERROR(IF($C10="Call",$O10*NORMSDIST($V10)-$E10*EXP(-OPT_RF*$T10)*NORMSDIST($W10),$E10*EXP(-OPT_RF*$T10)*NORMSDIST(-$W10)-$O10*NORMSDIST(-$V10)),"")) | Z10: =IF($A10="","",IFERROR($I10/$Y10,"")) | AA10: =IF($A10="","",IFERROR($O10*ABS($X10)/$I10,"")) | AB10: =IF($A10="","",IFERROR(INDEX(Underlying!$D$1:$D$5000,MATCH($D10,Underlying!$A$1:$A$5000,0)),0)) -> 0 | AC10: =IF($A10="","",IF(AND($J10>=OPT_MIN_VOL,$G10>=OPT_MIN_DTE),"بله","خیر")) -> خیر | AD10: =IF($A10="","",IF($AC10="خیر",0,IFERROR(MAX(-10,MIN(10,IF($C10="Call",$AB10,-$AB10)*0.6+IF($Z10<0.85,2,IF($Z10>1.25,-2,0))+IF($Q10="ATM",1,IF($Q10="ITM",0.5,-1))+IF($G10>=30,0.5,-0.5))),0))) -> 0 | AE10: =IF($A10="","",IF($AC10="خیر","بدون سیگنال (نقدشوندگی/سررسید)",IF($AD10>=TH_SBUY,"خرید قوی "&$C10,IF($AD10>=TH_BUY,"خرید "&$C10,IF($AD10<=TH_SSELL,"اجتناب / بستن موقعیت",IF($AD10<=TH_SELL,"ضعیف","بی‌طرف")))))) -> بدون سیگنال (نقدشوندگی/سررسید) | AF10: =IF($A10="","","سهم پایه: "&IFERROR(TEXT($AB10,"0.0"),"—")&" | وضعیت: "&$Q10&" | نوسان ضمنی: "&IFERROR(TEXT($U10,"0%"),"—")&" | بازار÷نظری: "&IFERROR(TEXT($Z10,"0.00"),"—")&" | اهرم: "&IFERROR(TEXT($AA10,"0.0"),"—")&"x"&" | "&$G10&" روز تا سررسید") -> سهم پایه: 0.0 | وضعیت: ITM | نوسان ضمنی: | بازار÷نظری: | اهرم: x | 25 روز تا سررسید
A11: ضخود2501 | B11: IRO9IKCO4011 | C11: Call | D11: خودرو | E11: 2500 | F11: 46287 | G11: 17 | H11: 1560 | I11: 1545 | J11: 940 | K11: 1452300000 | L11: 155 | M11: 6700 | N11: 1000 | O11: =IF($A11="","",IFERROR(INDEX(Underlying!$B$1:$B$5000,MATCH($D11,Underlying!$A$1:$A$5000,0)),"")) -> 0 | P11: =IF($A11="","",IFERROR($O11/$E11,"")) -> 0 | Q11: =IF($A11="","",IF($P11="","",IF($C11="Call",IF($P11>1+OPT_ATM_BAND,"ITM",IF($P11<1-OPT_ATM_BAND,"OTM","ATM")),IF($P11<1-OPT_ATM_BAND,"ITM",IF($P11>1+OPT_ATM_BAND,"OTM","ATM"))))) -> OTM | R11: =IF($A11="","",IFERROR(IF($C11="Call",MAX(0,$O11-$E11),MAX(0,$E11-$O11)),"")) -> 0 | S11: =IF($A11="","",IFERROR(MAX(0,$I11-$R11),"")) -> 1545 | T11: =IF($A11="","",IFERROR($G11/365,"")) -> 0.046575342 | U11: =IF($A11="","",IF(OR($P11="",ABS($P11-1)>3*OPT_ATM_BAND),"",IFERROR($I11/$O11*SQRT(2*PI()/$T11),""))) | V11: =IF($A11="","",IFERROR((LN($O11/$E11)+(OPT_RF+OPT_VOL^2/2)*$T11)/(OPT_VOL*SQRT($T11)),"")) | W11: =IF($A11="","",IFERROR($V11-OPT_VOL*SQRT($T11),"")) | X11: =IF($A11="","",IFERROR(IF($C11="Call",NORMSDIST($V11),NORMSDIST($V11)-1),"")) | Y11: =IF($A11="","",IFERROR(IF($C11="Call",$O11*NORMSDIST($V11)-$E11*EXP(-OPT_RF*$T11)*NORMSDIST($W11),$E11*EXP(-OPT_RF*$T11)*NORMSDIST(-$W11)-$O11*NORMSDIST(-$V11)),"")) | Z11: =IF($A11="","",IFERROR($I11/$Y11,"")) | AA11: =IF($A11="","",IFERROR($O11*ABS($X11)/$I11,"")) | AB11: =IF($A11="","",IFERROR(INDEX(Underlying!$D$1:$D$5000,MATCH($D11,Underlying!$A$1:$A$5000,0)),0)) -> 0 | AC11: =IF($A11="","",IF(AND($J11>=OPT_MIN_VOL,$G11>=OPT_MIN_DTE),"بله","خیر")) -> بله | AD11: =IF($A11="","",IF($AC11="خیر",0,IFERROR(MAX(-10,MIN(10,IF($C11="Call",$AB11,-$AB11)*0.6+IF($Z11<0.85,2,IF($Z11>1.25,-2,0))+IF($Q11="ATM",1,IF($Q11="ITM",0.5,-1))+IF($G11>=30,0.5,-0.5))),0))) -> -3.5 | AE11: =IF($A11="","",IF($AC11="خیر","بدون سیگنال (نقدشوندگی/سررسید)",IF($AD11>=TH_SBUY,"خرید قوی "&$C11,IF($AD11>=TH_BUY,"خرید "&$C11,IF($AD11<=TH_SSELL,"اجتناب / بستن موقعیت",IF($AD11<=TH_SELL,"ضعیف","بی‌طرف")))))) -> ضعیف | AF11: =IF($A11="","","سهم پایه: "&IFERROR(TEXT($AB11,"0.0"),"—")&" | وضعیت: "&$Q11&" | نوسان ضمنی: "&IFERROR(TEXT($U11,"0%"),"—")&" | بازار÷نظری: "&IFERROR(TEXT($Z11,"0.00"),"—")&" | اهرم: "&IFERROR(TEXT($AA11,"0.0"),"—")&"x"&" | "&$G11&" روز تا سررسید") -> سهم پایه: 0.0 | وضعیت: OTM | نوسان ضمنی: | بازار÷نظری: | اهرم: x | 17 روز تا سررسید
A12: طخود4001 | B12: IRO9IKCO4021 | C12: Put | D12: خودرو | E12: 4000 | F12: 46287 | G12: 17 | H12: 380 | I12: 395 | J12: 1320 | K12: 521400000 | L12: 201 | M12: 7900 | N12: 1000 | O12: =IF($A12="","",IFERROR(INDEX(Underlying!$B$1:$B$5000,MATCH($D12,Underlying!$A$1:$A$5000,0)),"")) -> 0 | P12: =IF($A12="","",IFERROR($O12/$E12,"")) -> 0 | Q12: =IF($A12="","",IF($P12="","",IF($C12="Call",IF($P12>1+OPT_ATM_BAND,"ITM",IF($P12<1-OPT_ATM_BAND,"OTM","ATM")),IF($P12<1-OPT_ATM_BAND,"ITM",IF($P12>1+OPT_ATM_BAND,"OTM","ATM"))))) -> ITM | R12: =IF($A12="","",IFERROR(IF($C12="Call",MAX(0,$O12-$E12),MAX(0,$E12-$O12)),"")) -> 4000 | S12: =IF($A12="","",IFERROR(MAX(0,$I12-$R12),"")) -> 0 | T12: =IF($A12="","",IFERROR($G12/365,"")) -> 0.046575342 | U12: =IF($A12="","",IF(OR($P12="",ABS($P12-1)>3*OPT_ATM_BAND),"",IFERROR($I12/$O12*SQRT(2*PI()/$T12),""))) | V12: =IF($A12="","",IFERROR((LN($O12/$E12)+(OPT_RF+OPT_VOL^2/2)*$T12)/(OPT_VOL*SQRT($T12)),"")) | W12: =IF($A12="","",IFERROR($V12-OPT_VOL*SQRT($T12),"")) | X12: =IF($A12="","",IFERROR(IF($C12="Call",NORMSDIST($V12),NORMSDIST($V12)-1),"")) | Y12: =IF($A12="","",IFERROR(IF($C12="Call",$O12*NORMSDIST($V12)-$E12*EXP(-OPT_RF*$T12)*NORMSDIST($W12),$E12*EXP(-OPT_RF*$T12)*NORMSDIST(-$W12)-$O12*NORMSDIST(-$V12)),"")) | Z12: =IF($A12="","",IFERROR($I12/$Y12,"")) | AA12: =IF($A12="","",IFERROR($O12*ABS($X12)/$I12,"")) | AB12: =IF($A12="","",IFERROR(INDEX(Underlying!$D$1:$D$5000,MATCH($D12,Underlying!$A$1:$A$5000,0)),0)) -> 0 | AC12: =IF($A12="","",IF(AND($J12>=OPT_MIN_VOL,$G12>=OPT_MIN_DTE),"بله","خیر")) -> بله | AD12: =IF($A12="","",IF($AC12="خیر",0,IFERROR(MAX(-10,MIN(10,IF($C12="Call",$AB12,-$AB12)*0.6+IF($Z12<0.85,2,IF($Z12>1.25,-2,0))+IF($Q12="ATM",1,IF($Q12="ITM",0.5,-1))+IF($G12>=30,0.5,-0.5))),0))) -> -2 | AE12: =IF($A12="","",IF($AC12="خیر","بدون سیگنال (نقدشوندگی/سررسید)",IF($AD12>=TH_SBUY,"خرید قوی "&$C12,IF($AD12>=TH_BUY,"خرید "&$C12,IF($AD12<=TH_SSELL,"اجتناب / بستن موقعیت",IF($AD12<=TH_SELL,"ضعیف","بی‌طرف")))))) -> ضعیف | AF12: =IF($A12="","","سهم پایه: "&IFERROR(TEXT($AB12,"0.0"),"—")&" | وضعیت: "&$Q12&" | نوسان ضمنی: "&IFERROR(TEXT($U12,"0%"),"—")&" | بازار÷نظری: "&IFERROR(TEXT($Z12,"0.00"),"—")&" | اهرم: "&IFERROR(TEXT($AA12,"0.0"),"—")&"x"&" | "&$G12&" روز تا سررسید") -> سهم پایه: 0.0 | وضعیت: ITM | نوسان ضمنی: | بازار÷نظری: | اهرم: x | 17 روز تا سررسید
O13: =IF($A13="","",IFERROR(INDEX(Underlying!$B$1:$B$5000,MATCH($D13,Underlying!$A$1:$A$5000,0)),"")) | P13: =IF($A13="","",IFERROR($O13/$E13,"")) | Q13: =IF($A13="","",IF($P13="","",IF($C13="Call",IF($P13>1+OPT_ATM_BAND,"ITM",IF($P13<1-OPT_ATM_BAND,"OTM","ATM")),IF($P13<1-OPT_ATM_BAND,"ITM",IF($P13>1+OPT_ATM_BAND,"OTM","ATM"))))) | R13: =IF($A13="","",IFERROR(IF($C13="Call",MAX(0,$O13-$E13),MAX(0,$E13-$O13)),"")) | S13: =IF($A13="","",IFERROR(MAX(0,$I13-$R13),"")) | T13: =IF($A13="","",IFERROR($G13/365,"")) | U13: =IF($A13="","",IF(OR($P13="",ABS($P13-1)>3*OPT_ATM_BAND),"",IFERROR($I13/$O13*SQRT(2*PI()/$T13),""))) | V13: =IF($A13="","",IFERROR((LN($O13/$E13)+(OPT_RF+OPT_VOL^2/2)*$T13)/(OPT_VOL*SQRT($T13)),"")) | W13: =IF($A13="","",IFERROR($V13-OPT_VOL*SQRT($T13),"")) | X13: =IF($A13="","",IFERROR(IF($C13="Call",NORMSDIST($V13),NORMSDIST($V13)-1),"")) | Y13: =IF($A13="","",IFERROR(IF($C13="Call",$O13*NORMSDIST($V13)-$E13*EXP(-OPT_RF*$T13)*NORMSDIST($W13),$E13*EXP(-OPT_RF*$T13)*NORMSDIST(-$W13)-$O13*NORMSDIST(-$V13)),"")) | Z13: =IF($A13="","",IFERROR($I13/$Y13,"")) | AA13: =IF($A13="","",IFERROR($O13*ABS($X13)/$I13,"")) | AB13: =IF($A13="","",IFERROR(INDEX(Underlying!$D$1:$D$5000,MATCH($D13,Underlying!$A$1:$A$5000,0)),0)) | AC13: =IF($A13="","",IF(AND($J13>=OPT_MIN_VOL,$G13>=OPT_MIN_DTE),"بله","خیر")) | AD13: =IF($A13="","",IF($AC13="خیر",0,IFERROR(MAX(-10,MIN(10,IF($C13="Call",$AB13,-$AB13)*0.6+IF($Z13<0.85,2,IF($Z13>1.25,-2,0))+IF($Q13="ATM",1,IF($Q13="ITM",0.5,-1))+IF($G13>=30,0.5,-0.5))),0))) | AE13: =IF($A13="","",IF($AC13="خیر","بدون سیگنال (نقدشوندگی/سررسید)",IF($AD13>=TH_SBUY,"خرید قوی "&$C13,IF($AD13>=TH_BUY,"خرید "&$C13,IF($AD13<=TH_SSELL,"اجتناب / بستن موقعیت",IF($AD13<=TH_SELL,"ضعیف","بی‌طرف")))))) | AF13: =IF($A13="","","سهم پایه: "&IFERROR(TEXT($AB13,"0.0"),"—")&" | وضعیت: "&$Q13&" | نوسان ضمنی: "&IFERROR(TEXT($U13,"0%"),"—")&" | بازار÷نظری: "&IFERROR(TEXT($Z13,"0.00"),"—")&" | اهرم: "&IFERROR(TEXT($AA13,"0.0"),"—")&"x"&" | "&$G13&" روز تا سررسید")
O14: =IF($A14="","",IFERROR(INDEX(Underlying!$B$1:$B$5000,MATCH($D14,Underlying!$A$1:$A$5000,0)),"")) | P14: =IF($A14="","",IFERROR($O14/$E14,"")) | Q14: =IF($A14="","",IF($P14="","",IF($C14="Call",IF($P14>1+OPT_ATM_BAND,"ITM",IF($P14<1-OPT_ATM_BAND,"OTM","ATM")),IF($P14<1-OPT_ATM_BAND,"ITM",IF($P14>1+OPT_ATM_BAND,"OTM","ATM"))))) | R14: =IF($A14="","",IFERROR(IF($C14="Call",MAX(0,$O14-$E14),MAX(0,$E14-$O14)),"")) | S14: =IF($A14="","",IFERROR(MAX(0,$I14-$R14),"")) | T14: =IF($A14="","",IFERROR($G14/365,"")) | U14: =IF($A14="","",IF(OR($P14="",ABS($P14-1)>3*OPT_ATM_BAND),"",IFERROR($I14/$O14*SQRT(2*PI()/$T14),""))) | V14: =IF($A14="","",IFERROR((LN($O14/$E14)+(OPT_RF+OPT_VOL^2/2)*$T14)/(OPT_VOL*SQRT($T14)),"")) | W14: =IF($A14="","",IFERROR($V14-OPT_VOL*SQRT($T14),"")) | X14: =IF($A14="","",IFERROR(IF($C14="Call",NORMSDIST($V14),NORMSDIST($V14)-1),"")) | Y14: =IF($A14="","",IFERROR(IF($C14="Call",$O14*NORMSDIST($V14)-$E14*EXP(-OPT_RF*$T14)*NORMSDIST($W14),$E14*EXP(-OPT_RF*$T14)*NORMSDIST(-$W14)-$O14*NORMSDIST(-$V14)),"")) | Z14: =IF($A14="","",IFERROR($I14/$Y14,"")) | AA14: =IF($A14="","",IFERROR($O14*ABS($X14)/$I14,"")) | AB14: =IF($A14="","",IFERROR(INDEX(Underlying!$D$1:$D$5000,MATCH($D14,Underlying!$A$1:$A$5000,0)),0)) | AC14: =IF($A14="","",IF(AND($J14>=OPT_MIN_VOL,$G14>=OPT_MIN_DTE),"بله","خیر")) | AD14: =IF($A14="","",IF($AC14="خیر",0,IFERROR(MAX(-10,MIN(10,IF($C14="Call",$AB14,-$AB14)*0.6+IF($Z14<0.85,2,IF($Z14>1.25,-2,0))+IF($Q14="ATM",1,IF($Q14="ITM",0.5,-1))+IF($G14>=30,0.5,-0.5))),0))) | AE14: =IF($A14="","",IF($AC14="خیر","بدون سیگنال (نقدشوندگی/سررسید)",IF($AD14>=TH_SBUY,"خرید قوی "&$C14,IF($AD14>=TH_BUY,"خرید "&$C14,IF($AD14<=TH_SSELL,"اجتناب / بستن موقعیت",IF($AD14<=TH_SELL,"ضعیف","بی‌طرف")))))) | AF14: =IF($A14="","","سهم پایه: "&IFERROR(TEXT($AB14,"0.0"),"—")&" | وضعیت: "&$Q14&" | نوسان ضمنی: "&IFERROR(TEXT($U14,"0%"),"—")&" | بازار÷نظری: "&IFERROR(TEXT($Z14,"0.00"),"—")&" | اهرم: "&IFERROR(TEXT($AA14,"0.0"),"—")&"x"&" | "&$G14&" روز تا سررسید")
O15: =IF($A15="","",IFERROR(INDEX(Underlying!$B$1:$B$5000,MATCH($D15,Underlying!$A$1:$A$5000,0)),"")) | P15: =IF($A15="","",IFERROR($O15/$E15,"")) | Q15: =IF($A15="","",IF($P15="","",IF($C15="Call",IF($P15>1+OPT_ATM_BAND,"ITM",IF($P15<1-OPT_ATM_BAND,"OTM","ATM")),IF($P15<1-OPT_ATM_BAND,"ITM",IF($P15>1+OPT_ATM_BAND,"OTM","ATM"))))) | R15: =IF($A15="","",IFERROR(IF($C15="Call",MAX(0,$O15-$E15),MAX(0,$E15-$O15)),"")) | S15: =IF($A15="","",IFERROR(MAX(0,$I15-$R15),"")) | T15: =IF($A15="","",IFERROR($G15/365,"")) | U15: =IF($A15="","",IF(OR($P15="",ABS($P15-1)>3*OPT_ATM_BAND),"",IFERROR($I15/$O15*SQRT(2*PI()/$T15),""))) | V15: =IF($A15="","",IFERROR((LN($O15/$E15)+(OPT_RF+OPT_VOL^2/2)*$T15)/(OPT_VOL*SQRT($T15)),"")) | W15: =IF($A15="","",IFERROR($V15-OPT_VOL*SQRT($T15),"")) | X15: =IF($A15="","",IFERROR(IF($C15="Call",NORMSDIST($V15),NORMSDIST($V15)-1),"")) | Y15: =IF($A15="","",IFERROR(IF($C15="Call",$O15*NORMSDIST($V15)-$E15*EXP(-OPT_RF*$T15)*NORMSDIST($W15),$E15*EXP(-OPT_RF*$T15)*NORMSDIST(-$W15)-$O15*NORMSDIST(-$V15)),"")) | Z15: =IF($A15="","",IFERROR($I15/$Y15,"")) | AA15: =IF($A15="","",IFERROR($O15*ABS($X15)/$I15,"")) | AB15: =IF($A15="","",IFERROR(INDEX(Underlying!$D$1:$D$5000,MATCH($D15,Underlying!$A$1:$A$5000,0)),0)) | AC15: =IF($A15="","",IF(AND($J15>=OPT_MIN_VOL,$G15>=OPT_MIN_DTE),"بله","خیر")) | AD15: =IF($A15="","",IF($AC15="خیر",0,IFERROR(MAX(-10,MIN(10,IF($C15="Call",$AB15,-$AB15)*0.6+IF($Z15<0.85,2,IF($Z15>1.25,-2,0))+IF($Q15="ATM",1,IF($Q15="ITM",0.5,-1))+IF($G15>=30,0.5,-0.5))),0))) | AE15: =IF($A15="","",IF($AC15="خیر","بدون سیگنال (نقدشوندگی/سررسید)",IF($AD15>=TH_SBUY,"خرید قوی "&$C15,IF($AD15>=TH_BUY,"خرید "&$C15,IF($AD15<=TH_SSELL,"اجتناب / بستن موقعیت",IF($AD15<=TH_SELL,"ضعیف","بی‌طرف")))))) | AF15: =IF($A15="","","سهم پایه: "&IFERROR(TEXT($AB15,"0.0"),"—")&" | وضعیت: "&$Q15&" | نوسان ضمنی: "&IFERROR(TEXT($U15,"0%"),"—")&" | بازار÷نظری: "&IFERROR(TEXT($Z15,"0.00"),"—")&" | اهرم: "&IFERROR(TEXT($AA15,"0.0"),"—")&"x"&" | "&$G15&" روز تا سررسید")
O16: =IF($A16="","",IFERROR(INDEX(Underlying!$B$1:$B$5000,MATCH($D16,Underlying!$A$1:$A$5000,0)),"")) | P16: =IF($A16="","",IFERROR($O16/$E16,"")) | Q16: =IF($A16="","",IF($P16="","",IF($C16="Call",IF($P16>1+OPT_ATM_BAND,"ITM",IF($P16<1-OPT_ATM_BAND,"OTM","ATM")),IF($P16<1-OPT_ATM_BAND,"ITM",IF($P16>1+OPT_ATM_BAND,"OTM","ATM"))))) | R16: =IF($A16="","",IFERROR(IF($C16="Call",MAX(0,$O16-$E16),MAX(0,$E16-$O16)),"")) | S16: =IF($A16="","",IFERROR(MAX(0,$I16-$R16),"")) | T16: =IF($A16="","",IFERROR($G16/365,"")) | U16: =IF($A16="","",IF(OR($P16="",ABS($P16-1)>3*OPT_ATM_BAND),"",IFERROR($I16/$O16*SQRT(2*PI()/$T16),""))) | V16: =IF($A16="","",IFERROR((LN($O16/$E16)+(OPT_RF+OPT_VOL^2/2)*$T16)/(OPT_VOL*SQRT($T16)),"")) | W16: =IF($A16="","",IFERROR($V16-OPT_VOL*SQRT($T16),"")) | X16: =IF($A16="","",IFERROR(IF($C16="Call",NORMSDIST($V16),NORMSDIST($V16)-1),"")) | Y16: =IF($A16="","",IFERROR(IF($C16="Call",$O16*NORMSDIST($V16)-$E16*EXP(-OPT_RF*$T16)*NORMSDIST($W16),$E16*EXP(-OPT_RF*$T16)*NORMSDIST(-$W16)-$O16*NORMSDIST(-$V16)),"")) | Z16: =IF($A16="","",IFERROR($I16/$Y16,"")) | AA16: =IF($A16="","",IFERROR($O16*ABS($X16)/$I16,"")) | AB16: =IF($A16="","",IFERROR(INDEX(Underlying!$D$1:$D$5000,MATCH($D16,Underlying!$A$1:$A$5000,0)),0)) | AC16: =IF($A16="","",IF(AND($J16>=OPT_MIN_VOL,$G16>=OPT_MIN_DTE),"بله","خیر")) | AD16: =IF($A16="","",IF($AC16="خیر",0,IFERROR(MAX(-10,MIN(10,IF($C16="Call",$AB16,-$AB16)*0.6+IF($Z16<0.85,2,IF($Z16>1.25,-2,0))+IF($Q16="ATM",1,IF($Q16="ITM",0.5,-1))+IF($G16>=30,0.5,-0.5))),0))) | AE16: =IF($A16="","",IF($AC16="خیر","بدون سیگنال (نقدشوندگی/سررسید)",IF($AD16>=TH_SBUY,"خرید قوی "&$C16,IF($AD16>=TH_BUY,"خرید "&$C16,IF($AD16<=TH_SSELL,"اجتناب / بستن موقعیت",IF($AD16<=TH_SELL,"ضعیف","بی‌طرف")))))) | AF16: =IF($A16="","","سهم پایه: "&IFERROR(TEXT($AB16,"0.0"),"—")&" | وضعیت: "&$Q16&" | نوسان ضمنی: "&IFERROR(TEXT($U16,"0%"),"—")&" | بازار÷نظری: "&IFERROR(TEXT($Z16,"0.00"),"—")&" | اهرم: "&IFERROR(TEXT($AA16,"0.0"),"—")&"x"&" | "&$G16&" روز تا سررسید")
O17: =IF($A17="","",IFERROR(INDEX(Underlying!$B$1:$B$5000,MATCH($D17,Underlying!$A$1:$A$5000,0)),"")) | P17: =IF($A17="","",IFERROR($O17/$E17,"")) | Q17: =IF($A17="","",IF($P17="","",IF($C17="Call",IF($P17>1+OPT_ATM_BAND,"ITM",IF($P17<1-OPT_ATM_BAND,"OTM","ATM")),IF($P17<1-OPT_ATM_BAND,"ITM",IF($P17>1+OPT_ATM_BAND,"OTM","ATM"))))) | R17: =IF($A17="","",IFERROR(IF($C17="Call",MAX(0,$O17-$E17),MAX(0,$E17-$O17)),"")) | S17: =IF($A17="","",IFERROR(MAX(0,$I17-$R17),"")) | T17: =IF($A17="","",IFERROR($G17/365,"")) | U17: =IF($A17="","",IF(OR($P17="",ABS($P17-1)>3*OPT_ATM_BAND),"",IFERROR($I17/$O17*SQRT(2*PI()/$T17),""))) | V17: =IF($A17="","",IFERROR((LN($O17/$E17)+(OPT_RF+OPT_VOL^2/2)*$T17)/(OPT_VOL*SQRT($T17)),"")) | W17: =IF($A17="","",IFERROR($V17-OPT_VOL*SQRT($T17),"")) | X17: =IF($A17="","",IFERROR(IF($C17="Call",NORMSDIST($V17),NORMSDIST($V17)-1),"")) | Y17: =IF($A17="","",IFERROR(IF($C17="Call",$O17*NORMSDIST($V17)-$E17*EXP(-OPT_RF*$T17)*NORMSDIST($W17),$E17*EXP(-OPT_RF*$T17)*NORMSDIST(-$W17)-$O17*NORMSDIST(-$V17)),"")) | Z17: =IF($A17="","",IFERROR($I17/$Y17,"")) | AA17: =IF($A17="","",IFERROR($O17*ABS($X17)/$I17,"")) | AB17: =IF($A17="","",IFERROR(INDEX(Underlying!$D$1:$D$5000,MATCH($D17,Underlying!$A$1:$A$5000,0)),0)) | AC17: =IF($A17="","",IF(AND($J17>=OPT_MIN_VOL,$G17>=OPT_MIN_DTE),"بله","خیر")) | AD17: =IF($A17="","",IF($AC17="خیر",0,IFERROR(MAX(-10,MIN(10,IF($C17="Call",$AB17,-$AB17)*0.6+IF($Z17<0.85,2,IF($Z17>1.25,-2,0))+IF($Q17="ATM",1,IF($Q17="ITM",0.5,-1))+IF($G17>=30,0.5,-0.5))),0))) | AE17: =IF($A17="","",IF($AC17="خیر","بدون سیگنال (نقدشوندگی/سررسید)",IF($AD17>=TH_SBUY,"خرید قوی "&$C17,IF($AD17>=TH_BUY,"خرید "&$C17,IF($AD17<=TH_SSELL,"اجتناب / بستن موقعیت",IF($AD17<=TH_SELL,"ضعیف","بی‌طرف")))))) | AF17: =IF($A17="","","سهم پایه: "&IFERROR(TEXT($AB17,"0.0"),"—")&" | وضعیت: "&$Q17&" | نوسان ضمنی: "&IFERROR(TEXT($U17,"0%"),"—")&" | بازار÷نظری: "&IFERROR(TEXT($Z17,"0.00"),"—")&" | اهرم: "&IFERROR(TEXT($AA17,"0.0"),"—")&"x"&" | "&$G17&" روز تا سررسید")
O18: =IF($A18="","",IFERROR(INDEX(Underlying!$B$1:$B$5000,MATCH($D18,Underlying!$A$1:$A$5000,0)),"")) | P18: =IF($A18="","",IFERROR($O18/$E18,"")) | Q18: =IF($A18="","",IF($P18="","",IF($C18="Call",IF($P18>1+OPT_ATM_BAND,"ITM",IF($P18<1-OPT_ATM_BAND,"OTM","ATM")),IF($P18<1-OPT_ATM_BAND,"ITM",IF($P18>1+OPT_ATM_BAND,"OTM","ATM"))))) | R18: =IF($A18="","",IFERROR(IF($C18="Call",MAX(0,$O18-$E18),MAX(0,$E18-$O18)),"")) | S18: =IF($A18="","",IFERROR(MAX(0,$I18-$R18),"")) | T18: =IF($A18="","",IFERROR($G18/365,"")) | U18: =IF($A18="","",IF(OR($P18="",ABS($P18-1)>3*OPT_ATM_BAND),"",IFERROR($I18/$O18*SQRT(2*PI()/$T18),""))) | V18: =IF($A18="","",IFERROR((LN($O18/$E18)+(OPT_RF+OPT_VOL^2/2)*$T18)/(OPT_VOL*SQRT($T18)),"")) | W18: =IF($A18="","",IFERROR($V18-OPT_VOL*SQRT($T18),"")) | X18: =IF($A18="","",IFERROR(IF($C18="Call",NORMSDIST($V18),NORMSDIST($V18)-1),"")) | Y18: =IF($A18="","",IFERROR(IF($C18="Call",$O18*NORMSDIST($V18)-$E18*EXP(-OPT_RF*$T18)*NORMSDIST($W18),$E18*EXP(-OPT_RF*$T18)*NORMSDIST(-$W18)-$O18*NORMSDIST(-$V18)),"")) | Z18: =IF($A18="","",IFERROR($I18/$Y18,"")) | AA18: =IF($A18="","",IFERROR($O18*ABS($X18)/$I18,"")) | AB18: =IF($A18="","",IFERROR(INDEX(Underlying!$D$1:$D$5000,MATCH($D18,Underlying!$A$1:$A$5000,0)),0)) | AC18: =IF($A18="","",IF(AND($J18>=OPT_MIN_VOL,$G18>=OPT_MIN_DTE),"بله","خیر")) | AD18: =IF($A18="","",IF($AC18="خیر",0,IFERROR(MAX(-10,MIN(10,IF($C18="Call",$AB18,-$AB18)*0.6+IF($Z18<0.85,2,IF($Z18>1.25,-2,0))+IF($Q18="ATM",1,IF($Q18="ITM",0.5,-1))+IF($G18>=30,0.5,-0.5))),0))) | AE18: =IF($A18="","",IF($AC18="خیر","بدون سیگنال (نقدشوندگی/سررسید)",IF($AD18>=TH_SBUY,"خرید قوی "&$C18,IF($AD18>=TH_BUY,"خرید "&$C18,IF($AD18<=TH_SSELL,"اجتناب / بستن موقعیت",IF($AD18<=TH_SELL,"ضعیف","بی‌طرف")))))) | AF18: =IF($A18="","","سهم پایه: "&IFERROR(TEXT($AB18,"0.0"),"—")&" | وضعیت: "&$Q18&" | نوسان ضمنی: "&IFERROR(TEXT($U18,"0%"),"—")&" | بازار÷نظری: "&IFERROR(TEXT($Z18,"0.00"),"—")&" | اهرم: "&IFERROR(TEXT($AA18,"0.0"),"—")&"x"&" | "&$G18&" روز تا سررسید")
O19: =IF($A19="","",IFERROR(INDEX(Underlying!$B$1:$B$5000,MATCH($D19,Underlying!$A$1:$A$5000,0)),"")) | P19: =IF($A19="","",IFERROR($O19/$E19,"")) | Q19: =IF($A19="","",IF($P19="","",IF($C19="Call",IF($P19>1+OPT_ATM_BAND,"ITM",IF($P19<1-OPT_ATM_BAND,"OTM","ATM")),IF($P19<1-OPT_ATM_BAND,"ITM",IF($P19>1+OPT_ATM_BAND,"OTM","ATM"))))) | R19: =IF($A19="","",IFERROR(IF($C19="Call",MAX(0,$O19-$E19),MAX(0,$E19-$O19)),"")) | S19: =IF($A19="","",IFERROR(MAX(0,$I19-$R19),"")) | T19: =IF($A19="","",IFERROR($G19/365,"")) | U19: =IF($A19="","",IF(OR($P19="",ABS($P19-1)>3*OPT_ATM_BAND),"",IFERROR($I19/$O19*SQRT(2*PI()/$T19),""))) | V19: =IF($A19="","",IFERROR((LN($O19/$E19)+(OPT_RF+OPT_VOL^2/2)*$T19)/(OPT_VOL*SQRT($T19)),"")) | W19: =IF($A19="","",IFERROR($V19-OPT_VOL*SQRT($T19),"")) | X19: =IF($A19="","",IFERROR(IF($C19="Call",NORMSDIST($V19),NORMSDIST($V19)-1),"")) | Y19: =IF($A19="","",IFERROR(IF($C19="Call",$O19*NORMSDIST($V19)-$E19*EXP(-OPT_RF*$T19)*NORMSDIST($W19),$E19*EXP(-OPT_RF*$T19)*NORMSDIST(-$W19)-$O19*NORMSDIST(-$V19)),"")) | Z19: =IF($A19="","",IFERROR($I19/$Y19,"")) | AA19: =IF($A19="","",IFERROR($O19*ABS($X19)/$I19,"")) | AB19: =IF($A19="","",IFERROR(INDEX(Underlying!$D$1:$D$5000,MATCH($D19,Underlying!$A$1:$A$5000,0)),0)) | AC19: =IF($A19="","",IF(AND($J19>=OPT_MIN_VOL,$G19>=OPT_MIN_DTE),"بله","خیر")) | AD19: =IF($A19="","",IF($AC19="خیر",0,IFERROR(MAX(-10,MIN(10,IF($C19="Call",$AB19,-$AB19)*0.6+IF($Z19<0.85,2,IF($Z19>1.25,-2,0))+IF($Q19="ATM",1,IF($Q19="ITM",0.5,-1))+IF($G19>=30,0.5,-0.5))),0))) | AE19: =IF($A19="","",IF($AC19="خیر","بدون سیگنال (نقدشوندگی/سررسید)",IF($AD19>=TH_SBUY,"خرید قوی "&$C19,IF($AD19>=TH_BUY,"خرید "&$C19,IF($AD19<=TH_SSELL,"اجتناب / بستن موقعیت",IF($AD19<=TH_SELL,"ضعیف","بی‌طرف")))))) | AF19: =IF($A19="","","سهم پایه: "&IFERROR(TEXT($AB19,"0.0"),"—")&" | وضعیت: "&$Q19&" | نوسان ضمنی: "&IFERROR(TEXT($U19,"0%"),"—")&" | بازار÷نظری: "&IFERROR(TEXT($Z19,"0.00"),"—")&" | اهرم: "&IFERROR(TEXT($AA19,"0.0"),"—")&"x"&" | "&$G19&" روز تا سررسید")
O20: =IF($A20="","",IFERROR(INDEX(Underlying!$B$1:$B$5000,MATCH($D20,Underlying!$A$1:$A$5000,0)),"")) | P20: =IF($A20="","",IFERROR($O20/$E20,"")) | Q20: =IF($A20="","",IF($P20="","",IF($C20="Call",IF($P20>1+OPT_ATM_BAND,"ITM",IF($P20<1-OPT_ATM_BAND,"OTM","ATM")),IF($P20<1-OPT_ATM_BAND,"ITM",IF($P20>1+OPT_ATM_BAND,"OTM","ATM"))))) | R20: =IF($A20="","",IFERROR(IF($C20="Call",MAX(0,$O20-$E20),MAX(0,$E20-$O20)),"")) | S20: =IF($A20="","",IFERROR(MAX(0,$I20-$R20),"")) | T20: =IF($A20="","",IFERROR($G20/365,"")) | U20: =IF($A20="","",IF(OR($P20="",ABS($P20-1)>3*OPT_ATM_BAND),"",IFERROR($I20/$O20*SQRT(2*PI()/$T20),""))) | V20: =IF($A20="","",IFERROR((LN($O20/$E20)+(OPT_RF+OPT_VOL^2/2)*$T20)/(OPT_VOL*SQRT($T20)),"")) | W20: =IF($A20="","",IFERROR($V20-OPT_VOL*SQRT($T20),"")) | X20: =IF($A20="","",IFERROR(IF($C20="Call",NORMSDIST($V20),NORMSDIST($V20)-1),"")) | Y20: =IF($A20="","",IFERROR(IF($C20="Call",$O20*NORMSDIST($V20)-$E20*EXP(-OPT_RF*$T20)*NORMSDIST($W20),$E20*EXP(-OPT_RF*$T20)*NORMSDIST(-$W20)-$O20*NORMSDIST(-$V20)),"")) | Z20: =IF($A20="","",IFERROR($I20/$Y20,"")) | AA20: =IF($A20="","",IFERROR($O20*ABS($X20)/$I20,"")) | AB20: =IF($A20="","",IFERROR(INDEX(Underlying!$D$1:$D$5000,MATCH($D20,Underlying!$A$1:$A$5000,0)),0)) | AC20: =IF($A20="","",IF(AND($J20>=OPT_MIN_VOL,$G20>=OPT_MIN_DTE),"بله","خیر")) | AD20: =IF($A20="","",IF($AC20="خیر",0,IFERROR(MAX(-10,MIN(10,IF($C20="Call",$AB20,-$AB20)*0.6+IF($Z20<0.85,2,IF($Z20>1.25,-2,0))+IF($Q20="ATM",1,IF($Q20="ITM",0.5,-1))+IF($G20>=30,0.5,-0.5))),0))) | AE20: =IF($A20="","",IF($AC20="خیر","بدون سیگنال (نقدشوندگی/سررسید)",IF($AD20>=TH_SBUY,"خرید قوی "&$C20,IF($AD20>=TH_BUY,"خرید "&$C20,IF($AD20<=TH_SSELL,"اجتناب / بستن موقعیت",IF($AD20<=TH_SELL,"ضعیف","بی‌طرف")))))) | AF20: =IF($A20="","","سهم پایه: "&IFERROR(TEXT($AB20,"0.0"),"—")&" | وضعیت: "&$Q20&" | نوسان ضمنی: "&IFERROR(TEXT($U20,"0%"),"—")&" | بازار÷نظری: "&IFERROR(TEXT($Z20,"0.00"),"—")&" | اهرم: "&IFERROR(TEXT($AA20,"0.0"),"—")&"x"&" | "&$G20&" روز تا سررسید")
O21: =IF($A21="","",IFERROR(INDEX(Underlying!$B$1:$B$5000,MATCH($D21,Underlying!$A$1:$A$5000,0)),"")) | P21: =IF($A21="","",IFERROR($O21/$E21,"")) | Q21: =IF($A21="","",IF($P21="","",IF($C21="Call",IF($P21>1+OPT_ATM_BAND,"ITM",IF($P21<1-OPT_ATM_BAND,"OTM","ATM")),IF($P21<1-OPT_ATM_BAND,"ITM",IF($P21>1+OPT_ATM_BAND,"OTM","ATM"))))) | R21: =IF($A21="","",IFERROR(IF($C21="Call",MAX(0,$O21-$E21),MAX(0,$E21-$O21)),"")) | S21: =IF($A21="","",IFERROR(MAX(0,$I21-$R21),"")) | T21: =IF($A21="","",IFERROR($G21/365,"")) | U21: =IF($A21="","",IF(OR($P21="",ABS($P21-1)>3*OPT_ATM_BAND),"",IFERROR($I21/$O21*SQRT(2*PI()/$T21),""))) | V21: =IF($A21="","",IFERROR((LN($O21/$E21)+(OPT_RF+OPT_VOL^2/2)*$T21)/(OPT_VOL*SQRT($T21)),"")) | W21: =IF($A21="","",IFERROR($V21-OPT_VOL*SQRT($T21),"")) | X21: =IF($A21="","",IFERROR(IF($C21="Call",NORMSDIST($V21),NORMSDIST($V21)-1),"")) | Y21: =IF($A21="","",IFERROR(IF($C21="Call",$O21*NORMSDIST($V21)-$E21*EXP(-OPT_RF*$T21)*NORMSDIST($W21),$E21*EXP(-OPT_RF*$T21)*NORMSDIST(-$W21)-$O21*NORMSDIST(-$V21)),"")) | Z21: =IF($A21="","",IFERROR($I21/$Y21,"")) | AA21: =IF($A21="","",IFERROR($O21*ABS($X21)/$I21,"")) | AB21: =IF($A21="","",IFERROR(INDEX(Underlying!$D$1:$D$5000,MATCH($D21,Underlying!$A$1:$A$5000,0)),0)) | AC21: =IF($A21="","",IF(AND($J21>=OPT_MIN_VOL,$G21>=OPT_MIN_DTE),"بله","خیر")) | AD21: =IF($A21="","",IF($AC21="خیر",0,IFERROR(MAX(-10,MIN(10,IF($C21="Call",$AB21,-$AB21)*0.6+IF($Z21<0.85,2,IF($Z21>1.25,-2,0))+IF($Q21="ATM",1,IF($Q21="ITM",0.5,-1))+IF($G21>=30,0.5,-0.5))),0))) | AE21: =IF($A21="","",IF($AC21="خیر","بدون سیگنال (نقدشوندگی/سررسید)",IF($AD21>=TH_SBUY,"خرید قوی "&$C21,IF($AD21>=TH_BUY,"خرید "&$C21,IF($AD21<=TH_SSELL,"اجتناب / بستن موقعیت",IF($AD21<=TH_SELL,"ضعیف","بی‌طرف")))))) | AF21: =IF($A21="","","سهم پایه: "&IFERROR(TEXT($AB21,"0.0"),"—")&" | وضعیت: "&$Q21&" | نوسان ضمنی: "&IFERROR(TEXT($U21,"0%"),"—")&" | بازار÷نظری: "&IFERROR(TEXT($Z21,"0.00"),"—")&" | اهرم: "&IFERROR(TEXT($AA21,"0.0"),"—")&"x"&" | "&$G21&" روز تا سررسید")
O22: =IF($A22="","",IFERROR(INDEX(Underlying!$B$1:$B$5000,MATCH($D22,Underlying!$A$1:$A$5000,0)),"")) | P22: =IF($A22="","",IFERROR($O22/$E22,"")) | Q22: =IF($A22="","",IF($P22="","",IF($C22="Call",IF($P22>1+OPT_ATM_BAND,"ITM",IF($P22<1-OPT_ATM_BAND,"OTM","ATM")),IF($P22<1-OPT_ATM_BAND,"ITM",IF($P22>1+OPT_ATM_BAND,"OTM","ATM"))))) | R22: =IF($A22="","",IFERROR(IF($C22="Call",MAX(0,$O22-$E22),MAX(0,$E22-$O22)),"")) | S22: =IF($A22="","",IFERROR(MAX(0,$I22-$R22),"")) | T22: =IF($A22="","",IFERROR($G22/365,"")) | U22: =IF($A22="","",IF(OR($P22="",ABS($P22-1)>3*OPT_ATM_BAND),"",IFERROR($I22/$O22*SQRT(2*PI()/$T22),""))) | V22: =IF($A22="","",IFERROR((LN($O22/$E22)+(OPT_RF+OPT_VOL^2/2)*$T22)/(OPT_VOL*SQRT($T22)),"")) | W22: =IF($A22="","",IFERROR($V22-OPT_VOL*SQRT($T22),"")) | X22: =IF($A22="","",IFERROR(IF($C22="Call",NORMSDIST($V22),NORMSDIST($V22)-1),"")) | Y22: =IF($A22="","",IFERROR(IF($C22="Call",$O22*NORMSDIST($V22)-$E22*EXP(-OPT_RF*$T22)*NORMSDIST($W22),$E22*EXP(-OPT_RF*$T22)*NORMSDIST(-$W22)-$O22*NORMSDIST(-$V22)),"")) | Z22: =IF($A22="","",IFERROR($I22/$Y22,"")) | AA22: =IF($A22="","",IFERROR($O22*ABS($X22)/$I22,"")) | AB22: =IF($A22="","",IFERROR(INDEX(Underlying!$D$1:$D$5000,MATCH($D22,Underlying!$A$1:$A$5000,0)),0)) | AC22: =IF($A22="","",IF(AND($J22>=OPT_MIN_VOL,$G22>=OPT_MIN_DTE),"بله","خیر")) | AD22: =IF($A22="","",IF($AC22="خیر",0,IFERROR(MAX(-10,MIN(10,IF($C22="Call",$AB22,-$AB22)*0.6+IF($Z22<0.85,2,IF($Z22>1.25,-2,0))+IF($Q22="ATM",1,IF($Q22="ITM",0.5,-1))+IF($G22>=30,0.5,-0.5))),0))) | AE22: =IF($A22="","",IF($AC22="خیر","بدون سیگنال (نقدشوندگی/سررسید)",IF($AD22>=TH_SBUY,"خرید قوی "&$C22,IF($AD22>=TH_BUY,"خرید "&$C22,IF($AD22<=TH_SSELL,"اجتناب / بستن موقعیت",IF($AD22<=TH_SELL,"ضعیف","بی‌طرف")))))) | AF22: =IF($A22="","","سهم پایه: "&IFERROR(TEXT($AB22,"0.0"),"—")&" | وضعیت: "&$Q22&" | نوسان ضمنی: "&IFERROR(TEXT($U22,"0%"),"—")&" | بازار÷نظری: "&IFERROR(TEXT($Z22,"0.00"),"—")&" | اهرم: "&IFERROR(TEXT($AA22,"0.0"),"—")&"x"&" | "&$G22&" روز تا سررسید")
O23: =IF($A23="","",IFERROR(INDEX(Underlying!$B$1:$B$5000,MATCH($D23,Underlying!$A$1:$A$5000,0)),"")) | P23: =IF($A23="","",IFERROR($O23/$E23,"")) | Q23: =IF($A23="","",IF($P23="","",IF($C23="Call",IF($P23>1+OPT_ATM_BAND,"ITM",IF($P23<1-OPT_ATM_BAND,"OTM","ATM")),IF($P23<1-OPT_ATM_BAND,"ITM",IF($P23>1+OPT_ATM_BAND,"OTM","ATM"))))) | R23: =IF($A23="","",IFERROR(IF($C23="Call",MAX(0,$O23-$E23),MAX(0,$E23-$O23)),"")) | S23: =IF($A23="","",IFERROR(MAX(0,$I23-$R23),"")) | T23: =IF($A23="","",IFERROR($G23/365,"")) | U23: =IF($A23="","",IF(OR($P23="",ABS($P23-1)>3*OPT_ATM_BAND),"",IFERROR($I23/$O23*SQRT(2*PI()/$T23),""))) | V23: =IF($A23="","",IFERROR((LN($O23/$E23)+(OPT_RF+OPT_VOL^2/2)*$T23)/(OPT_VOL*SQRT($T23)),"")) | W23: =IF($A23="","",IFERROR($V23-OPT_VOL*SQRT($T23),"")) | X23: =IF($A23="","",IFERROR(IF($C23="Call",NORMSDIST($V23),NORMSDIST($V23)-1),"")) | Y23: =IF($A23="","",IFERROR(IF($C23="Call",$O23*NORMSDIST($V23)-$E23*EXP(-OPT_RF*$T23)*NORMSDIST($W23),$E23*EXP(-OPT_RF*$T23)*NORMSDIST(-$W23)-$O23*NORMSDIST(-$V23)),"")) | Z23: =IF($A23="","",IFERROR($I23/$Y23,"")) | AA23: =IF($A23="","",IFERROR($O23*ABS($X23)/$I23,"")) | AB23: =IF($A23="","",IFERROR(INDEX(Underlying!$D$1:$D$5000,MATCH($D23,Underlying!$A$1:$A$5000,0)),0)) | AC23: =IF($A23="","",IF(AND($J23>=OPT_MIN_VOL,$G23>=OPT_MIN_DTE),"بله","خیر")) | AD23: =IF($A23="","",IF($AC23="خیر",0,IFERROR(MAX(-10,MIN(10,IF($C23="Call",$AB23,-$AB23)*0.6+IF($Z23<0.85,2,IF($Z23>1.25,-2,0))+IF($Q23="ATM",1,IF($Q23="ITM",0.5,-1))+IF($G23>=30,0.5,-0.5))),0))) | AE23: =IF($A23="","",IF($AC23="خیر","بدون سیگنال (نقدشوندگی/سررسید)",IF($AD23>=TH_SBUY,"خرید قوی "&$C23,IF($AD23>=TH_BUY,"خرید "&$C23,IF($AD23<=TH_SSELL,"اجتناب / بستن موقعیت",IF($AD23<=TH_SELL,"ضعیف","بی‌طرف")))))) | AF23: =IF($A23="","","سهم پایه: "&IFERROR(TEXT($AB23,"0.0"),"—")&" | وضعیت: "&$Q23&" | نوسان ضمنی: "&IFERROR(TEXT($U23,"0%"),"—")&" | بازار÷نظری: "&IFERROR(TEXT($Z23,"0.00"),"—")&" | اهرم: "&IFERROR(TEXT($AA23,"0.0"),"—")&"x"&" | "&$G23&" روز تا سررسید")
O24: =IF($A24="","",IFERROR(INDEX(Underlying!$B$1:$B$5000,MATCH($D24,Underlying!$A$1:$A$5000,0)),"")) | P24: =IF($A24="","",IFERROR($O24/$E24,"")) | Q24: =IF($A24="","",IF($P24="","",IF($C24="Call",IF($P24>1+OPT_ATM_BAND,"ITM",IF($P24<1-OPT_ATM_BAND,"OTM","ATM")),IF($P24<1-OPT_ATM_BAND,"ITM",IF($P24>1+OPT_ATM_BAND,"OTM","ATM"))))) | R24: =IF($A24="","",IFERROR(IF($C24="Call",MAX(0,$O24-$E24),MAX(0,$E24-$O24)),"")) | S24: =IF($A24="","",IFERROR(MAX(0,$I24-$R24),"")) | T24: =IF($A24="","",IFERROR($G24/365,"")) | U24: =IF($A24="","",IF(OR($P24="",ABS($P24-1)>3*OPT_ATM_BAND),"",IFERROR($I24/$O24*SQRT(2*PI()/$T24),""))) | V24: =IF($A24="","",IFERROR((LN($O24/$E24)+(OPT_RF+OPT_VOL^2/2)*$T24)/(OPT_VOL*SQRT($T24)),"")) | W24: =IF($A24="","",IFERROR($V24-OPT_VOL*SQRT($T24),"")) | X24: =IF($A24="","",IFERROR(IF($C24="Call",NORMSDIST($V24),NORMSDIST($V24)-1),"")) | Y24: =IF($A24="","",IFERROR(IF($C24="Call",$O24*NORMSDIST($V24)-$E24*EXP(-OPT_RF*$T24)*NORMSDIST($W24),$E24*EXP(-OPT_RF*$T24)*NORMSDIST(-$W24)-$O24*NORMSDIST(-$V24)),"")) | Z24: =IF($A24="","",IFERROR($I24/$Y24,"")) | AA24: =IF($A24="","",IFERROR($O24*ABS($X24)/$I24,"")) | AB24: =IF($A24="","",IFERROR(INDEX(Underlying!$D$1:$D$5000,MATCH($D24,Underlying!$A$1:$A$5000,0)),0)) | AC24: =IF($A24="","",IF(AND($J24>=OPT_MIN_VOL,$G24>=OPT_MIN_DTE),"بله","خیر")) | AD24: =IF($A24="","",IF($AC24="خیر",0,IFERROR(MAX(-10,MIN(10,IF($C24="Call",$AB24,-$AB24)*0.6+IF($Z24<0.85,2,IF($Z24>1.25,-2,0))+IF($Q24="ATM",1,IF($Q24="ITM",0.5,-1))+IF($G24>=30,0.5,-0.5))),0))) | AE24: =IF($A24="","",IF($AC24="خیر","بدون سیگنال (نقدشوندگی/سررسید)",IF($AD24>=TH_SBUY,"خرید قوی "&$C24,IF($AD24>=TH_BUY,"خرید "&$C24,IF($AD24<=TH_SSELL,"اجتناب / بستن موقعیت",IF($AD24<=TH_SELL,"ضعیف","بی‌طرف")))))) | AF24: =IF($A24="","","سهم پایه: "&IFERROR(TEXT($AB24,"0.0"),"—")&" | وضعیت: "&$Q24&" | نوسان ضمنی: "&IFERROR(TEXT($U24,"0%"),"—")&" | بازار÷نظری: "&IFERROR(TEXT($Z24,"0.00"),"—")&" | اهرم: "&IFERROR(TEXT($AA24,"0.0"),"—")&"x"&" | "&$G24&" روز تا سررسید")
... O124: =IF($A124="","",IFERROR(INDEX(Underlying!$B$1:$B$5000,MATCH($D124,Underlying!$A$1:$A$5000,0)),"")) | P124: =IF($A124="","",IFERROR($O124/$E124,"")) | Q124: =IF($A124="","",IF($P124="","",IF($C124="Call",IF($P124>1+OPT_ATM_BAND,"ITM",IF($P124<1-OPT_ATM_BAND,"OTM","ATM")),IF($P124<1-OPT_ATM_BAND,"ITM",IF($P124>1+OPT_ATM_BAND,"OTM","ATM"))))) | R124: =IF($A124="","",IFERROR(IF($C124="Call",MAX(0,$O124-$E124),MAX(0,$E124-$O124)),"")) | S124: =IF($A124="","",IFERROR(MAX(0,$I124-$R124),"")) | T124: =IF($A124="","",IFERROR($G124/365,"")) | U124: =IF($A124="","",IF(OR($P124="",ABS($P124-1)>3*OPT_ATM_BAND),"",IFERROR($I124/$O124*SQRT(2*PI()/$T124),""))) | V124: =IF($A124="","",IFERROR((LN($O124/$E124)+(OPT_RF+OPT_VOL^2/2)*$T124)/(OPT_VOL*SQRT($T124)),"")) | W124: =IF($A124="","",IFERROR($V124-OPT_VOL*SQRT($T124),"")) | X124: =IF($A124="","",IFERROR(IF($C124="Call",NORMSDIST($V124),NORMSDIST($V124)-1),"")) | Y124: =IF($A124="","",IFERROR(IF($C124="Call",$O124*NORMSDIST($V124)-$E124*EXP(-OPT_RF*$T124)*NORMSDIST($W124),$E124*EXP(-OPT_RF*$T124)*NORMSDIST(-$W124)-$O124*NORMSDIST(-$V124)),"")) | Z124: =IF($A124="","",IFERROR($I124/$Y124,"")) | AA124: =IF($A124="","",IFERROR($O124*ABS($X124)/$I124,"")) | AB124: =IF($A124="","",IFERROR(INDEX(Underlying!$D$1:$D$5000,MATCH($D124,Underlying!$A$1:$A$5000,0)),0)) | AC124: =IF($A124="","",IF(AND($J124>=OPT_MIN_VOL,$G124>=OPT_MIN_DTE),"بله","خیر")) | AD124: =IF($A124="","",IF($AC124="خیر",0,IFERROR(MAX(-10,MIN(10,IF($C124="Call",$AB124,-$AB124)*0.6+IF($Z124<0.85,2,IF($Z124>1.25,-2,0))+IF($Q124="ATM",1,IF($Q124="ITM",0.5,-1))+IF($G124>=30,0.5,-0.5))),0))) | AE124: =IF($A124="","",IF($AC124="خیر","بدون سیگنال (نقدشوندگی/سررسید)",IF($AD124>=TH_SBUY,"خرید قوی "&$C124,IF($AD124>=TH_BUY,"خرید "&$C124,IF($AD124<=TH_SSELL,"اجتناب / بستن موقعیت",IF($AD124<=TH_SELL,"ضعیف","بی‌طرف")))))) | AF124: =IF($A124="","","سهم پایه: "&IFERROR(TEXT($AB124,"0.0"),"—")&" | وضعیت: "&$Q124&" | نوسان ضمنی: "&IFERROR(TEXT($U124,"0%"),"—")&" | بازار÷نظری: "&IFERROR(TEXT($Z124,"0.00"),"—")&" | اهرم: "&IFERROR(TEXT($AA124,"0.0"),"—")&"x"&" | "&$G124&" روز تا سررسید")
A126: ⚠️ نکات صحت داده در این شیت:
A127: • فیلد openInterest (موقعیت‌های باز) در مستندات ریپو ثبت نشده است؛ نام دقیق آن باید با یک پاسخ واقعی MarketWatchOption تأیید شود.
A128: • نوسان ضمنی با تقریب Brenner–Subrahmanyam محاسبه شده: IV ≈ (C/S)×√(2π/T). این تقریب فقط نزدیک ATM دقت قابل قبول دارد؛ برای OTM عمیق خطا زیاد است.
A129: • قیمت نظری بلک-شولز با نوسان فرضی OPT_VOL از شیت Settings محاسبه می‌شود، نه با نوسان ضمنی بازار — یعنی «گران/ارزان» نسبت به فرض شماست، نه حقیقت مطلق.
A130: • بلک-شولز برای اختیار اروپایی است. اگر قرارداد آمریکایی باشد، قیمت نظری اختیار فروش کم‌برآورد می‌شود.

Sheet Underlying
A1: دارایی پایه (Underlying)
A2: این جدول را اسکریپت link_workbooks.py از فایل Stocks_Signals.xlsx پر می‌کند. تا وقتی خالی است، محاسبات آپشن مقدار نمی‌گیرند.
A3: نماد پایه | B3: آخرین قیمت | C3: قیمت پایانی | D3: امتیاز کل سهم | E3: سیگنال سهم | F3: قدرت سیگنال | G3: تاریخ به‌روزرسانی
A4: lVal18AFC | B4: pDrCotVal | C4: pClosing | D4: امتیاز کل | E4: برچسب | F4: ۱ تا ۵ | G4: -
A5: خودرو
A6: فولاد
A7: كگل
A46: برای پرکردن خودکار: python scripts/link_workbooks.py --stocks Stocks_Signals.xlsx --options Options_Signals.xlsx

Sheet Settings
A1: تنظیمات و پارامترهای سیستم
A2: هر عدد آبی‌رنگ قابل تغییر است؛ همه فرمول‌های فایل از همین سلول‌ها می‌خوانند.
B4: ۵) آستانه سیگنال (امتیاز کل از −۱۰ تا +۱۰)
B5: حد «خرید قوی» (≥) | C5: 5
B6: حد «خرید» (≥) | C6: 2
B7: حد «فروش» (≤) | C7: -2
B8: حد «فروش قوی» (≤) | C8: -5
B10: ۶) پارامترهای بخش آپشن
B11: نرخ بدون ریسک سالانه | C11: 0.3 | D11: برای قیمت‌گذاری بلک-شولز
B12: نوسان فرضی سالانه دارایی پایه | C12: 0.55 | D12: مبنای مقایسه گران/ارزان بودن قرارداد
B13: حداقل روز تا سررسید | C13: 7 | D13: کمتر از این، سیگنال معتبر نیست
B14: حداقل حجم معاملات روزانه قرارداد | C14: 100 | D14: فیلتر نقدشوندگی
B15: بازه ATM (± نسبت به قیمت اعمال) | C15: 0.03
B16: تعداد روز معاملاتی در سال | C16: 245
B18: ۸) سایر
B19: پنجره ساختار روند کوتاه (سقف/کف) | C19: 20 | D19: برای تشخیص Higher High / Lower Low
B20: پنجره ساختار روند بلند (سقف/کف) | C20: 60 | D20: روند میان‌مدت
B21: دامنه نوسان روزانه بازار | C21: 0.07 | D21: ⚠️ مقدار جاری را تأیید کنید
B22: حداقل ارزش معاملات روزانه معتبر (میلیارد ریال) | C22: 50 | D22: زیر این حد، سیگنال «کم‌اعتبار» علامت می‌خورد
B24: راهنمای رنگ: سلول زرد با متن آبی = ورودی قابل تغییر شما · متن مشکی = فرمول · متن سبز = ارجاع به شیت دیگر.

Sheet API_Map
A1: نگاشت ستون‌ها به APIهای بازار (API_Map)
A2: این شیت قرارداد رسمی بین فایل اکسل و اسکریپت پایتون است: اسکریپت ستون مقصد هر فیلد را از همین‌جا می‌خواند. منبع: ریپازیتوری BabakEslami/tse-market-data
A3: شیت | B3: ستون | C3: برچسب فارسی | D3: فیلد JSON | E3: Endpoint | F3: توضیح فیلد | G3: وضعیت تأیید
A4: Options | B4: A | C4: نماد قرارداد | D4: instrumentName | E4: https://webgw.tse.ir/InstrumentProvider/api/v1/MarketWatch/MarketWatchOption/fa | F4: نماد قرارداد اختیار | G4: تست واقعی
A5: Options | B5: B | C5: ISIN | D5: instrumentId | E5: https://webgw.tse.ir/InstrumentProvider/api/v1/MarketWatch/MarketWatchOption/fa | F5: ISIN قرارداد | G5: تست واقعی
A6: Options | B6: E | C6: قیمت اعمال | D6: qeymateEmal | E6: https://webgw.tse.ir/InstrumentProvider/api/v1/MarketWatch/MarketWatchOption/fa | F6: قیمت اعمال | G6: تست واقعی
A7: Options | B7: F | C7: تاریخ سررسید | D7: tarixSarresid | E7: https://webgw.tse.ir/InstrumentProvider/api/v1/MarketWatch/MarketWatchOption/fa | F7: تاریخ سررسید | G7: تست واقعی
A8: Options | B8: G | C8: روز تا سررسید | D8: baghimandetasarresid | E8: https://webgw.tse.ir/InstrumentProvider/api/v1/MarketWatch/MarketWatchOption/fa | F8: روز مانده تا سررسید | G8: تست واقعی
A9: Options | B9: H | C9: آخرین قیمت | D9: lastPrice | E9: https://webgw.tse.ir/InstrumentProvider/api/v1/MarketWatch/MarketWatchOption/fa | F9: آخرین قیمت قرارداد | G9: تست واقعی
A10: Options | B10: I | C10: قیمت پایانی | D10: closingPrice | E10: https://webgw.tse.ir/InstrumentProvider/api/v1/MarketWatch/MarketWatchOption/fa | F10: قیمت پایانی قرارداد | G10: تست واقعی
A11: Options | B11: J | C11: حجم معاملات | D11: tradeVolume | E11: https://webgw.tse.ir/InstrumentProvider/api/v1/MarketWatch/MarketWatchOption/fa | F11: حجم معاملات قرارداد | G11: تست واقعی
A12: Options | B12: K | C12: ارزش معاملات | D12: tradeValue | E12: https://webgw.tse.ir/InstrumentProvider/api/v1/MarketWatch/MarketWatchOption/fa | F12: ارزش معاملات قرارداد | G12: تست واقعی
A13: Options | B13: L | C13: تعداد معاملات | D13: tradeCount | E13: https://webgw.tse.ir/InstrumentProvider/api/v1/MarketWatch/MarketWatchOption/fa | F13: تعداد معاملات قرارداد | G13: تست واقعی
A14: Options | B14: M | C14: موقعیت‌های باز ⚠️ | D14: openInterest | E14: https://webgw.tse.ir/InstrumentProvider/api/v1/MarketWatch/MarketWatchOption/fa | F14: ⚠️ موقعیت‌های باز — نام فیلد در مستند ریپو نیامده | G14: نیازمند تأیید
... A27: Options | B27: AD | C27: امتیاز آپشن | D27: −۱۰ تا +۱۰ | E27: — | F27: — | G27: نامشخص
A29: دو الزام عملیاتی هنگام فراخوانی این APIها:
A30: ۱) هدر User-Agent مرورگری الزامی است؛ بدون آن پاسخ‌ها بلوکه می‌شوند.
A31: ۲) فراخوانی مستقیم از مرورگر به‌دلیل CORS/۴۰۳ کار نمی‌کند — باید از یک بک‌اند (همان اسکریپت پایتون) فراخوانی شود.
A32: ۳) ردیف‌های زردرنگ «نیازمند تأیید»اند: نام فیلدشان از نمونه ساختاری یا استنباط آمده، نه از یک پاسخ واقعی API. قبل از اتکای عملیاتی، با یک درخواست واقعی تأیید کنید.

Sheet Documentation
A1: راهنمای سیستم سیگنال‌دهی بازار سرمایه ایران
A2: نسخه ۱٫۰ · ساخته‌شده در ۱۴۰۵/۰۶/۱۴ · بدون VBA · همه محاسبات با فرمول اکسل
A3: ⚠️ داده‌های داخل فایل نمونه (DEMO) و ساختگی‌اند. هیچ عددی در این فایل داده واقعی بازار نیست. InsCode و ISIN نمادها هم تأییدنشده‌اند. پیش از هر تصمیم معاملاتی، داده‌ها را با scripts/tse_updater.py جایگزین کنید.
A4: ۱) فلسفه طراحی
A5: این فایل برای معامله‌گر میان‌مدت ساخته شده، نه روزانه. سه پرسش را پشت سر هم می‌پرسد:
A6: ۱. بازار کجاست؟ (رژیم بازار از شاخص کل و هم‌وزن) — اگر بازار نزولی است، سیگنال خرید تک‌سهم کم‌ارزش‌تر است.
A7: ۲. سهم در چه روندی است؟ (میانگین‌های متحرک + ساختار سقف/کف + شیب)
A8: ۳. پول هوشمند چه می‌کند؟ (سرانه خرید و فروش حقیقی، خالص جریان نرمال‌شده)
A9: تحلیل بنیادی عمداً وارد نشده است. این یک انتخاب است، نه فراموشی.
A10: ۲) یک هشدار روش‌شناختی که باید بخوانید
A11: «ورود پول حقیقی» به‌تنهایی سیگنال ضعیفی است. عدد خالص ریالی در نماد بزرگ همیشه بزرگ است بدون آنکه معنا داشته باشد. به همین دلیل این سیستم دو معیار نرمال‌شده را جایگزین کرده است:
A12: • سرانه خرید حقیقی ÷ سرانه فروش حقیقی — یعنی «هر خریدار حقیقی چقدر بزرگ‌تر از هر فروشنده حقیقی است».
... A16: شش زیرنمره مستقل ساخته می‌شود که هرکدام بین −۱۰ تا +۱۰ است، سپس با وزن‌های شیت Settings ترکیب می‌شوند:
A17: T — امتیاز روند | B17: قیمت نسبت به MA میان‌مدت (±۳) + آرایش MA میان/بلند (±۳) + شکست سقف یا کف کوتاه‌مدت (±۲) + شیب MA کوتاه (±۲)
A18: S — امتیاز پول هوشمند | B18: قدرت خریدار (±۴) + خالص ورود امروز نسبت به ارزش معاملات (±۳) + خالص ورود ۵ روزه (±۳)
A19: M — امتیاز میانگین‌ها | B19: (تعداد MAهایی که قیمت بالای آن‌هاست × ۵) − ۱۰ ← از −۱۰ (زیر همه) تا +۱۰ (بالای همه)
A20: V — امتیاز حجم | B20: جهت تغییر قیمت × شدت حجم نسبت به میانگین ۲۰ روزه (±۹). حجم بالا در روز مثبت تأیید است، در روز منفی هشدار.
A21: K — امتیاز بازار | B21: رژیم بازار از شاخص کل (±۳) و هم‌وزن (±۴) و مومنتوم هم‌وزن (±۳). یکسان برای همه نمادها.
A22: Z — امتیاز زمان | B22: چرخه هرست + پنجره گن + موج الیوت. پیش‌فرض وزن صفر.
A23: امتیاز کل = (T×W_TREND + S×W_SMART + M×W_MA + V×W_VOL + K×W_MARKET + Z×W_TIME) ÷ جمع وزن‌ها
A24: تقسیم بر جمع وزن‌ها عمدی است: اگر وزنی را صفر کنید یا وزن جدیدی اضافه کنید، مقیاس −۱۰ تا +۱۰ حفظ می‌شود.
A25: برچسب سیگنال | B25: امتیاز ≥ TH_SBUY → خرید قوی · ≥ TH_BUY → خرید · ≤ TH_SSELL → فروش قوی · ≤ TH_SELL → فروش · بقیه → نگهداری
A26: قدرت سیگنال ۱ تا ۵ | B26: بر اساس قدرمطلق امتیاز کل: ≥۸ → ۵ · ≥۵ → ۴ · ≥۳ → ۳ · ≥۱٫۵ → ۲ · بقیه → ۱
A27: ۵) چطور وزن‌ها را تغییر دهم؟
A28: فقط سلول‌های زرد شیت Settings را تغییر دهید. سلول «جمع وزن‌ها» باید ۱۰۰٪ بماند؛ اگر نماند، پیام قرمز نشان داده می‌شود ولی محاسبه همچنان درست است چون بر جمع واقعی تقسیم می‌شود.
A29: چند تنظیم پیشنهادی برای شروع:
A30: • بازار پرنوسان و بی‌روند: W_MARKET را بالا ببرید (مثلاً ۲۰٪) و W_VOL را پایین.
A31: • تمرکز روی پول هوشمند: W_SMART را تا ۴۵٪ ببرید ولی TH_BUY را هم بالاتر بگذارید تا سیگنال کاذب کمتر شود.
A32: • فعال‌سازی لایه زمانی: W_TIME را روی ۱۰٪ بگذارید و به همان اندازه از W_TREND کم کنید.
A33: ۷) اتصال به APIها
A34: شیت API_Map نگاشت کامل هر ستون به فیلد JSON و endpoint را دارد. اسکریپت پایتون همان را می‌خواند و ستون مقصد را پیدا می‌کند.
A35: جستجوی نماد | B35: GET https://cdn.tsetmc.com/api/Instrument/GetInstrumentSearch/{Query}
A36: قیمت لحظه‌ای | B36: GET https://cdn.tsetmc.com/api/ClosingPrice/GetClosingPriceInfo/{InsCode}
A37: تاریخچه روزانه | B37: GET https://cdn.tsetmc.com/api/ClosingPrice/GetClosingPriceDailyList/{InsCode}/{Top}
A38: حقیقی/حقوقی | B38: GET https://cdn.tsetmc.com/api/ClientType/GetClientType/{InsCode}/1/0
A39: حقیقی/حقوقی تاریخی | B39: GET https://cdn.tsetmc.com/api/ClientType/GetClientTypeHistory/{InsCode}/{DEven}
A40: سفارش‌ها | B40: GET https://cdn.tsetmc.com/api/BestLimits/{InsCode}
A41: شاخص‌ها | B41: GET https://cdn.tsetmc.com/api/Index/GetIndexB1LastAll/SelectedIndexes/1
A42: دیده‌بان کامل | B42: GET https://webgw.tse.ir/InstrumentProvider/api/v1/MarketWatch/MarketWatchCash/fa
A43: لایو یک نماد | B43: GET https://webgw.tse.ir/InstrumentProvider/api/v1/Instrument/LiveInstrumentByIdQuery/fa?InstrumentId={ISIN}
...
