Workbook

Sheet Dashboard
A1: داشبورد سیگنال بازار سرمایه ایران
A2: ⚠️ داده‌های این فایل نمونه (DEMO) و ساختگی‌اند — واقعی نیستند. برای استفاده واقعی با scripts/tse_updater.py از tsetmc جایگزین کنید.
A4: ۱) وضعیت کلی بازار
A5: تاریخ آخرین داده | B5: =IFERROR(INDEX(Market_Index!$C$1:$C$5000,MI_LASTROW),"—") -> 1405/06/11 | D5: تعداد نمادهای تحت نظر | E5: =COUNTA(Watchlist!$A$5:$A$12) -> 8
A6: شاخص کل | B6: =IFERROR(INDEX(Market_Index!$D$1:$D$5000,MI_LASTROW),"—") -> 2159994.4 | D6: ارزش معاملات نمادهای تحت نظر (م.ریال) | E6: =IFERROR(SUM(Calculations!$G$5:$G$64),0) -> 2784.8215
A7: تغییر روزانه شاخص کل | B7: =IFERROR(INDEX(Market_Index!$E$1:$E$5000,MI_LASTROW),"—") | D7: خالص ورود پول حقیقی امروز (م.ریال) | E7: =IFERROR(SUM(Calculations!$AC$5:$AC$64),0) -> -101.65453
A8: شاخص کل هم‌وزن | B8: =IFERROR(INDEX(Market_Index!$I$1:$I$5000,MI_LASTROW),"—") -> 796843.24 | D8: خالص ورود پول حقیقی ۵ روزه (م.ریال) | E8: =IFERROR(SUM(Calculations!$AH$5:$AH$64),0) -> 881.00999
A9: تغییر روزانه هم‌وزن | B9: =IFERROR(INDEX(Market_Index!$J$1:$J$5000,MI_LASTROW),"—") | D9: میانگین امتیاز کل نمادها | E9: =IFERROR(AVERAGE(Signals!$T$4:$T$63),0) -> -1.259375
A10: امتیاز رژیم بازار (−۱۰ تا +۱۰) | B10: =MARKET_SCORE -> -7 | D10: نسبت سیگنال خرید به فروش | E10: =IFERROR((COUNTIF(Signals!$U$4:$U$63,"خرید قوی")+COUNTIF(Signals!$U$4:$U$63,"خرید"))/(COUNTIF(Signals!$U$4:$U$63,"فروش قوی")+COUNTIF(Signals!$U$4:$U$63,"فروش")),"—") -> 0.5
A11: وضعیت بازار | B11: =MARKET_LABEL -> نزولی قوی | D11: جمع وزن‌های سیستم | E11: =W_SUM -> 1
A13: ۲) خلاصه سیگنال‌ها
A14: خرید قوی | B14: خرید | C14: نگهداری | D14: فروش | E14: فروش قوی
A15: =COUNTIF(Signals!$U$4:$U$63,"خرید قوی") -> 1 | B15: =COUNTIF(Signals!$U$4:$U$63,"خرید") -> 1 | C15: =COUNTIF(Signals!$U$4:$U$63,"نگهداری") -> 2 | D15: =COUNTIF(Signals!$U$4:$U$63,"فروش") -> 1 | E15: =COUNTIF(Signals!$U$4:$U$63,"فروش قوی") -> 3
A16: سیگنال‌های «کم‌اعتبار» (نقدشوندگی پایین): | B16: =COUNTIF(Signals!$Z$4:$Z$63,"کم‌اعتبار") -> 0
A18: ۳) ده نماد برتر برای خرید (فقط امتیاز ≥ حد خرید)
A19: رتبه | B19: نماد | C19: نام شرکت | D19: آخرین قیمت | E19: امتیاز کل | F19: سیگنال | G19: قدرت | H19: جریان پول هوشمند
A20: 1 | B20: =IFERROR(IF(INDEX(Calculations!$AP$5:$AP$64,MATCH(1,Calculations!$AT$5:$AT$64,0))>=TH_BUY,INDEX(Calculations!$A$5:$A$64,MATCH(1,Calculations!$AT$5:$AT$64,0)),""),"") -> شستا | C20: =IF($B20="","",IFERROR(INDEX(Signals!$B$4:$B$63,MATCH($B20,Signals!$A$4:$A$63,0)),"")) -> سرمايه گذاري تامين اجتماعي | D20: =IF($B20="","",IFERROR(INDEX(Signals!$E$4:$E$63,MATCH($B20,Signals!$A$4:$A$63,0)),"")) -> 2007 | E20: =IF($B20="","",IFERROR(INDEX(Signals!$T$4:$T$63,MATCH($B20,Signals!$A$4:$A$63,0)),"")) -> 6.35 | F20: =IF($B20="","",IFERROR(INDEX(Signals!$U$4:$U$63,MATCH($B20,Signals!$A$4:$A$63,0)),"")) -> خرید قوی | G20: =IF($B20="","",IFERROR(INDEX(Signals!$V$4:$V$63,MATCH($B20,Signals!$A$4:$A$63,0)),"")) -> 4 | H20: =IF($B20="","",IFERROR(INDEX(Signals!$J$4:$J$63,MATCH($B20,Signals!$A$4:$A$63,0)),"")) -> ورود قوی پول حقیقی
A21: 2 | B21: =IFERROR(IF(INDEX(Calculations!$AP$5:$AP$64,MATCH(2,Calculations!$AT$5:$AT$64,0))>=TH_BUY,INDEX(Calculations!$A$5:$A$64,MATCH(2,Calculations!$AT$5:$AT$64,0)),""),"") -> اخابر | C21: =IF($B21="","",IFERROR(INDEX(Signals!$B$4:$B$63,MATCH($B21,Signals!$A$4:$A$63,0)),"")) -> مخابرات ايران | D21: =IF($B21="","",IFERROR(INDEX(Signals!$E$4:$E$63,MATCH($B21,Signals!$A$4:$A$63,0)),"")) -> 1194 | E21: =IF($B21="","",IFERROR(INDEX(Signals!$T$4:$T$63,MATCH($B21,Signals!$A$4:$A$63,0)),"")) -> 3.95 | F21: =IF($B21="","",IFERROR(INDEX(Signals!$U$4:$U$63,MATCH($B21,Signals!$A$4:$A$63,0)),"")) -> خرید | G21: =IF($B21="","",IFERROR(INDEX(Signals!$V$4:$V$63,MATCH($B21,Signals!$A$4:$A$63,0)),"")) -> 3 | H21: =IF($B21="","",IFERROR(INDEX(Signals!$J$4:$J$63,MATCH($B21,Signals!$A$4:$A$63,0)),"")) -> ورود قوی پول حقیقی
A22: 3 | B22: =IFERROR(IF(INDEX(Calculations!$AP$5:$AP$64,MATCH(3,Calculations!$AT$5:$AT$64,0))>=TH_BUY,INDEX(Calculations!$A$5:$A$64,MATCH(3,Calculations!$AT$5:$AT$64,0)),""),"") | C22: =IF($B22="","",IFERROR(INDEX(Signals!$B$4:$B$63,MATCH($B22,Signals!$A$4:$A$63,0)),"")) | D22: =IF($B22="","",IFERROR(INDEX(Signals!$E$4:$E$63,MATCH($B22,Signals!$A$4:$A$63,0)),"")) | E22: =IF($B22="","",IFERROR(INDEX(Signals!$T$4:$T$63,MATCH($B22,Signals!$A$4:$A$63,0)),"")) | F22: =IF($B22="","",IFERROR(INDEX(Signals!$U$4:$U$63,MATCH($B22,Signals!$A$4:$A$63,0)),"")) | G22: =IF($B22="","",IFERROR(INDEX(Signals!$V$4:$V$63,MATCH($B22,Signals!$A$4:$A$63,0)),"")) | H22: =IF($B22="","",IFERROR(INDEX(Signals!$J$4:$J$63,MATCH($B22,Signals!$A$4:$A$63,0)),""))
A23: 4 | B23: =IFERROR(IF(INDEX(Calculations!$AP$5:$AP$64,MATCH(4,Calculations!$AT$5:$AT$64,0))>=TH_BUY,INDEX(Calculations!$A$5:$A$64,MATCH(4,Calculations!$AT$5:$AT$64,0)),""),"") | C23: =IF($B23="","",IFERROR(INDEX(Signals!$B$4:$B$63,MATCH($B23,Signals!$A$4:$A$63,0)),"")) | D23: =IF($B23="","",IFERROR(INDEX(Signals!$E$4:$E$63,MATCH($B23,Signals!$A$4:$A$63,0)),"")) | E23: =IF($B23="","",IFERROR(INDEX(Signals!$T$4:$T$63,MATCH($B23,Signals!$A$4:$A$63,0)),"")) | F23: =IF($B23="","",IFERROR(INDEX(Signals!$U$4:$U$63,MATCH($B23,Signals!$A$4:$A$63,0)),"")) | G23: =IF($B23="","",IFERROR(INDEX(Signals!$V$4:$V$63,MATCH($B23,Signals!$A$4:$A$63,0)),"")) | H23: =IF($B23="","",IFERROR(INDEX(Signals!$J$4:$J$63,MATCH($B23,Signals!$A$4:$A$63,0)),""))
A24: 5 | B24: =IFERROR(IF(INDEX(Calculations!$AP$5:$AP$64,MATCH(5,Calculations!$AT$5:$AT$64,0))>=TH_BUY,INDEX(Calculations!$A$5:$A$64,MATCH(5,Calculations!$AT$5:$AT$64,0)),""),"") | C24: =IF($B24="","",IFERROR(INDEX(Signals!$B$4:$B$63,MATCH($B24,Signals!$A$4:$A$63,0)),"")) | D24: =IF($B24="","",IFERROR(INDEX(Signals!$E$4:$E$63,MATCH($B24,Signals!$A$4:$A$63,0)),"")) | E24: =IF($B24="","",IFERROR(INDEX(Signals!$T$4:$T$63,MATCH($B24,Signals!$A$4:$A$63,0)),"")) | F24: =IF($B24="","",IFERROR(INDEX(Signals!$U$4:$U$63,MATCH($B24,Signals!$A$4:$A$63,0)),"")) | G24: =IF($B24="","",IFERROR(INDEX(Signals!$V$4:$V$63,MATCH($B24,Signals!$A$4:$A$63,0)),"")) | H24: =IF($B24="","",IFERROR(INDEX(Signals!$J$4:$J$63,MATCH($B24,Signals!$A$4:$A$63,0)),""))
A25: 6 | B25: =IFERROR(IF(INDEX(Calculations!$AP$5:$AP$64,MATCH(6,Calculations!$AT$5:$AT$64,0))>=TH_BUY,INDEX(Calculations!$A$5:$A$64,MATCH(6,Calculations!$AT$5:$AT$64,0)),""),"") | C25: =IF($B25="","",IFERROR(INDEX(Signals!$B$4:$B$63,MATCH($B25,Signals!$A$4:$A$63,0)),"")) | D25: =IF($B25="","",IFERROR(INDEX(Signals!$E$4:$E$63,MATCH($B25,Signals!$A$4:$A$63,0)),"")) | E25: =IF($B25="","",IFERROR(INDEX(Signals!$T$4:$T$63,MATCH($B25,Signals!$A$4:$A$63,0)),"")) | F25: =IF($B25="","",IFERROR(INDEX(Signals!$U$4:$U$63,MATCH($B25,Signals!$A$4:$A$63,0)),"")) | G25: =IF($B25="","",IFERROR(INDEX(Signals!$V$4:$V$63,MATCH($B25,Signals!$A$4:$A$63,0)),"")) | H25: =IF($B25="","",IFERROR(INDEX(Signals!$J$4:$J$63,MATCH($B25,Signals!$A$4:$A$63,0)),""))
A26: 7 | B26: =IFERROR(IF(INDEX(Calculations!$AP$5:$AP$64,MATCH(7,Calculations!$AT$5:$AT$64,0))>=TH_BUY,INDEX(Calculations!$A$5:$A$64,MATCH(7,Calculations!$AT$5:$AT$64,0)),""),"") | C26: =IF($B26="","",IFERROR(INDEX(Signals!$B$4:$B$63,MATCH($B26,Signals!$A$4:$A$63,0)),"")) | D26: =IF($B26="","",IFERROR(INDEX(Signals!$E$4:$E$63,MATCH($B26,Signals!$A$4:$A$63,0)),"")) | E26: =IF($B26="","",IFERROR(INDEX(Signals!$T$4:$T$63,MATCH($B26,Signals!$A$4:$A$63,0)),"")) | F26: =IF($B26="","",IFERROR(INDEX(Signals!$U$4:$U$63,MATCH($B26,Signals!$A$4:$A$63,0)),"")) | G26: =IF($B26="","",IFERROR(INDEX(Signals!$V$4:$V$63,MATCH($B26,Signals!$A$4:$A$63,0)),"")) | H26: =IF($B26="","",IFERROR(INDEX(Signals!$J$4:$J$63,MATCH($B26,Signals!$A$4:$A$63,0)),""))
A27: 8 | B27: =IFERROR(IF(INDEX(Calculations!$AP$5:$AP$64,MATCH(8,Calculations!$AT$5:$AT$64,0))>=TH_BUY,INDEX(Calculations!$A$5:$A$64,MATCH(8,Calculations!$AT$5:$AT$64,0)),""),"") | C27: =IF($B27="","",IFERROR(INDEX(Signals!$B$4:$B$63,MATCH($B27,Signals!$A$4:$A$63,0)),"")) | D27: =IF($B27="","",IFERROR(INDEX(Signals!$E$4:$E$63,MATCH($B27,Signals!$A$4:$A$63,0)),"")) | E27: =IF($B27="","",IFERROR(INDEX(Signals!$T$4:$T$63,MATCH($B27,Signals!$A$4:$A$63,0)),"")) | F27: =IF($B27="","",IFERROR(INDEX(Signals!$U$4:$U$63,MATCH($B27,Signals!$A$4:$A$63,0)),"")) | G27: =IF($B27="","",IFERROR(INDEX(Signals!$V$4:$V$63,MATCH($B27,Signals!$A$4:$A$63,0)),"")) | H27: =IF($B27="","",IFERROR(INDEX(Signals!$J$4:$J$63,MATCH($B27,Signals!$A$4:$A$63,0)),""))
A28: 9 | B28: =IFERROR(IF(INDEX(Calculations!$AP$5:$AP$64,MATCH(9,Calculations!$AT$5:$AT$64,0))>=TH_BUY,INDEX(Calculations!$A$5:$A$64,MATCH(9,Calculations!$AT$5:$AT$64,0)),""),"") | C28: =IF($B28="","",IFERROR(INDEX(Signals!$B$4:$B$63,MATCH($B28,Signals!$A$4:$A$63,0)),"")) | D28: =IF($B28="","",IFERROR(INDEX(Signals!$E$4:$E$63,MATCH($B28,Signals!$A$4:$A$63,0)),"")) | E28: =IF($B28="","",IFERROR(INDEX(Signals!$T$4:$T$63,MATCH($B28,Signals!$A$4:$A$63,0)),"")) | F28: =IF($B28="","",IFERROR(INDEX(Signals!$U$4:$U$63,MATCH($B28,Signals!$A$4:$A$63,0)),"")) | G28: =IF($B28="","",IFERROR(INDEX(Signals!$V$4:$V$63,MATCH($B28,Signals!$A$4:$A$63,0)),"")) | H28: =IF($B28="","",IFERROR(INDEX(Signals!$J$4:$J$63,MATCH($B28,Signals!$A$4:$A$63,0)),""))
A29: 10 | B29: =IFERROR(IF(INDEX(Calculations!$AP$5:$AP$64,MATCH(10,Calculations!$AT$5:$AT$64,0))>=TH_BUY,INDEX(Calculations!$A$5:$A$64,MATCH(10,Calculations!$AT$5:$AT$64,0)),""),"") | C29: =IF($B29="","",IFERROR(INDEX(Signals!$B$4:$B$63,MATCH($B29,Signals!$A$4:$A$63,0)),"")) | D29: =IF($B29="","",IFERROR(INDEX(Signals!$E$4:$E$63,MATCH($B29,Signals!$A$4:$A$63,0)),"")) | E29: =IF($B29="","",IFERROR(INDEX(Signals!$T$4:$T$63,MATCH($B29,Signals!$A$4:$A$63,0)),"")) | F29: =IF($B29="","",IFERROR(INDEX(Signals!$U$4:$U$63,MATCH($B29,Signals!$A$4:$A$63,0)),"")) | G29: =IF($B29="","",IFERROR(INDEX(Signals!$V$4:$V$63,MATCH($B29,Signals!$A$4:$A$63,0)),"")) | H29: =IF($B29="","",IFERROR(INDEX(Signals!$J$4:$J$63,MATCH($B29,Signals!$A$4:$A$63,0)),""))
A31: ۴) ده نماد برتر برای فروش (فقط امتیاز ≤ حد فروش)
A32: رتبه | B32: نماد | C32: نام شرکت | D32: آخرین قیمت | E32: امتیاز کل | F32: سیگنال | G32: قدرت | H32: جریان پول هوشمند
A33: 1 | B33: =IFERROR(IF(INDEX(Calculations!$AP$5:$AP$64,MATCH(1,Calculations!$AU$5:$AU$64,0))<=TH_SELL,INDEX(Calculations!$A$5:$A$64,MATCH(1,Calculations!$AU$5:$AU$64,0)),""),"") -> وبملت | C33: =IF($B33="","",IFERROR(INDEX(Signals!$B$4:$B$63,MATCH($B33,Signals!$A$4:$A$63,0)),"")) -> بانك ملت | D33: =IF($B33="","",IFERROR(INDEX(Signals!$E$4:$E$63,MATCH($B33,Signals!$A$4:$A$63,0)),"")) -> 4483 | E33: =IF($B33="","",IFERROR(INDEX(Signals!$T$4:$T$63,MATCH($B33,Signals!$A$4:$A$63,0)),"")) -> -7.45 | F33: =IF($B33="","",IFERROR(INDEX(Signals!$U$4:$U$63,MATCH($B33,Signals!$A$4:$A$63,0)),"")) -> فروش قوی | G33: =IF($B33="","",IFERROR(INDEX(Signals!$V$4:$V$63,MATCH($B33,Signals!$A$4:$A$63,0)),"")) -> 4 | H33: =IF($B33="","",IFERROR(INDEX(Signals!$J$4:$J$63,MATCH($B33,Signals!$A$4:$A$63,0)),"")) -> خروج قوی پول حقیقی
A34: 2 | B34: =IFERROR(IF(INDEX(Calculations!$AP$5:$AP$64,MATCH(2,Calculations!$AU$5:$AU$64,0))<=TH_SELL,INDEX(Calculations!$A$5:$A$64,MATCH(2,Calculations!$AU$5:$AU$64,0)),""),"") -> شپنا | C34: =IF($B34="","",IFERROR(INDEX(Signals!$B$4:$B$63,MATCH($B34,Signals!$A$4:$A$63,0)),"")) -> پالايش نفت اصفهان | D34: =IF($B34="","",IFERROR(INDEX(Signals!$E$4:$E$63,MATCH($B34,Signals!$A$4:$A$63,0)),"")) -> 3784 | E34: =IF($B34="","",IFERROR(INDEX(Signals!$T$4:$T$63,MATCH($B34,Signals!$A$4:$A$63,0)),"")) -> -6.175 | F34: =IF($B34="","",IFERROR(INDEX(Signals!$U$4:$U$63,MATCH($B34,Signals!$A$4:$A$63,0)),"")) -> فروش قوی | G34: =IF($B34="","",IFERROR(INDEX(Signals!$V$4:$V$63,MATCH($B34,Signals!$A$4:$A$63,0)),"")) -> 4 | H34: =IF($B34="","",IFERROR(INDEX(Signals!$J$4:$J$63,MATCH($B34,Signals!$A$4:$A$63,0)),"")) -> خروج پول حقیقی
A35: 3 | B35: =IFERROR(IF(INDEX(Calculations!$AP$5:$AP$64,MATCH(3,Calculations!$AU$5:$AU$64,0))<=TH_SELL,INDEX(Calculations!$A$5:$A$64,MATCH(3,Calculations!$AU$5:$AU$64,0)),""),"") -> فملي | C35: =IF($B35="","",IFERROR(INDEX(Signals!$B$4:$B$63,MATCH($B35,Signals!$A$4:$A$63,0)),"")) -> ملي صنايع مس ايران | D35: =IF($B35="","",IFERROR(INDEX(Signals!$E$4:$E$63,MATCH($B35,Signals!$A$4:$A$63,0)),"")) -> 6713 | E35: =IF($B35="","",IFERROR(INDEX(Signals!$T$4:$T$63,MATCH($B35,Signals!$A$4:$A$63,0)),"")) -> -5.2 | F35: =IF($B35="","",IFERROR(INDEX(Signals!$U$4:$U$63,MATCH($B35,Signals!$A$4:$A$63,0)),"")) -> فروش قوی | G35: =IF($B35="","",IFERROR(INDEX(Signals!$V$4:$V$63,MATCH($B35,Signals!$A$4:$A$63,0)),"")) -> 4 | H35: =IF($B35="","",IFERROR(INDEX(Signals!$J$4:$J$63,MATCH($B35,Signals!$A$4:$A$63,0)),"")) -> خروج پول حقیقی
A36: 4 | B36: =IFERROR(IF(INDEX(Calculations!$AP$5:$AP$64,MATCH(4,Calculations!$AU$5:$AU$64,0))<=TH_SELL,INDEX(Calculations!$A$5:$A$64,MATCH(4,Calculations!$AU$5:$AU$64,0)),""),"") -> كگل | C36: =IF($B36="","",IFERROR(INDEX(Signals!$B$4:$B$63,MATCH($B36,Signals!$A$4:$A$63,0)),"")) -> معدني و صنعتي گل گهر | D36: =IF($B36="","",IFERROR(INDEX(Signals!$E$4:$E$63,MATCH($B36,Signals!$A$4:$A$63,0)),"")) -> 11194 | E36: =IF($B36="","",IFERROR(INDEX(Signals!$T$4:$T$63,MATCH($B36,Signals!$A$4:$A$63,0)),"")) -> -4 | F36: =IF($B36="","",IFERROR(INDEX(Signals!$U$4:$U$63,MATCH($B36,Signals!$A$4:$A$63,0)),"")) -> فروش | G36: =IF($B36="","",IFERROR(INDEX(Signals!$V$4:$V$63,MATCH($B36,Signals!$A$4:$A$63,0)),"")) -> 3 | H36: =IF($B36="","",IFERROR(INDEX(Signals!$J$4:$J$63,MATCH($B36,Signals!$A$4:$A$63,0)),"")) -> ورود پول حقیقی
A37: 5 | B37: =IFERROR(IF(INDEX(Calculations!$AP$5:$AP$64,MATCH(5,Calculations!$AU$5:$AU$64,0))<=TH_SELL,INDEX(Calculations!$A$5:$A$64,MATCH(5,Calculations!$AU$5:$AU$64,0)),""),"") | C37: =IF($B37="","",IFERROR(INDEX(Signals!$B$4:$B$63,MATCH($B37,Signals!$A$4:$A$63,0)),"")) | D37: =IF($B37="","",IFERROR(INDEX(Signals!$E$4:$E$63,MATCH($B37,Signals!$A$4:$A$63,0)),"")) | E37: =IF($B37="","",IFERROR(INDEX(Signals!$T$4:$T$63,MATCH($B37,Signals!$A$4:$A$63,0)),"")) | F37: =IF($B37="","",IFERROR(INDEX(Signals!$U$4:$U$63,MATCH($B37,Signals!$A$4:$A$63,0)),"")) | G37: =IF($B37="","",IFERROR(INDEX(Signals!$V$4:$V$63,MATCH($B37,Signals!$A$4:$A$63,0)),"")) | H37: =IF($B37="","",IFERROR(INDEX(Signals!$J$4:$J$63,MATCH($B37,Signals!$A$4:$A$63,0)),""))
A38: 6 | B38: =IFERROR(IF(INDEX(Calculations!$AP$5:$AP$64,MATCH(6,Calculations!$AU$5:$AU$64,0))<=TH_SELL,INDEX(Calculations!$A$5:$A$64,MATCH(6,Calculations!$AU$5:$AU$64,0)),""),"") | C38: =IF($B38="","",IFERROR(INDEX(Signals!$B$4:$B$63,MATCH($B38,Signals!$A$4:$A$63,0)),"")) | D38: =IF($B38="","",IFERROR(INDEX(Signals!$E$4:$E$63,MATCH($B38,Signals!$A$4:$A$63,0)),"")) | E38: =IF($B38="","",IFERROR(INDEX(Signals!$T$4:$T$63,MATCH($B38,Signals!$A$4:$A$63,0)),"")) | F38: =IF($B38="","",IFERROR(INDEX(Signals!$U$4:$U$63,MATCH($B38,Signals!$A$4:$A$63,0)),"")) | G38: =IF($B38="","",IFERROR(INDEX(Signals!$V$4:$V$63,MATCH($B38,Signals!$A$4:$A$63,0)),"")) | H38: =IF($B38="","",IFERROR(INDEX(Signals!$J$4:$J$63,MATCH($B38,Signals!$A$4:$A$63,0)),""))
A39: 7 | B39: =IFERROR(IF(INDEX(Calculations!$AP$5:$AP$64,MATCH(7,Calculations!$AU$5:$AU$64,0))<=TH_SELL,INDEX(Calculations!$A$5:$A$64,MATCH(7,Calculations!$AU$5:$AU$64,0)),""),"") | C39: =IF($B39="","",IFERROR(INDEX(Signals!$B$4:$B$63,MATCH($B39,Signals!$A$4:$A$63,0)),"")) | D39: =IF($B39="","",IFERROR(INDEX(Signals!$E$4:$E$63,MATCH($B39,Signals!$A$4:$A$63,0)),"")) | E39: =IF($B39="","",IFERROR(INDEX(Signals!$T$4:$T$63,MATCH($B39,Signals!$A$4:$A$63,0)),"")) | F39: =IF($B39="","",IFERROR(INDEX(Signals!$U$4:$U$63,MATCH($B39,Signals!$A$4:$A$63,0)),"")) | G39: =IF($B39="","",IFERROR(INDEX(Signals!$V$4:$V$63,MATCH($B39,Signals!$A$4:$A$63,0)),"")) | H39: =IF($B39="","",IFERROR(INDEX(Signals!$J$4:$J$63,MATCH($B39,Signals!$A$4:$A$63,0)),""))
A40: 8 | B40: =IFERROR(IF(INDEX(Calculations!$AP$5:$AP$64,MATCH(8,Calculations!$AU$5:$AU$64,0))<=TH_SELL,INDEX(Calculations!$A$5:$A$64,MATCH(8,Calculations!$AU$5:$AU$64,0)),""),"") | C40: =IF($B40="","",IFERROR(INDEX(Signals!$B$4:$B$63,MATCH($B40,Signals!$A$4:$A$63,0)),"")) | D40: =IF($B40="","",IFERROR(INDEX(Signals!$E$4:$E$63,MATCH($B40,Signals!$A$4:$A$63,0)),"")) | E40: =IF($B40="","",IFERROR(INDEX(Signals!$T$4:$T$63,MATCH($B40,Signals!$A$4:$A$63,0)),"")) | F40: =IF($B40="","",IFERROR(INDEX(Signals!$U$4:$U$63,MATCH($B40,Signals!$A$4:$A$63,0)),"")) | G40: =IF($B40="","",IFERROR(INDEX(Signals!$V$4:$V$63,MATCH($B40,Signals!$A$4:$A$63,0)),"")) | H40: =IF($B40="","",IFERROR(INDEX(Signals!$J$4:$J$63,MATCH($B40,Signals!$A$4:$A$63,0)),""))
A41: 9 | B41: =IFERROR(IF(INDEX(Calculations!$AP$5:$AP$64,MATCH(9,Calculations!$AU$5:$AU$64,0))<=TH_SELL,INDEX(Calculations!$A$5:$A$64,MATCH(9,Calculations!$AU$5:$AU$64,0)),""),"") | C41: =IF($B41="","",IFERROR(INDEX(Signals!$B$4:$B$63,MATCH($B41,Signals!$A$4:$A$63,0)),"")) | D41: =IF($B41="","",IFERROR(INDEX(Signals!$E$4:$E$63,MATCH($B41,Signals!$A$4:$A$63,0)),"")) | E41: =IF($B41="","",IFERROR(INDEX(Signals!$T$4:$T$63,MATCH($B41,Signals!$A$4:$A$63,0)),"")) | F41: =IF($B41="","",IFERROR(INDEX(Signals!$U$4:$U$63,MATCH($B41,Signals!$A$4:$A$63,0)),"")) | G41: =IF($B41="","",IFERROR(INDEX(Signals!$V$4:$V$63,MATCH($B41,Signals!$A$4:$A$63,0)),"")) | H41: =IF($B41="","",IFERROR(INDEX(Signals!$J$4:$J$63,MATCH($B41,Signals!$A$4:$A$63,0)),""))
A42: 10 | B42: =IFERROR(IF(INDEX(Calculations!$AP$5:$AP$64,MATCH(10,Calculations!$AU$5:$AU$64,0))<=TH_SELL,INDEX(Calculations!$A$5:$A$64,MATCH(10,Calculations!$AU$5:$AU$64,0)),""),"") | C42: =IF($B42="","",IFERROR(INDEX(Signals!$B$4:$B$63,MATCH($B42,Signals!$A$4:$A$63,0)),"")) | D42: =IF($B42="","",IFERROR(INDEX(Signals!$E$4:$E$63,MATCH($B42,Signals!$A$4:$A$63,0)),"")) | E42: =IF($B42="","",IFERROR(INDEX(Signals!$T$4:$T$63,MATCH($B42,Signals!$A$4:$A$63,0)),"")) | F42: =IF($B42="","",IFERROR(INDEX(Signals!$U$4:$U$63,MATCH($B42,Signals!$A$4:$A$63,0)),"")) | G42: =IF($B42="","",IFERROR(INDEX(Signals!$V$4:$V$63,MATCH($B42,Signals!$A$4:$A$63,0)),"")) | H42: =IF($B42="","",IFERROR(INDEX(Signals!$J$4:$J$63,MATCH($B42,Signals!$A$4:$A$63,0)),""))
A44: خواندن این داشبورد از راست به چپ و از بالا به پایین: اول «امتیاز رژیم بازار» را ببینید.
A45: اگر رژیم بازار نزولی قوی است، سیگنال‌های خرید تک‌سهم را با احتیاط بیشتری بخوانید — سیستم این را با وزن W_MARKET لحاظ کرده ولی جایگزین قضاوت شما نیست.
...

Sheet Signals
A1: جدول سیگنال نهایی (Signals)
A2: قابل فیلتر و مرتب‌سازی. امتیاز کل بین −۱۰ تا +۱۰ است و آستانه‌های برچسب در Settings تعریف شده‌اند.
A3: نماد | B3: نام شرکت | C3: صنعت | D3: بازار | E3: آخرین قیمت | F3: درصد تغییر | G3: روند کل بازار | H3: روند سهم | I3: ساختار روند | J3: جریان پول هوشمند | K3: قدرت خریدار | L3: وضعیت میانگین‌ها | M3: نسبت حجم | N3: امتیاز روند | O3: امتیاز پول هوشمند | P3: امتیاز میانگین‌ها | Q3: امتیاز حجم | R3: امتیاز بازار | S3: امتیاز زمان | T3: امتیاز کل | U3: سیگنال نهایی | V3: قدرت سیگنال | W3: دلیل سیگنال | X3: حد ضرر پیشنهادی | Y3: ریسک تا حد ضرر | Z3: اعتبار
A4: =IF(Calculations!$A$5="","",Calculations!$A$5) -> فولاد | B4: =IF($A4="","",IFERROR(INDEX(Watchlist!$B$1:$B$5000,MATCH($A4,Watchlist!$A$1:$A$5000,0)),"")) -> فولاد مباركه اصفهان | C4: =IF($A4="","",IFERROR(INDEX(Watchlist!$F$1:$F$5000,MATCH($A4,Watchlist!$A$1:$A$5000,0)),"")) -> فلزات اساسي | D4: =IF($A4="","",IFERROR(INDEX(Watchlist!$E$1:$E$5000,MATCH($A4,Watchlist!$A$1:$A$5000,0)),"")) -> بورس | E4: =IF($A4="","",IFERROR(Calculations!$D$5,"")) -> 8466 | F4: =IF($A4="","",IFERROR(Calculations!$F$5,"")) -> -0.012787118 | G4: =IF($A4="","",MARKET_LABEL) -> نزولی قوی | H4: =IF($A4="","",IF($N4>=6,"صعودی قوی",IF($N4>=2,"صعودی",IF($N4<=-6,"نزولی قوی",IF($N4<=-2,"نزولی","خنثی"))))) -> صعودی قوی | I4: =IF($A4="","",IFERROR(Calculations!$U$5,"")) -> درون محدوده | J4: =IF($A4="","",IF($O4>=6,"ورود قوی پول حقیقی",IF($O4>=2,"ورود پول حقیقی",IF($O4<=-6,"خروج قوی پول حقیقی",IF($O4<=-2,"خروج پول حقیقی","متعادل"))))) -> خروج پول حقیقی | K4: =IF($A4="","",IFERROR(Calculations!$AG$5,"")) -> 0.41356994 | L4: =IF($A4="","",IFERROR(Calculations!$O$5,"")) -> آرایش صعودی کامل | M4: =IF($A4="","",IFERROR(Calculations!$AA$5,"")) -> 0.95599626 | N4: =IF($A4="","",IFERROR(Calculations!$AJ$5,0)) -> 8 | O4: =IF($A4="","",IFERROR(Calculations!$AK$5,0)) -> -4 | P4: =IF($A4="","",IFERROR(Calculations!$AL$5,0)) -> 5 | Q4: =IF($A4="","",IFERROR(Calculations!$AM$5,0)) -> -2 | R4: =IF($A4="","",IFERROR(Calculations!$AN$5,0)) -> -7 | S4: =IF($A4="","",IFERROR(Calculations!$AO$5,0)) -> 0 | T4: =IF($A4="","",IFERROR(Calculations!$AP$5,0)) -> 1.45 | U4: =IF($A4="","",IF($T4>=TH_SBUY,"خرید قوی",IF($T4>=TH_BUY,"خرید",IF($T4<=TH_SSELL,"فروش قوی",IF($T4<=TH_SELL,"فروش","نگهداری"))))) -> نگهداری | V4: =IF($A4="","",IFERROR(Calculations!$AQ$5,1)) -> 1 | W4: =IF($A4="","","روند: "&$H4&" | ساختار: "&$I4&" | پول هوشمند: "&$J4&" | قدرت خریدار: "&IFERROR(TEXT($K4,"0.00"),"—")&"x"&" | میانگین‌ها: "&IFERROR(TEXT(Calculations!$N$5,"0"),"—")&"/4 ("&$L4&")"&" | حجم: "&IFERROR(TEXT($M4,"0.00"),"—")&"x"&" | بازار: "&$G4) -> روند: صعودی قوی | ساختار: درون محدوده | پول هوشمند: خروج پول حقیقی | قدرت خریدار: 0.41x | میانگین‌ها: 3/4 (آرایش صعودی کامل) | حجم: 0.96x | بازار: نزولی قوی | X4: =IF($A4="","",IFERROR(Calculations!$X$5,"")) -> 7979.2857 | Y4: =IF($A4="","",IFERROR(($E4-$X4)/$E4,"")) -> 0.057490466 | Z4: =IF($A4="","",IFERROR(Calculations!$AR$5,"")) -> معتبر
A5: =IF(Calculations!$A$6="","",Calculations!$A$6) -> فملي | B5: =IF($A5="","",IFERROR(INDEX(Watchlist!$B$1:$B$5000,MATCH($A5,Watchlist!$A$1:$A$5000,0)),"")) -> ملي صنايع مس ايران | C5: =IF($A5="","",IFERROR(INDEX(Watchlist!$F$1:$F$5000,MATCH($A5,Watchlist!$A$1:$A$5000,0)),"")) -> فلزات اساسي | D5: =IF($A5="","",IFERROR(INDEX(Watchlist!$E$1:$E$5000,MATCH($A5,Watchlist!$A$1:$A$5000,0)),"")) -> بورس | E5: =IF($A5="","",IFERROR(Calculations!$D$6,"")) -> 6713 | F5: =IF($A5="","",IFERROR(Calculations!$F$6,"")) -> -0.0065369187 | G5: =IF($A5="","",MARKET_LABEL) -> نزولی قوی | H5: =IF($A5="","",IF($N5>=6,"صعودی قوی",IF($N5>=2,"صعودی",IF($N5<=-6,"نزولی قوی",IF($N5<=-2,"نزولی","خنثی"))))) -> نزولی قوی | I5: =IF($A5="","",IFERROR(Calculations!$U$6,"")) -> درون محدوده | J5: =IF($A5="","",IF($O5>=6,"ورود قوی پول حقیقی",IF($O5>=2,"ورود پول حقیقی",IF($O5<=-6,"خروج قوی پول حقیقی",IF($O5<=-2,"خروج پول حقیقی","متعادل"))))) -> خروج پول حقیقی | K5: =IF($A5="","",IFERROR(Calculations!$AG$6,"")) -> 0.6050356 | L5: =IF($A5="","",IFERROR(Calculations!$O$6,"")) -> آرایش نزولی کامل | M5: =IF($A5="","",IFERROR(Calculations!$AA$6,"")) -> 0.98405018 | N5: =IF($A5="","",IFERROR(Calculations!$AJ$6,0)) -> -8 | O5: =IF($A5="","",IFERROR(Calculations!$AK$6,0)) -> -2.5 | P5: =IF($A5="","",IFERROR(Calculations!$AL$6,0)) -> -5 | Q5: =IF($A5="","",IFERROR(Calculations!$AM$6,0)) -> -2 | R5: =IF($A5="","",IFERROR(Calculations!$AN$6,0)) -> -7 | S5: =IF($A5="","",IFERROR(Calculations!$AO$6,0)) -> 0 | T5: =IF($A5="","",IFERROR(Calculations!$AP$6,0)) -> -5.2 | U5: =IF($A5="","",IF($T5>=TH_SBUY,"خرید قوی",IF($T5>=TH_BUY,"خرید",IF($T5<=TH_SSELL,"فروش قوی",IF($T5<=TH_SELL,"فروش","نگهداری"))))) -> فروش قوی | V5: =IF($A5="","",IFERROR(Calculations!$AQ$6,1)) -> 4 | W5: =IF($A5="","","روند: "&$H5&" | ساختار: "&$I5&" | پول هوشمند: "&$J5&" | قدرت خریدار: "&IFERROR(TEXT($K5,"0.00"),"—")&"x"&" | میانگین‌ها: "&IFERROR(TEXT(Calculations!$N$6,"0"),"—")&"/4 ("&$L5&")"&" | حجم: "&IFERROR(TEXT($M5,"0.00"),"—")&"x"&" | بازار: "&$G5) -> روند: نزولی قوی | ساختار: درون محدوده | پول هوشمند: خروج پول حقیقی | قدرت خریدار: 0.61x | میانگین‌ها: 1/4 (آرایش نزولی کامل) | حجم: 0.98x | بازار: نزولی قوی | X5: =IF($A5="","",IFERROR(Calculations!$X$6,"")) -> 6119.4286 | Y5: =IF($A5="","",IFERROR(($E5-$X5)/$E5,"")) -> 0.088421187 | Z5: =IF($A5="","",IFERROR(Calculations!$AR$6,"")) -> معتبر
A6: =IF(Calculations!$A$7="","",Calculations!$A$7) -> شپنا | B6: =IF($A6="","",IFERROR(INDEX(Watchlist!$B$1:$B$5000,MATCH($A6,Watchlist!$A$1:$A$5000,0)),"")) -> پالايش نفت اصفهان | C6: =IF($A6="","",IFERROR(INDEX(Watchlist!$F$1:$F$5000,MATCH($A6,Watchlist!$A$1:$A$5000,0)),"")) -> فرآورده‌هاي نفتي | D6: =IF($A6="","",IFERROR(INDEX(Watchlist!$E$1:$E$5000,MATCH($A6,Watchlist!$A$1:$A$5000,0)),"")) -> بورس | E6: =IF($A6="","",IFERROR(Calculations!$D$7,"")) -> 3784 | F6: =IF($A6="","",IFERROR(Calculations!$F$7,"")) -> -0.011667993 | G6: =IF($A6="","",MARKET_LABEL) -> نزولی قوی | H6: =IF($A6="","",IF($N6>=6,"صعودی قوی",IF($N6>=2,"صعودی",IF($N6<=-6,"نزولی قوی",IF($N6<=-2,"نزولی","خنثی"))))) -> نزولی قوی | I6: =IF($A6="","",IFERROR(Calculations!$U$7,"")) -> درون محدوده | J6: =IF($A6="","",IF($O6>=6,"ورود قوی پول حقیقی",IF($O6>=2,"ورود پول حقیقی",IF($O6<=-6,"خروج قوی پول حقیقی",IF($O6<=-2,"خروج پول حقیقی","متعادل"))))) -> خروج پول حقیقی | K6: =IF($A6="","",IFERROR(Calculations!$AG$7,"")) -> 0.70028009 | L6: =IF($A6="","",IFERROR(Calculations!$O$7,"")) -> تقاطع مرگ | M6: =IF($A6="","",IFERROR(Calculations!$AA$7,"")) -> 0.82825728 | N6: =IF($A6="","",IFERROR(Calculations!$AJ$7,0)) -> -6.5 | O6: =IF($A6="","",IFERROR(Calculations!$AK$7,0)) -> -5 | P6: =IF($A6="","",IFERROR(Calculations!$AL$7,0)) -> -10 | Q6: =IF($A6="","",IFERROR(Calculations!$AM$7,0)) -> -2 | R6: =IF($A6="","",IFERROR(Calculations!$AN$7,0)) -> -7 | S6: =IF($A6="","",IFERROR(Calculations!$AO$7,0)) -> 0 | T6: =IF($A6="","",IFERROR(Calculations!$AP$7,0)) -> -6.175 | U6: =IF($A6="","",IF($T6>=TH_SBUY,"خرید قوی",IF($T6>=TH_BUY,"خرید",IF($T6<=TH_SSELL,"فروش قوی",IF($T6<=TH_SELL,"فروش","نگهداری"))))) -> فروش قوی | V6: =IF($A6="","",IFERROR(Calculations!$AQ$7,1)) -> 4 | W6: =IF($A6="","","روند: "&$H6&" | ساختار: "&$I6&" | پول هوشمند: "&$J6&" | قدرت خریدار: "&IFERROR(TEXT($K6,"0.00"),"—")&"x"&" | میانگین‌ها: "&IFERROR(TEXT(Calculations!$N$7,"0"),"—")&"/4 ("&$L6&")"&" | حجم: "&IFERROR(TEXT($M6,"0.00"),"—")&"x"&" | بازار: "&$G6) -> روند: نزولی قوی | ساختار: درون محدوده | پول هوشمند: خروج پول حقیقی | قدرت خریدار: 0.70x | میانگین‌ها: 0/4 (تقاطع مرگ) | حجم: 0.83x | بازار: نزولی قوی | X6: =IF($A6="","",IFERROR(Calculations!$X$7,"")) -> 3537.1429 | Y6: =IF($A6="","",IFERROR(($E6-$X6)/$E6,"")) -> 0.065237088 | Z6: =IF($A6="","",IFERROR(Calculations!$AR$7,"")) -> معتبر
A7: =IF(Calculations!$A$8="","",Calculations!$A$8) -> خودرو | B7: =IF($A7="","",IFERROR(INDEX(Watchlist!$B$1:$B$5000,MATCH($A7,Watchlist!$A$1:$A$5000,0)),"")) -> ايران خودرو | C7: =IF($A7="","",IFERROR(INDEX(Watchlist!$F$1:$F$5000,MATCH($A7,Watchlist!$A$1:$A$5000,0)),"")) -> خودرو و ساخت قطعات | D7: =IF($A7="","",IFERROR(INDEX(Watchlist!$E$1:$E$5000,MATCH($A7,Watchlist!$A$1:$A$5000,0)),"")) -> بورس | E7: =IF($A7="","",IFERROR(Calculations!$D$8,"")) -> 3785 | F7: =IF($A7="","",IFERROR(Calculations!$F$8,"")) -> -0.035021416 | G7: =IF($A7="","",MARKET_LABEL) -> نزولی قوی | H7: =IF($A7="","",IF($N7>=6,"صعودی قوی",IF($N7>=2,"صعودی",IF($N7<=-6,"نزولی قوی",IF($N7<=-2,"نزولی","خنثی"))))) -> صعودی قوی | I7: =IF($A7="","",IFERROR(Calculations!$U$8,"")) -> درون محدوده | J7: =IF($A7="","",IF($O7>=6,"ورود قوی پول حقیقی",IF($O7>=2,"ورود پول حقیقی",IF($O7<=-6,"خروج قوی پول حقیقی",IF($O7<=-2,"خروج پول حقیقی","متعادل"))))) -> خروج قوی پول حقیقی | K7: =IF($A7="","",IFERROR(Calculations!$AG$8,"")) -> 0.68813814 | L7: =IF($A7="","",IFERROR(Calculations!$O$8,"")) -> آرایش صعودی کامل | M7: =IF($A7="","",IFERROR(Calculations!$AA$8,"")) -> 0.98071145 | N7: =IF($A7="","",IFERROR(Calculations!$AJ$8,0)) -> 8 | O7: =IF($A7="","",IFERROR(Calculations!$AK$8,0)) -> -8 | P7: =IF($A7="","",IFERROR(Calculations!$AL$8,0)) -> 10 | Q7: =IF($A7="","",IFERROR(Calculations!$AM$8,0)) -> -2 | R7: =IF($A7="","",IFERROR(Calculations!$AN$8,0)) -> -7 | S7: =IF($A7="","",IFERROR(Calculations!$AO$8,0)) -> 0 | T7: =IF($A7="","",IFERROR(Calculations!$AP$8,0)) -> 1 | U7: =IF($A7="","",IF($T7>=TH_SBUY,"خرید قوی",IF($T7>=TH_BUY,"خرید",IF($T7<=TH_SSELL,"فروش قوی",IF($T7<=TH_SELL,"فروش","نگهداری"))))) -> نگهداری | V7: =IF($A7="","",IFERROR(Calculations!$AQ$8,1)) -> 1 | W7: =IF($A7="","","روند: "&$H7&" | ساختار: "&$I7&" | پول هوشمند: "&$J7&" | قدرت خریدار: "&IFERROR(TEXT($K7,"0.00"),"—")&"x"&" | میانگین‌ها: "&IFERROR(TEXT(Calculations!$N$8,"0"),"—")&"/4 ("&$L7&")"&" | حجم: "&IFERROR(TEXT($M7,"0.00"),"—")&"x"&" | بازار: "&$G7) -> روند: صعودی قوی | ساختار: درون محدوده | پول هوشمند: خروج قوی پول حقیقی | قدرت خریدار: 0.69x | میانگین‌ها: 4/4 (آرایش صعودی کامل) | حجم: 0.98x | بازار: نزولی قوی | X7: =IF($A7="","",IFERROR(Calculations!$X$8,"")) -> 3402.1429 | Y7: =IF($A7="","",IFERROR(($E7-$X7)/$E7,"")) -> 0.10115116 | Z7: =IF($A7="","",IFERROR(Calculations!$AR$8,"")) -> معتبر
A8: =IF(Calculations!$A$9="","",Calculations!$A$9) -> وبملت | B8: =IF($A8="","",IFERROR(INDEX(Watchlist!$B$1:$B$5000,MATCH($A8,Watchlist!$A$1:$A$5000,0)),"")) -> بانك ملت | C8: =IF($A8="","",IFERROR(INDEX(Watchlist!$F$1:$F$5000,MATCH($A8,Watchlist!$A$1:$A$5000,0)),"")) -> بانكها و موسسات اعتباري | D8: =IF($A8="","",IFERROR(INDEX(Watchlist!$E$1:$E$5000,MATCH($A8,Watchlist!$A$1:$A$5000,0)),"")) -> بورس | E8: =IF($A8="","",IFERROR(Calculations!$D$9,"")) -> 4483 | F8: =IF($A8="","",IFERROR(Calculations!$F$9,"")) -> -0.03592552 | G8: =IF($A8="","",MARKET_LABEL) -> نزولی قوی | H8: =IF($A8="","",IF($N8>=6,"صعودی قوی",IF($N8>=2,"صعودی",IF($N8<=-6,"نزولی قوی",IF($N8<=-2,"نزولی","خنثی"))))) -> نزولی قوی | I8: =IF($A8="","",IFERROR(Calculations!$U$9,"")) -> درون محدوده | J8: =IF($A8="","",IF($O8>=6,"ورود قوی پول حقیقی",IF($O8>=2,"ورود پول حقیقی",IF($O8<=-6,"خروج قوی پول حقیقی",IF($O8<=-2,"خروج پول حقیقی","متعادل"))))) -> خروج قوی پول حقیقی | K8: =IF($A8="","",IFERROR(Calculations!$AG$9,"")) -> 0.42631044 | L8: =IF($A8="","",IFERROR(Calculations!$O$9,"")) -> آرایش نزولی کامل | M8: =IF($A8="","",IFERROR(Calculations!$AA$9,"")) -> 0.86800613 | N8: =IF($A8="","",IFERROR(Calculations!$AJ$9,0)) -> -8 | O8: =IF($A8="","",IFERROR(Calculations!$AK$9,0)) -> -10 | P8: =IF($A8="","",IFERROR(Calculations!$AL$9,0)) -> -5 | Q8: =IF($A8="","",IFERROR(Calculations!$AM$9,0)) -> -2 | R8: =IF($A8="","",IFERROR(Calculations!$AN$9,0)) -> -7 | S8: =IF($A8="","",IFERROR(Calculations!$AO$9,0)) -> 0 | T8: =IF($A8="","",IFERROR(Calculations!$AP$9,0)) -> -7.45 | U8: =IF($A8="","",IF($T8>=TH_SBUY,"خرید قوی",IF($T8>=TH_BUY,"خرید",IF($T8<=TH_SSELL,"فروش قوی",IF($T8<=TH_SELL,"فروش","نگهداری"))))) -> فروش قوی | V8: =IF($A8="","",IFERROR(Calculations!$AQ$9,1)) -> 4 | W8: =IF($A8="","","روند: "&$H8&" | ساختار: "&$I8&" | پول هوشمند: "&$J8&" | قدرت خریدار: "&IFERROR(TEXT($K8,"0.00"),"—")&"x"&" | میانگین‌ها: "&IFERROR(TEXT(Calculations!$N$9,"0"),"—")&"/4 ("&$L8&")"&" | حجم: "&IFERROR(TEXT($M8,"0.00"),"—")&"x"&" | بازار: "&$G8) -> روند: نزولی قوی | ساختار: درون محدوده | پول هوشمند: خروج قوی پول حقیقی | قدرت خریدار: 0.43x | میانگین‌ها: 1/4 (آرایش نزولی کامل) | حجم: 0.87x | بازار: نزولی قوی | X8: =IF($A8="","",IFERROR(Calculations!$X$9,"")) -> 4208.2857 | Y8: =IF($A8="","",IFERROR(($E8-$X8)/$E8,"")) -> 0.061279118 | Z8: =IF($A8="","",IFERROR(Calculations!$AR$9,"")) -> معتبر
A9: =IF(Calculations!$A$10="","",Calculations!$A$10) -> شستا | B9: =IF($A9="","",IFERROR(INDEX(Watchlist!$B$1:$B$5000,MATCH($A9,Watchlist!$A$1:$A$5000,0)),"")) -> سرمايه گذاري تامين اجتماعي | C9: =IF($A9="","",IFERROR(INDEX(Watchlist!$F$1:$F$5000,MATCH($A9,Watchlist!$A$1:$A$5000,0)),"")) -> چند رشته‌اي صنعتي | D9: =IF($A9="","",IFERROR(INDEX(Watchlist!$E$1:$E$5000,MATCH($A9,Watchlist!$A$1:$A$5000,0)),"")) -> بورس | E9: =IF($A9="","",IFERROR(Calculations!$D$10,"")) -> 2007 | F9: =IF($A9="","",IFERROR(Calculations!$F$10,"")) -> 0.0060392552 | G9: =IF($A9="","",MARKET_LABEL) -> نزولی قوی | H9: =IF($A9="","",IF($N9>=6,"صعودی قوی",IF($N9>=2,"صعودی",IF($N9<=-6,"نزولی قوی",IF($N9<=-2,"نزولی","خنثی"))))) -> صعودی قوی | I9: =IF($A9="","",IFERROR(Calculations!$U$10,"")) -> درون محدوده | J9: =IF($A9="","",IF($O9>=6,"ورود قوی پول حقیقی",IF($O9>=2,"ورود پول حقیقی",IF($O9<=-6,"خروج قوی پول حقیقی",IF($O9<=-2,"خروج پول حقیقی","متعادل"))))) -> ورود قوی پول حقیقی | K9: =IF($A9="","",IFERROR(Calculations!$AG$10,"")) -> 1.5489763 | L9: =IF($A9="","",IFERROR(Calculations!$O$10,"")) -> آرایش صعودی کامل | M9: =IF($A9="","",IFERROR(Calculations!$AA$10,"")) -> 0.73931876 | N9: =IF($A9="","",IFERROR(Calculations!$AJ$10,0)) -> 8 | O9: =IF($A9="","",IFERROR(Calculations!$AK$10,0)) -> 8.5 | P9: =IF($A9="","",IFERROR(Calculations!$AL$10,0)) -> 10 | Q9: =IF($A9="","",IFERROR(Calculations!$AM$10,0)) -> 2 | R9: =IF($A9="","",IFERROR(Calculations!$AN$10,0)) -> -7 | S9: =IF($A9="","",IFERROR(Calculations!$AO$10,0)) -> 0 | T9: =IF($A9="","",IFERROR(Calculations!$AP$10,0)) -> 6.35 | U9: =IF($A9="","",IF($T9>=TH_SBUY,"خرید قوی",IF($T9>=TH_BUY,"خرید",IF($T9<=TH_SSELL,"فروش قوی",IF($T9<=TH_SELL,"فروش","نگهداری"))))) -> خرید قوی | V9: =IF($A9="","",IFERROR(Calculations!$AQ$10,1)) -> 4 | W9: =IF($A9="","","روند: "&$H9&" | ساختار: "&$I9&" | پول هوشمند: "&$J9&" | قدرت خریدار: "&IFERROR(TEXT($K9,"0.00"),"—")&"x"&" | میانگین‌ها: "&IFERROR(TEXT(Calculations!$N$10,"0"),"—")&"/4 ("&$L9&")"&" | حجم: "&IFERROR(TEXT($M9,"0.00"),"—")&"x"&" | بازار: "&$G9) -> روند: صعودی قوی | ساختار: درون محدوده | پول هوشمند: ورود قوی پول حقیقی | قدرت خریدار: 1.55x | میانگین‌ها: 4/4 (آرایش صعودی کامل) | حجم: 0.74x | بازار: نزولی قوی | X9: =IF($A9="","",IFERROR(Calculations!$X$10,"")) -> 1850.1429 | Y9: =IF($A9="","",IFERROR(($E9-$X9)/$E9,"")) -> 0.078155029 | Z9: =IF($A9="","",IFERROR(Calculations!$AR$10,"")) -> معتبر
A10: =IF(Calculations!$A$11="","",Calculations!$A$11) -> اخابر | B10: =IF($A10="","",IFERROR(INDEX(Watchlist!$B$1:$B$5000,MATCH($A10,Watchlist!$A$1:$A$5000,0)),"")) -> مخابرات ايران | C10: =IF($A10="","",IFERROR(INDEX(Watchlist!$F$1:$F$5000,MATCH($A10,Watchlist!$A$1:$A$5000,0)),"")) -> مخابرات | D10: =IF($A10="","",IFERROR(INDEX(Watchlist!$E$1:$E$5000,MATCH($A10,Watchlist!$A$1:$A$5000,0)),"")) -> بورس | E10: =IF($A10="","",IFERROR(Calculations!$D$11,"")) -> 1194 | F10: =IF($A10="","",IFERROR(Calculations!$F$11,"")) -> 0.013179572 | G10: =IF($A10="","",MARKET_LABEL) -> نزولی قوی | H10: =IF($A10="","",IF($N10>=6,"صعودی قوی",IF($N10>=2,"صعودی",IF($N10<=-6,"نزولی قوی",IF($N10<=-2,"نزولی","خنثی"))))) -> صعودی | I10: =IF($A10="","",IFERROR(Calculations!$U$11,"")) -> درون محدوده | J10: =IF($A10="","",IF($O10>=6,"ورود قوی پول حقیقی",IF($O10>=2,"ورود پول حقیقی",IF($O10<=-6,"خروج قوی پول حقیقی",IF($O10<=-2,"خروج پول حقیقی","متعادل"))))) -> ورود قوی پول حقیقی | K10: =IF($A10="","",IFERROR(Calculations!$AG$11,"")) -> 1.7285201 | L10: =IF($A10="","",IFERROR(Calculations!$O$11,"")) -> تقاطع مرگ | M10: =IF($A10="","",IFERROR(Calculations!$AA$11,"")) -> 0.87115483 | N10: =IF($A10="","",IFERROR(Calculations!$AJ$11,0)) -> 2 | O10: =IF($A10="","",IFERROR(Calculations!$AK$11,0)) -> 10 | P10: =IF($A10="","",IFERROR(Calculations!$AL$11,0)) -> 5 | Q10: =IF($A10="","",IFERROR(Calculations!$AM$11,0)) -> 2 | R10: =IF($A10="","",IFERROR(Calculations!$AN$11,0)) -> -7 | S10: =IF($A10="","",IFERROR(Calculations!$AO$11,0)) -> 0 | T10: =IF($A10="","",IFERROR(Calculations!$AP$11,0)) -> 3.95 | U10: =IF($A10="","",IF($T10>=TH_SBUY,"خرید قوی",IF($T10>=TH_BUY,"خرید",IF($T10<=TH_SSELL,"فروش قوی",IF($T10<=TH_SELL,"فروش","نگهداری"))))) -> خرید | V10: =IF($A10="","",IFERROR(Calculations!$AQ$11,1)) -> 3 | W10: =IF($A10="","","روند: "&$H10&" | ساختار: "&$I10&" | پول هوشمند: "&$J10&" | قدرت خریدار: "&IFERROR(TEXT($K10,"0.00"),"—")&"x"&" | میانگین‌ها: "&IFERROR(TEXT(Calculations!$N$11,"0"),"—")&"/4 ("&$L10&")"&" | حجم: "&IFERROR(TEXT($M10,"0.00"),"—")&"x"&" | بازار: "&$G10) -> روند: صعودی | ساختار: درون محدوده | پول هوشمند: ورود قوی پول حقیقی | قدرت خریدار: 1.73x | میانگین‌ها: 3/4 (تقاطع مرگ) | حجم: 0.87x | بازار: نزولی قوی | X10: =IF($A10="","",IFERROR(Calculations!$X$11,"")) -> 1117.8571 | Y10: =IF($A10="","",IFERROR(($E10-$X10)/$E10,"")) -> 0.063771237 | Z10: =IF($A10="","",IFERROR(Calculations!$AR$11,"")) -> معتبر
A11: =IF(Calculations!$A$12="","",Calculations!$A$12) -> كگل | B11: =IF($A11="","",IFERROR(INDEX(Watchlist!$B$1:$B$5000,MATCH($A11,Watchlist!$A$1:$A$5000,0)),"")) -> معدني و صنعتي گل گهر | C11: =IF($A11="","",IFERROR(INDEX(Watchlist!$F$1:$F$5000,MATCH($A11,Watchlist!$A$1:$A$5000,0)),"")) -> استخراج كانه‌هاي فلزي | D11: =IF($A11="","",IFERROR(INDEX(Watchlist!$E$1:$E$5000,MATCH($A11,Watchlist!$A$1:$A$5000,0)),"")) -> بورس | E11: =IF($A11="","",IFERROR(Calculations!$D$12,"")) -> 11194 | F11: =IF($A11="","",IFERROR(Calculations!$F$12,"")) -> -0.018377131 | G11: =IF($A11="","",MARKET_LABEL) -> نزولی قوی | H11: =IF($A11="","",IF($N11>=6,"صعودی قوی",IF($N11>=2,"صعودی",IF($N11<=-6,"نزولی قوی",IF($N11<=-2,"نزولی","خنثی"))))) -> نزولی قوی | I11: =IF($A11="","",IFERROR(Calculations!$U$12,"")) -> درون محدوده | J11: =IF($A11="","",IF($O11>=6,"ورود قوی پول حقیقی",IF($O11>=2,"ورود پول حقیقی",IF($O11<=-6,"خروج قوی پول حقیقی",IF($O11<=-2,"خروج پول حقیقی","متعادل"))))) -> ورود پول حقیقی | K11: =IF($A11="","",IFERROR(Calculations!$AG$12,"")) -> 0.65343634 | L11: =IF($A11="","",IFERROR(Calculations!$O$12,"")) -> تقاطع مرگ | M11: =IF($A11="","",IFERROR(Calculations!$AA$12,"")) -> 0.99200282 | N11: =IF($A11="","",IFERROR(Calculations!$AJ$12,0)) -> -8 | O11: =IF($A11="","",IFERROR(Calculations!$AK$12,0)) -> 4 | P11: =IF($A11="","",IFERROR(Calculations!$AL$12,0)) -> -10 | Q11: =IF($A11="","",IFERROR(Calculations!$AM$12,0)) -> -2 | R11: =IF($A11="","",IFERROR(Calculations!$AN$12,0)) -> -7 | S11: =IF($A11="","",IFERROR(Calculations!$AO$12,0)) -> 0 | T11: =IF($A11="","",IFERROR(Calculations!$AP$12,0)) -> -4 | U11: =IF($A11="","",IF($T11>=TH_SBUY,"خرید قوی",IF($T11>=TH_BUY,"خرید",IF($T11<=TH_SSELL,"فروش قوی",IF($T11<=TH_SELL,"فروش","نگهداری"))))) -> فروش | V11: =IF($A11="","",IFERROR(Calculations!$AQ$12,1)) -> 3 | W11: =IF($A11="","","روند: "&$H11&" | ساختار: "&$I11&" | پول هوشمند: "&$J11&" | قدرت خریدار: "&IFERROR(TEXT($K11,"0.00"),"—")&"x"&" | میانگین‌ها: "&IFERROR(TEXT(Calculations!$N$12,"0"),"—")&"/4 ("&$L11&")"&" | حجم: "&IFERROR(TEXT($M11,"0.00"),"—")&"x"&" | بازار: "&$G11) -> روند: نزولی قوی | ساختار: درون محدوده | پول هوشمند: ورود پول حقیقی | قدرت خریدار: 0.65x | میانگین‌ها: 0/4 (تقاطع مرگ) | حجم: 0.99x | بازار: نزولی قوی | X11: =IF($A11="","",IFERROR(Calculations!$X$12,"")) -> 10534.286 | Y11: =IF($A11="","",IFERROR(($E11-$X11)/$E11,"")) -> 0.058934633 | Z11: =IF($A11="","",IFERROR(Calculations!$AR$12,"")) -> معتبر
A12: =IF(Calculations!$A$13="","",Calculations!$A$13) | B12: =IF($A12="","",IFERROR(INDEX(Watchlist!$B$1:$B$5000,MATCH($A12,Watchlist!$A$1:$A$5000,0)),"")) | C12: =IF($A12="","",IFERROR(INDEX(Watchlist!$F$1:$F$5000,MATCH($A12,Watchlist!$A$1:$A$5000,0)),"")) | D12: =IF($A12="","",IFERROR(INDEX(Watchlist!$E$1:$E$5000,MATCH($A12,Watchlist!$A$1:$A$5000,0)),"")) | E12: =IF($A12="","",IFERROR(Calculations!$D$13,"")) | F12: =IF($A12="","",IFERROR(Calculations!$F$13,"")) | G12: =IF($A12="","",MARKET_LABEL) | H12: =IF($A12="","",IF($N12>=6,"صعودی قوی",IF($N12>=2,"صعودی",IF($N12<=-6,"نزولی قوی",IF($N12<=-2,"نزولی","خنثی"))))) | I12: =IF($A12="","",IFERROR(Calculations!$U$13,"")) | J12: =IF($A12="","",IF($O12>=6,"ورود قوی پول حقیقی",IF($O12>=2,"ورود پول حقیقی",IF($O12<=-6,"خروج قوی پول حقیقی",IF($O12<=-2,"خروج پول حقیقی","متعادل"))))) | K12: =IF($A12="","",IFERROR(Calculations!$AG$13,"")) | L12: =IF($A12="","",IFERROR(Calculations!$O$13,"")) | M12: =IF($A12="","",IFERROR(Calculations!$AA$13,"")) | N12: =IF($A12="","",IFERROR(Calculations!$AJ$13,0)) | O12: =IF($A12="","",IFERROR(Calculations!$AK$13,0)) | P12: =IF($A12="","",IFERROR(Calculations!$AL$13,0)) | Q12: =IF($A12="","",IFERROR(Calculations!$AM$13,0)) | R12: =IF($A12="","",IFERROR(Calculations!$AN$13,0)) | S12: =IF($A12="","",IFERROR(Calculations!$AO$13,0)) | T12: =IF($A12="","",IFERROR(Calculations!$AP$13,0)) | U12: =IF($A12="","",IF($T12>=TH_SBUY,"خرید قوی",IF($T12>=TH_BUY,"خرید",IF($T12<=TH_SSELL,"فروش قوی",IF($T12<=TH_SELL,"فروش","نگهداری"))))) | V12: =IF($A12="","",IFERROR(Calculations!$AQ$13,1)) | W12: =IF($A12="","","روند: "&$H12&" | ساختار: "&$I12&" | پول هوشمند: "&$J12&" | قدرت خریدار: "&IFERROR(TEXT($K12,"0.00"),"—")&"x"&" | میانگین‌ها: "&IFERROR(TEXT(Calculations!$N$13,"0"),"—")&"/4 ("&$L12&")"&" | حجم: "&IFERROR(TEXT($M12,"0.00"),"—")&"x"&" | بازار: "&$G12) | X12: =IF($A12="","",IFERROR(Calculations!$X$13,"")) | Y12: =IF($A12="","",IFERROR(($E12-$X12)/$E12,"")) | Z12: =IF($A12="","",IFERROR(Calculations!$AR$13,""))
A13: =IF(Calculations!$A$14="","",Calculations!$A$14) | B13: =IF($A13="","",IFERROR(INDEX(Watchlist!$B$1:$B$5000,MATCH($A13,Watchlist!$A$1:$A$5000,0)),"")) | C13: =IF($A13="","",IFERROR(INDEX(Watchlist!$F$1:$F$5000,MATCH($A13,Watchlist!$A$1:$A$5000,0)),"")) | D13: =IF($A13="","",IFERROR(INDEX(Watchlist!$E$1:$E$5000,MATCH($A13,Watchlist!$A$1:$A$5000,0)),"")) | E13: =IF($A13="","",IFERROR(Calculations!$D$14,"")) | F13: =IF($A13="","",IFERROR(Calculations!$F$14,"")) | G13: =IF($A13="","",MARKET_LABEL) | H13: =IF($A13="","",IF($N13>=6,"صعودی قوی",IF($N13>=2,"صعودی",IF($N13<=-6,"نزولی قوی",IF($N13<=-2,"نزولی","خنثی"))))) | I13: =IF($A13="","",IFERROR(Calculations!$U$14,"")) | J13: =IF($A13="","",IF($O13>=6,"ورود قوی پول حقیقی",IF($O13>=2,"ورود پول حقیقی",IF($O13<=-6,"خروج قوی پول حقیقی",IF($O13<=-2,"خروج پول حقیقی","متعادل"))))) | K13: =IF($A13="","",IFERROR(Calculations!$AG$14,"")) | L13: =IF($A13="","",IFERROR(Calculations!$O$14,"")) | M13: =IF($A13="","",IFERROR(Calculations!$AA$14,"")) | N13: =IF($A13="","",IFERROR(Calculations!$AJ$14,0)) | O13: =IF($A13="","",IFERROR(Calculations!$AK$14,0)) | P13: =IF($A13="","",IFERROR(Calculations!$AL$14,0)) | Q13: =IF($A13="","",IFERROR(Calculations!$AM$14,0)) | R13: =IF($A13="","",IFERROR(Calculations!$AN$14,0)) | S13: =IF($A13="","",IFERROR(Calculations!$AO$14,0)) | T13: =IF($A13="","",IFERROR(Calculations!$AP$14,0)) | U13: =IF($A13="","",IF($T13>=TH_SBUY,"خرید قوی",IF($T13>=TH_BUY,"خرید",IF($T13<=TH_SSELL,"فروش قوی",IF($T13<=TH_SELL,"فروش","نگهداری"))))) | V13: =IF($A13="","",IFERROR(Calculations!$AQ$14,1)) | W13: =IF($A13="","","روند: "&$H13&" | ساختار: "&$I13&" | پول هوشمند: "&$J13&" | قدرت خریدار: "&IFERROR(TEXT($K13,"0.00"),"—")&"x"&" | میانگین‌ها: "&IFERROR(TEXT(Calculations!$N$14,"0"),"—")&"/4 ("&$L13&")"&" | حجم: "&IFERROR(TEXT($M13,"0.00"),"—")&"x"&" | بازار: "&$G13) | X13: =IF($A13="","",IFERROR(Calculations!$X$14,"")) | Y13: =IF($A13="","",IFERROR(($E13-$X13)/$E13,"")) | Z13: =IF($A13="","",IFERROR(Calculations!$AR$14,""))
A14: =IF(Calculations!$A$15="","",Calculations!$A$15) | B14: =IF($A14="","",IFERROR(INDEX(Watchlist!$B$1:$B$5000,MATCH($A14,Watchlist!$A$1:$A$5000,0)),"")) | C14: =IF($A14="","",IFERROR(INDEX(Watchlist!$F$1:$F$5000,MATCH($A14,Watchlist!$A$1:$A$5000,0)),"")) | D14: =IF($A14="","",IFERROR(INDEX(Watchlist!$E$1:$E$5000,MATCH($A14,Watchlist!$A$1:$A$5000,0)),"")) | E14: =IF($A14="","",IFERROR(Calculations!$D$15,"")) | F14: =IF($A14="","",IFERROR(Calculations!$F$15,"")) | G14: =IF($A14="","",MARKET_LABEL) | H14: =IF($A14="","",IF($N14>=6,"صعودی قوی",IF($N14>=2,"صعودی",IF($N14<=-6,"نزولی قوی",IF($N14<=-2,"نزولی","خنثی"))))) | I14: =IF($A14="","",IFERROR(Calculations!$U$15,"")) | J14: =IF($A14="","",IF($O14>=6,"ورود قوی پول حقیقی",IF($O14>=2,"ورود پول حقیقی",IF($O14<=-6,"خروج قوی پول حقیقی",IF($O14<=-2,"خروج پول حقیقی","متعادل"))))) | K14: =IF($A14="","",IFERROR(Calculations!$AG$15,"")) | L14: =IF($A14="","",IFERROR(Calculations!$O$15,"")) | M14: =IF($A14="","",IFERROR(Calculations!$AA$15,"")) | N14: =IF($A14="","",IFERROR(Calculations!$AJ$15,0)) | O14: =IF($A14="","",IFERROR(Calculations!$AK$15,0)) | P14: =IF($A14="","",IFERROR(Calculations!$AL$15,0)) | Q14: =IF($A14="","",IFERROR(Calculations!$AM$15,0)) | R14: =IF($A14="","",IFERROR(Calculations!$AN$15,0)) | S14: =IF($A14="","",IFERROR(Calculations!$AO$15,0)) | T14: =IF($A14="","",IFERROR(Calculations!$AP$15,0)) | U14: =IF($A14="","",IF($T14>=TH_SBUY,"خرید قوی",IF($T14>=TH_BUY,"خرید",IF($T14<=TH_SSELL,"فروش قوی",IF($T14<=TH_SELL,"فروش","نگهداری"))))) | V14: =IF($A14="","",IFERROR(Calculations!$AQ$15,1)) | W14: =IF($A14="","","روند: "&$H14&" | ساختار: "&$I14&" | پول هوشمند: "&$J14&" | قدرت خریدار: "&IFERROR(TEXT($K14,"0.00"),"—")&"x"&" | میانگین‌ها: "&IFERROR(TEXT(Calculations!$N$15,"0"),"—")&"/4 ("&$L14&")"&" | حجم: "&IFERROR(TEXT($M14,"0.00"),"—")&"x"&" | بازار: "&$G14) | X14: =IF($A14="","",IFERROR(Calculations!$X$15,"")) | Y14: =IF($A14="","",IFERROR(($E14-$X14)/$E14,"")) | Z14: =IF($A14="","",IFERROR(Calculations!$AR$15,""))
A15: =IF(Calculations!$A$16="","",Calculations!$A$16) | B15: =IF($A15="","",IFERROR(INDEX(Watchlist!$B$1:$B$5000,MATCH($A15,Watchlist!$A$1:$A$5000,0)),"")) | C15: =IF($A15="","",IFERROR(INDEX(Watchlist!$F$1:$F$5000,MATCH($A15,Watchlist!$A$1:$A$5000,0)),"")) | D15: =IF($A15="","",IFERROR(INDEX(Watchlist!$E$1:$E$5000,MATCH($A15,Watchlist!$A$1:$A$5000,0)),"")) | E15: =IF($A15="","",IFERROR(Calculations!$D$16,"")) | F15: =IF($A15="","",IFERROR(Calculations!$F$16,"")) | G15: =IF($A15="","",MARKET_LABEL) | H15: =IF($A15="","",IF($N15>=6,"صعودی قوی",IF($N15>=2,"صعودی",IF($N15<=-6,"نزولی قوی",IF($N15<=-2,"نزولی","خنثی"))))) | I15: =IF($A15="","",IFERROR(Calculations!$U$16,"")) | J15: =IF($A15="","",IF($O15>=6,"ورود قوی پول حقیقی",IF($O15>=2,"ورود پول حقیقی",IF($O15<=-6,"خروج قوی پول حقیقی",IF($O15<=-2,"خروج پول حقیقی","متعادل"))))) | K15: =IF($A15="","",IFERROR(Calculations!$AG$16,"")) | L15: =IF($A15="","",IFERROR(Calculations!$O$16,"")) | M15: =IF($A15="","",IFERROR(Calculations!$AA$16,"")) | N15: =IF($A15="","",IFERROR(Calculations!$AJ$16,0)) | O15: =IF($A15="","",IFERROR(Calculations!$AK$16,0)) | P15: =IF($A15="","",IFERROR(Calculations!$AL$16,0)) | Q15: =IF($A15="","",IFERROR(Calculations!$AM$16,0)) | R15: =IF($A15="","",IFERROR(Calculations!$AN$16,0)) | S15: =IF($A15="","",IFERROR(Calculations!$AO$16,0)) | T15: =IF($A15="","",IFERROR(Calculations!$AP$16,0)) | U15: =IF($A15="","",IF($T15>=TH_SBUY,"خرید قوی",IF($T15>=TH_BUY,"خرید",IF($T15<=TH_SSELL,"فروش قوی",IF($T15<=TH_SELL,"فروش","نگهداری"))))) | V15: =IF($A15="","",IFERROR(Calculations!$AQ$16,1)) | W15: =IF($A15="","","روند: "&$H15&" | ساختار: "&$I15&" | پول هوشمند: "&$J15&" | قدرت خریدار: "&IFERROR(TEXT($K15,"0.00"),"—")&"x"&" | میانگین‌ها: "&IFERROR(TEXT(Calculations!$N$16,"0"),"—")&"/4 ("&$L15&")"&" | حجم: "&IFERROR(TEXT($M15,"0.00"),"—")&"x"&" | بازار: "&$G15) | X15: =IF($A15="","",IFERROR(Calculations!$X$16,"")) | Y15: =IF($A15="","",IFERROR(($E15-$X15)/$E15,"")) | Z15: =IF($A15="","",IFERROR(Calculations!$AR$16,""))
A16: =IF(Calculations!$A$17="","",Calculations!$A$17) | B16: =IF($A16="","",IFERROR(INDEX(Watchlist!$B$1:$B$5000,MATCH($A16,Watchlist!$A$1:$A$5000,0)),"")) | C16: =IF($A16="","",IFERROR(INDEX(Watchlist!$F$1:$F$5000,MATCH($A16,Watchlist!$A$1:$A$5000,0)),"")) | D16: =IF($A16="","",IFERROR(INDEX(Watchlist!$E$1:$E$5000,MATCH($A16,Watchlist!$A$1:$A$5000,0)),"")) | E16: =IF($A16="","",IFERROR(Calculations!$D$17,"")) | F16: =IF($A16="","",IFERROR(Calculations!$F$17,"")) | G16: =IF($A16="","",MARKET_LABEL) | H16: =IF($A16="","",IF($N16>=6,"صعودی قوی",IF($N16>=2,"صعودی",IF($N16<=-6,"نزولی قوی",IF($N16<=-2,"نزولی","خنثی"))))) | I16: =IF($A16="","",IFERROR(Calculations!$U$17,"")) | J16: =IF($A16="","",IF($O16>=6,"ورود قوی پول حقیقی",IF($O16>=2,"ورود پول حقیقی",IF($O16<=-6,"خروج قوی پول حقیقی",IF($O16<=-2,"خروج پول حقیقی","متعادل"))))) | K16: =IF($A16="","",IFERROR(Calculations!$AG$17,"")) | L16: =IF($A16="","",IFERROR(Calculations!$O$17,"")) | M16: =IF($A16="","",IFERROR(Calculations!$AA$17,"")) | N16: =IF($A16="","",IFERROR(Calculations!$AJ$17,0)) | O16: =IF($A16="","",IFERROR(Calculations!$AK$17,0)) | P16: =IF($A16="","",IFERROR(Calculations!$AL$17,0)) | Q16: =IF($A16="","",IFERROR(Calculations!$AM$17,0)) | R16: =IF($A16="","",IFERROR(Calculations!$AN$17,0)) | S16: =IF($A16="","",IFERROR(Calculations!$AO$17,0)) | T16: =IF($A16="","",IFERROR(Calculations!$AP$17,0)) | U16: =IF($A16="","",IF($T16>=TH_SBUY,"خرید قوی",IF($T16>=TH_BUY,"خرید",IF($T16<=TH_SSELL,"فروش قوی",IF($T16<=TH_SELL,"فروش","نگهداری"))))) | V16: =IF($A16="","",IFERROR(Calculations!$AQ$17,1)) | W16: =IF($A16="","","روند: "&$H16&" | ساختار: "&$I16&" | پول هوشمند: "&$J16&" | قدرت خریدار: "&IFERROR(TEXT($K16,"0.00"),"—")&"x"&" | میانگین‌ها: "&IFERROR(TEXT(Calculations!$N$17,"0"),"—")&"/4 ("&$L16&")"&" | حجم: "&IFERROR(TEXT($M16,"0.00"),"—")&"x"&" | بازار: "&$G16) | X16: =IF($A16="","",IFERROR(Calculations!$X$17,"")) | Y16: =IF($A16="","",IFERROR(($E16-$X16)/$E16,"")) | Z16: =IF($A16="","",IFERROR(Calculations!$AR$17,""))
A17: =IF(Calculations!$A$18="","",Calculations!$A$18) | B17: =IF($A17="","",IFERROR(INDEX(Watchlist!$B$1:$B$5000,MATCH($A17,Watchlist!$A$1:$A$5000,0)),"")) | C17: =IF($A17="","",IFERROR(INDEX(Watchlist!$F$1:$F$5000,MATCH($A17,Watchlist!$A$1:$A$5000,0)),"")) | D17: =IF($A17="","",IFERROR(INDEX(Watchlist!$E$1:$E$5000,MATCH($A17,Watchlist!$A$1:$A$5000,0)),"")) | E17: =IF($A17="","",IFERROR(Calculations!$D$18,"")) | F17: =IF($A17="","",IFERROR(Calculations!$F$18,"")) | G17: =IF($A17="","",MARKET_LABEL) | H17: =IF($A17="","",IF($N17>=6,"صعودی قوی",IF($N17>=2,"صعودی",IF($N17<=-6,"نزولی قوی",IF($N17<=-2,"نزولی","خنثی"))))) | I17: =IF($A17="","",IFERROR(Calculations!$U$18,"")) | J17: =IF($A17="","",IF($O17>=6,"ورود قوی پول حقیقی",IF($O17>=2,"ورود پول حقیقی",IF($O17<=-6,"خروج قوی پول حقیقی",IF($O17<=-2,"خروج پول حقیقی","متعادل"))))) | K17: =IF($A17="","",IFERROR(Calculations!$AG$18,"")) | L17: =IF($A17="","",IFERROR(Calculations!$O$18,"")) | M17: =IF($A17="","",IFERROR(Calculations!$AA$18,"")) | N17: =IF($A17="","",IFERROR(Calculations!$AJ$18,0)) | O17: =IF($A17="","",IFERROR(Calculations!$AK$18,0)) | P17: =IF($A17="","",IFERROR(Calculations!$AL$18,0)) | Q17: =IF($A17="","",IFERROR(Calculations!$AM$18,0)) | R17: =IF($A17="","",IFERROR(Calculations!$AN$18,0)) | S17: =IF($A17="","",IFERROR(Calculations!$AO$18,0)) | T17: =IF($A17="","",IFERROR(Calculations!$AP$18,0)) | U17: =IF($A17="","",IF($T17>=TH_SBUY,"خرید قوی",IF($T17>=TH_BUY,"خرید",IF($T17<=TH_SSELL,"فروش قوی",IF($T17<=TH_SELL,"فروش","نگهداری"))))) | V17: =IF($A17="","",IFERROR(Calculations!$AQ$18,1)) | W17: =IF($A17="","","روند: "&$H17&" | ساختار: "&$I17&" | پول هوشمند: "&$J17&" | قدرت خریدار: "&IFERROR(TEXT($K17,"0.00"),"—")&"x"&" | میانگین‌ها: "&IFERROR(TEXT(Calculations!$N$18,"0"),"—")&"/4 ("&$L17&")"&" | حجم: "&IFERROR(TEXT($M17,"0.00"),"—")&"x"&" | بازار: "&$G17) | X17: =IF($A17="","",IFERROR(Calculations!$X$18,"")) | Y17: =IF($A17="","",IFERROR(($E17-$X17)/$E17,"")) | Z17: =IF($A17="","",IFERROR(Calculations!$AR$18,""))
A18: =IF(Calculations!$A$19="","",Calculations!$A$19) | B18: =IF($A18="","",IFERROR(INDEX(Watchlist!$B$1:$B$5000,MATCH($A18,Watchlist!$A$1:$A$5000,0)),"")) | C18: =IF($A18="","",IFERROR(INDEX(Watchlist!$F$1:$F$5000,MATCH($A18,Watchlist!$A$1:$A$5000,0)),"")) | D18: =IF($A18="","",IFERROR(INDEX(Watchlist!$E$1:$E$5000,MATCH($A18,Watchlist!$A$1:$A$5000,0)),"")) | E18: =IF($A18="","",IFERROR(Calculations!$D$19,"")) | F18: =IF($A18="","",IFERROR(Calculations!$F$19,"")) | G18: =IF($A18="","",MARKET_LABEL) | H18: =IF($A18="","",IF($N18>=6,"صعودی قوی",IF($N18>=2,"صعودی",IF($N18<=-6,"نزولی قوی",IF($N18<=-2,"نزولی","خنثی"))))) | I18: =IF($A18="","",IFERROR(Calculations!$U$19,"")) | J18: =IF($A18="","",IF($O18>=6,"ورود قوی پول حقیقی",IF($O18>=2,"ورود پول حقیقی",IF($O18<=-6,"خروج قوی پول حقیقی",IF($O18<=-2,"خروج پول حقیقی","متعادل"))))) | K18: =IF($A18="","",IFERROR(Calculations!$AG$19,"")) | L18: =IF($A18="","",IFERROR(Calculations!$O$19,"")) | M18: =IF($A18="","",IFERROR(Calculations!$AA$19,"")) | N18: =IF($A18="","",IFERROR(Calculations!$AJ$19,0)) | O18: =IF($A18="","",IFERROR(Calculations!$AK$19,0)) | P18: =IF($A18="","",IFERROR(Calculations!$AL$19,0)) | Q18: =IF($A18="","",IFERROR(Calculations!$AM$19,0)) | R18: =IF($A18="","",IFERROR(Calculations!$AN$19,0)) | S18: =IF($A18="","",IFERROR(Calculations!$AO$19,0)) | T18: =IF($A18="","",IFERROR(Calculations!$AP$19,0)) | U18: =IF($A18="","",IF($T18>=TH_SBUY,"خرید قوی",IF($T18>=TH_BUY,"خرید",IF($T18<=TH_SSELL,"فروش قوی",IF($T18<=TH_SELL,"فروش","نگهداری"))))) | V18: =IF($A18="","",IFERROR(Calculations!$AQ$19,1)) | W18: =IF($A18="","","روند: "&$H18&" | ساختار: "&$I18&" | پول هوشمند: "&$J18&" | قدرت خریدار: "&IFERROR(TEXT($K18,"0.00"),"—")&"x"&" | میانگین‌ها: "&IFERROR(TEXT(Calculations!$N$19,"0"),"—")&"/4 ("&$L18&")"&" | حجم: "&IFERROR(TEXT($M18,"0.00"),"—")&"x"&" | بازار: "&$G18) | X18: =IF($A18="","",IFERROR(Calculations!$X$19,"")) | Y18: =IF($A18="","",IFERROR(($E18-$X18)/$E18,"")) | Z18: =IF($A18="","",IFERROR(Calculations!$AR$19,""))
A19: =IF(Calculations!$A$20="","",Calculations!$A$20) | B19: =IF($A19="","",IFERROR(INDEX(Watchlist!$B$1:$B$5000,MATCH($A19,Watchlist!$A$1:$A$5000,0)),"")) | C19: =IF($A19="","",IFERROR(INDEX(Watchlist!$F$1:$F$5000,MATCH($A19,Watchlist!$A$1:$A$5000,0)),"")) | D19: =IF($A19="","",IFERROR(INDEX(Watchlist!$E$1:$E$5000,MATCH($A19,Watchlist!$A$1:$A$5000,0)),"")) | E19: =IF($A19="","",IFERROR(Calculations!$D$20,"")) | F19: =IF($A19="","",IFERROR(Calculations!$F$20,"")) | G19: =IF($A19="","",MARKET_LABEL) | H19: =IF($A19="","",IF($N19>=6,"صعودی قوی",IF($N19>=2,"صعودی",IF($N19<=-6,"نزولی قوی",IF($N19<=-2,"نزولی","خنثی"))))) | I19: =IF($A19="","",IFERROR(Calculations!$U$20,"")) | J19: =IF($A19="","",IF($O19>=6,"ورود قوی پول حقیقی",IF($O19>=2,"ورود پول حقیقی",IF($O19<=-6,"خروج قوی پول حقیقی",IF($O19<=-2,"خروج پول حقیقی","متعادل"))))) | K19: =IF($A19="","",IFERROR(Calculations!$AG$20,"")) | L19: =IF($A19="","",IFERROR(Calculations!$O$20,"")) | M19: =IF($A19="","",IFERROR(Calculations!$AA$20,"")) | N19: =IF($A19="","",IFERROR(Calculations!$AJ$20,0)) | O19: =IF($A19="","",IFERROR(Calculations!$AK$20,0)) | P19: =IF($A19="","",IFERROR(Calculations!$AL$20,0)) | Q19: =IF($A19="","",IFERROR(Calculations!$AM$20,0)) | R19: =IF($A19="","",IFERROR(Calculations!$AN$20,0)) | S19: =IF($A19="","",IFERROR(Calculations!$AO$20,0)) | T19: =IF($A19="","",IFERROR(Calculations!$AP$20,0)) | U19: =IF($A19="","",IF($T19>=TH_SBUY,"خرید قوی",IF($T19>=TH_BUY,"خرید",IF($T19<=TH_SSELL,"فروش قوی",IF($T19<=TH_SELL,"فروش","نگهداری"))))) | V19: =IF($A19="","",IFERROR(Calculations!$AQ$20,1)) | W19: =IF($A19="","","روند: "&$H19&" | ساختار: "&$I19&" | پول هوشمند: "&$J19&" | قدرت خریدار: "&IFERROR(TEXT($K19,"0.00"),"—")&"x"&" | میانگین‌ها: "&IFERROR(TEXT(Calculations!$N$20,"0"),"—")&"/4 ("&$L19&")"&" | حجم: "&IFERROR(TEXT($M19,"0.00"),"—")&"x"&" | بازار: "&$G19) | X19: =IF($A19="","",IFERROR(Calculations!$X$20,"")) | Y19: =IF($A19="","",IFERROR(($E19-$X19)/$E19,"")) | Z19: =IF($A19="","",IFERROR(Calculations!$AR$20,""))
A20: =IF(Calculations!$A$21="","",Calculations!$A$21) | B20: =IF($A20="","",IFERROR(INDEX(Watchlist!$B$1:$B$5000,MATCH($A20,Watchlist!$A$1:$A$5000,0)),"")) | C20: =IF($A20="","",IFERROR(INDEX(Watchlist!$F$1:$F$5000,MATCH($A20,Watchlist!$A$1:$A$5000,0)),"")) | D20: =IF($A20="","",IFERROR(INDEX(Watchlist!$E$1:$E$5000,MATCH($A20,Watchlist!$A$1:$A$5000,0)),"")) | E20: =IF($A20="","",IFERROR(Calculations!$D$21,"")) | F20: =IF($A20="","",IFERROR(Calculations!$F$21,"")) | G20: =IF($A20="","",MARKET_LABEL) | H20: =IF($A20="","",IF($N20>=6,"صعودی قوی",IF($N20>=2,"صعودی",IF($N20<=-6,"نزولی قوی",IF($N20<=-2,"نزولی","خنثی"))))) | I20: =IF($A20="","",IFERROR(Calculations!$U$21,"")) | J20: =IF($A20="","",IF($O20>=6,"ورود قوی پول حقیقی",IF($O20>=2,"ورود پول حقیقی",IF($O20<=-6,"خروج قوی پول حقیقی",IF($O20<=-2,"خروج پول حقیقی","متعادل"))))) | K20: =IF($A20="","",IFERROR(Calculations!$AG$21,"")) | L20: =IF($A20="","",IFERROR(Calculations!$O$21,"")) | M20: =IF($A20="","",IFERROR(Calculations!$AA$21,"")) | N20: =IF($A20="","",IFERROR(Calculations!$AJ$21,0)) | O20: =IF($A20="","",IFERROR(Calculations!$AK$21,0)) | P20: =IF($A20="","",IFERROR(Calculations!$AL$21,0)) | Q20: =IF($A20="","",IFERROR(Calculations!$AM$21,0)) | R20: =IF($A20="","",IFERROR(Calculations!$AN$21,0)) | S20: =IF($A20="","",IFERROR(Calculations!$AO$21,0)) | T20: =IF($A20="","",IFERROR(Calculations!$AP$21,0)) | U20: =IF($A20="","",IF($T20>=TH_SBUY,"خرید قوی",IF($T20>=TH_BUY,"خرید",IF($T20<=TH_SSELL,"فروش قوی",IF($T20<=TH_SELL,"فروش","نگهداری"))))) | V20: =IF($A20="","",IFERROR(Calculations!$AQ$21,1)) | W20: =IF($A20="","","روند: "&$H20&" | ساختار: "&$I20&" | پول هوشمند: "&$J20&" | قدرت خریدار: "&IFERROR(TEXT($K20,"0.00"),"—")&"x"&" | میانگین‌ها: "&IFERROR(TEXT(Calculations!$N$21,"0"),"—")&"/4 ("&$L20&")"&" | حجم: "&IFERROR(TEXT($M20,"0.00"),"—")&"x"&" | بازار: "&$G20) | X20: =IF($A20="","",IFERROR(Calculations!$X$21,"")) | Y20: =IF($A20="","",IFERROR(($E20-$X20)/$E20,"")) | Z20: =IF($A20="","",IFERROR(Calculations!$AR$21,""))
A21: =IF(Calculations!$A$22="","",Calculations!$A$22) | B21: =IF($A21="","",IFERROR(INDEX(Watchlist!$B$1:$B$5000,MATCH($A21,Watchlist!$A$1:$A$5000,0)),"")) | C21: =IF($A21="","",IFERROR(INDEX(Watchlist!$F$1:$F$5000,MATCH($A21,Watchlist!$A$1:$A$5000,0)),"")) | D21: =IF($A21="","",IFERROR(INDEX(Watchlist!$E$1:$E$5000,MATCH($A21,Watchlist!$A$1:$A$5000,0)),"")) | E21: =IF($A21="","",IFERROR(Calculations!$D$22,"")) | F21: =IF($A21="","",IFERROR(Calculations!$F$22,"")) | G21: =IF($A21="","",MARKET_LABEL) | H21: =IF($A21="","",IF($N21>=6,"صعودی قوی",IF($N21>=2,"صعودی",IF($N21<=-6,"نزولی قوی",IF($N21<=-2,"نزولی","خنثی"))))) | I21: =IF($A21="","",IFERROR(Calculations!$U$22,"")) | J21: =IF($A21="","",IF($O21>=6,"ورود قوی پول حقیقی",IF($O21>=2,"ورود پول حقیقی",IF($O21<=-6,"خروج قوی پول حقیقی",IF($O21<=-2,"خروج پول حقیقی","متعادل"))))) | K21: =IF($A21="","",IFERROR(Calculations!$AG$22,"")) | L21: =IF($A21="","",IFERROR(Calculations!$O$22,"")) | M21: =IF($A21="","",IFERROR(Calculations!$AA$22,"")) | N21: =IF($A21="","",IFERROR(Calculations!$AJ$22,0)) | O21: =IF($A21="","",IFERROR(Calculations!$AK$22,0)) | P21: =IF($A21="","",IFERROR(Calculations!$AL$22,0)) | Q21: =IF($A21="","",IFERROR(Calculations!$AM$22,0)) | R21: =IF($A21="","",IFERROR(Calculations!$AN$22,0)) | S21: =IF($A21="","",IFERROR(Calculations!$AO$22,0)) | T21: =IF($A21="","",IFERROR(Calculations!$AP$22,0)) | U21: =IF($A21="","",IF($T21>=TH_SBUY,"خرید قوی",IF($T21>=TH_BUY,"خرید",IF($T21<=TH_SSELL,"فروش قوی",IF($T21<=TH_SELL,"فروش","نگهداری"))))) | V21: =IF($A21="","",IFERROR(Calculations!$AQ$22,1)) | W21: =IF($A21="","","روند: "&$H21&" | ساختار: "&$I21&" | پول هوشمند: "&$J21&" | قدرت خریدار: "&IFERROR(TEXT($K21,"0.00"),"—")&"x"&" | میانگین‌ها: "&IFERROR(TEXT(Calculations!$N$22,"0"),"—")&"/4 ("&$L21&")"&" | حجم: "&IFERROR(TEXT($M21,"0.00"),"—")&"x"&" | بازار: "&$G21) | X21: =IF($A21="","",IFERROR(Calculations!$X$22,"")) | Y21: =IF($A21="","",IFERROR(($E21-$X21)/$E21,"")) | Z21: =IF($A21="","",IFERROR(Calculations!$AR$22,""))
A22: =IF(Calculations!$A$23="","",Calculations!$A$23) | B22: =IF($A22="","",IFERROR(INDEX(Watchlist!$B$1:$B$5000,MATCH($A22,Watchlist!$A$1:$A$5000,0)),"")) | C22: =IF($A22="","",IFERROR(INDEX(Watchlist!$F$1:$F$5000,MATCH($A22,Watchlist!$A$1:$A$5000,0)),"")) | D22: =IF($A22="","",IFERROR(INDEX(Watchlist!$E$1:$E$5000,MATCH($A22,Watchlist!$A$1:$A$5000,0)),"")) | E22: =IF($A22="","",IFERROR(Calculations!$D$23,"")) | F22: =IF($A22="","",IFERROR(Calculations!$F$23,"")) | G22: =IF($A22="","",MARKET_LABEL) | H22: =IF($A22="","",IF($N22>=6,"صعودی قوی",IF($N22>=2,"صعودی",IF($N22<=-6,"نزولی قوی",IF($N22<=-2,"نزولی","خنثی"))))) | I22: =IF($A22="","",IFERROR(Calculations!$U$23,"")) | J22: =IF($A22="","",IF($O22>=6,"ورود قوی پول حقیقی",IF($O22>=2,"ورود پول حقیقی",IF($O22<=-6,"خروج قوی پول حقیقی",IF($O22<=-2,"خروج پول حقیقی","متعادل"))))) | K22: =IF($A22="","",IFERROR(Calculations!$AG$23,"")) | L22: =IF($A22="","",IFERROR(Calculations!$O$23,"")) | M22: =IF($A22="","",IFERROR(Calculations!$AA$23,"")) | N22: =IF($A22="","",IFERROR(Calculations!$AJ$23,0)) | O22: =IF($A22="","",IFERROR(Calculations!$AK$23,0)) | P22: =IF($A22="","",IFERROR(Calculations!$AL$23,0)) | Q22: =IF($A22="","",IFERROR(Calculations!$AM$23,0)) | R22: =IF($A22="","",IFERROR(Calculations!$AN$23,0)) | S22: =IF($A22="","",IFERROR(Calculations!$AO$23,0)) | T22: =IF($A22="","",IFERROR(Calculations!$AP$23,0)) | U22: =IF($A22="","",IF($T22>=TH_SBUY,"خرید قوی",IF($T22>=TH_BUY,"خرید",IF($T22<=TH_SSELL,"فروش قوی",IF($T22<=TH_SELL,"فروش","نگهداری"))))) | V22: =IF($A22="","",IFERROR(Calculations!$AQ$23,1)) | W22: =IF($A22="","","روند: "&$H22&" | ساختار: "&$I22&" | پول هوشمند: "&$J22&" | قدرت خریدار: "&IFERROR(TEXT($K22,"0.00"),"—")&"x"&" | میانگین‌ها: "&IFERROR(TEXT(Calculations!$N$23,"0"),"—")&"/4 ("&$L22&")"&" | حجم: "&IFERROR(TEXT($M22,"0.00"),"—")&"x"&" | بازار: "&$G22) | X22: =IF($A22="","",IFERROR(Calculations!$X$23,"")) | Y22: =IF($A22="","",IFERROR(($E22-$X22)/$E22,"")) | Z22: =IF($A22="","",IFERROR(Calculations!$AR$23,""))
